2019-12-09 01:06:00,889; client.py - line: 58 -DEBUG: Starting python client.
2019-12-09 01:06:00,889; client.py - line: 58 -DEBUG: Starting python client.
2019-12-09 01:06:00,890; client.py - line: 78 -INFO: Starting Unity...
2019-12-09 01:06:00,890; client.py - line: 78 -INFO: Starting Unity...
2019-12-09 01:06:00,890; client.py - line: 79 -DEBUG: path to unity: /home/haecker/Documents/src/git/python_unity_images/build_linux/unity_server_rendering_images.x86_64
2019-12-09 01:06:00,890; client.py - line: 79 -DEBUG: path to unity: /home/haecker/Documents/src/git/python_unity_images/build_linux/unity_server_rendering_images.x86_64
2019-12-09 01:06:00,897; client.py - line: 92 -INFO: Waiting for unity...
2019-12-09 01:06:00,897; client.py - line: 92 -INFO: Waiting for unity...
2019-12-09 01:06:03,902; client.py - line: 119 -INFO: Client now connecting to server.
2019-12-09 01:06:03,902; client.py - line: 119 -INFO: Client now connecting to server.
2019-12-09 01:06:03,903; client.py - line: 127 -DEBUG: Config data for TCP socket: host: 127.0.0.1; port: 50050
2019-12-09 01:06:03,903; client.py - line: 127 -DEBUG: Config data for TCP socket: host: 127.0.0.1; port: 50050
2019-12-09 01:06:03,903; client.py - line: 140 -DEBUG: Socket can not connect. Make sure that the tcp_server from unity is already running.
2019-12-09 01:06:03,903; client.py - line: 140 -DEBUG: Socket can not connect. Make sure that the tcp_server from unity is already running.
2019-12-09 01:06:03,903; client.py - line: 141 -DEBUG: [Errno 111] Connection refused
2019-12-09 01:06:03,903; client.py - line: 141 -DEBUG: [Errno 111] Connection refused
2019-12-09 01:06:03,954; client.py - line: 149 -DEBUG: Try next port: 49990
2019-12-09 01:06:03,954; client.py - line: 149 -DEBUG: Try next port: 49990
2019-12-09 01:06:03,954; client.py - line: 140 -DEBUG: Socket can not connect. Make sure that the tcp_server from unity is already running.
2019-12-09 01:06:03,954; client.py - line: 140 -DEBUG: Socket can not connect. Make sure that the tcp_server from unity is already running.
2019-12-09 01:06:03,954; client.py - line: 141 -DEBUG: [Errno 103] Software caused connection abort
2019-12-09 01:06:03,954; client.py - line: 141 -DEBUG: [Errno 103] Software caused connection abort
2019-12-09 01:06:04,004; client.py - line: 149 -DEBUG: Try next port: 49991
2019-12-09 01:06:04,004; client.py - line: 149 -DEBUG: Try next port: 49991
2019-12-09 01:06:04,006; client.py - line: 140 -DEBUG: Socket can not connect. Make sure that the tcp_server from unity is already running.
2019-12-09 01:06:04,006; client.py - line: 140 -DEBUG: Socket can not connect. Make sure that the tcp_server from unity is already running.
2019-12-09 01:06:04,006; client.py - line: 141 -DEBUG: [Errno 111] Connection refused
2019-12-09 01:06:04,006; client.py - line: 141 -DEBUG: [Errno 111] Connection refused
2019-12-09 01:06:04,058; client.py - line: 149 -DEBUG: Try next port: 49992
2019-12-09 01:06:04,058; client.py - line: 149 -DEBUG: Try next port: 49992
2019-12-09 01:06:04,059; client.py - line: 140 -DEBUG: Socket can not connect. Make sure that the tcp_server from unity is already running.
2019-12-09 01:06:04,059; client.py - line: 140 -DEBUG: Socket can not connect. Make sure that the tcp_server from unity is already running.
2019-12-09 01:06:04,060; client.py - line: 141 -DEBUG: [Errno 103] Software caused connection abort
2019-12-09 01:06:04,060; client.py - line: 141 -DEBUG: [Errno 103] Software caused connection abort
2019-12-09 01:06:04,111; client.py - line: 149 -DEBUG: Try next port: 49993
2019-12-09 01:06:04,111; client.py - line: 149 -DEBUG: Try next port: 49993
2019-12-09 01:06:04,112; client.py - line: 140 -DEBUG: Socket can not connect. Make sure that the tcp_server from unity is already running.
2019-12-09 01:06:04,112; client.py - line: 140 -DEBUG: Socket can not connect. Make sure that the tcp_server from unity is already running.
2019-12-09 01:06:04,112; client.py - line: 141 -DEBUG: [Errno 111] Connection refused
2019-12-09 01:06:04,112; client.py - line: 141 -DEBUG: [Errno 111] Connection refused
2019-12-09 01:06:04,163; client.py - line: 149 -DEBUG: Try next port: 49994
2019-12-09 01:06:04,163; client.py - line: 149 -DEBUG: Try next port: 49994
2019-12-09 01:06:04,164; client.py - line: 140 -DEBUG: Socket can not connect. Make sure that the tcp_server from unity is already running.
2019-12-09 01:06:04,164; client.py - line: 140 -DEBUG: Socket can not connect. Make sure that the tcp_server from unity is already running.
2019-12-09 01:06:04,165; client.py - line: 141 -DEBUG: [Errno 103] Software caused connection abort
2019-12-09 01:06:04,165; client.py - line: 141 -DEBUG: [Errno 103] Software caused connection abort
2019-12-09 01:06:04,215; client.py - line: 149 -DEBUG: Try next port: 49995
2019-12-09 01:06:04,215; client.py - line: 149 -DEBUG: Try next port: 49995
2019-12-09 01:06:04,216; client.py - line: 140 -DEBUG: Socket can not connect. Make sure that the tcp_server from unity is already running.
2019-12-09 01:06:04,216; client.py - line: 140 -DEBUG: Socket can not connect. Make sure that the tcp_server from unity is already running.
2019-12-09 01:06:04,216; client.py - line: 141 -DEBUG: [Errno 111] Connection refused
2019-12-09 01:06:04,216; client.py - line: 141 -DEBUG: [Errno 111] Connection refused
2019-12-09 01:06:04,266; client.py - line: 149 -DEBUG: Try next port: 49996
2019-12-09 01:06:04,266; client.py - line: 149 -DEBUG: Try next port: 49996
2019-12-09 01:06:04,267; client.py - line: 140 -DEBUG: Socket can not connect. Make sure that the tcp_server from unity is already running.
2019-12-09 01:06:04,267; client.py - line: 140 -DEBUG: Socket can not connect. Make sure that the tcp_server from unity is already running.
2019-12-09 01:06:04,268; client.py - line: 141 -DEBUG: [Errno 103] Software caused connection abort
2019-12-09 01:06:04,268; client.py - line: 141 -DEBUG: [Errno 103] Software caused connection abort
2019-12-09 01:06:04,318; client.py - line: 149 -DEBUG: Try next port: 49997
2019-12-09 01:06:04,318; client.py - line: 149 -DEBUG: Try next port: 49997
2019-12-09 01:06:04,319; client.py - line: 140 -DEBUG: Socket can not connect. Make sure that the tcp_server from unity is already running.
2019-12-09 01:06:04,319; client.py - line: 140 -DEBUG: Socket can not connect. Make sure that the tcp_server from unity is already running.
2019-12-09 01:06:04,320; client.py - line: 141 -DEBUG: [Errno 111] Connection refused
2019-12-09 01:06:04,320; client.py - line: 141 -DEBUG: [Errno 111] Connection refused
2019-12-09 01:06:04,371; client.py - line: 149 -DEBUG: Try next port: 49998
2019-12-09 01:06:04,371; client.py - line: 149 -DEBUG: Try next port: 49998
2019-12-09 01:06:04,372; client.py - line: 140 -DEBUG: Socket can not connect. Make sure that the tcp_server from unity is already running.
2019-12-09 01:06:04,372; client.py - line: 140 -DEBUG: Socket can not connect. Make sure that the tcp_server from unity is already running.
2019-12-09 01:06:04,373; client.py - line: 141 -DEBUG: [Errno 103] Software caused connection abort
2019-12-09 01:06:04,373; client.py - line: 141 -DEBUG: [Errno 103] Software caused connection abort
2019-12-09 01:06:04,424; client.py - line: 149 -DEBUG: Try next port: 49999
2019-12-09 01:06:04,424; client.py - line: 149 -DEBUG: Try next port: 49999
2019-12-09 01:06:04,425; client.py - line: 140 -DEBUG: Socket can not connect. Make sure that the tcp_server from unity is already running.
2019-12-09 01:06:04,425; client.py - line: 140 -DEBUG: Socket can not connect. Make sure that the tcp_server from unity is already running.
2019-12-09 01:06:04,426; client.py - line: 141 -DEBUG: [Errno 111] Connection refused
2019-12-09 01:06:04,426; client.py - line: 141 -DEBUG: [Errno 111] Connection refused
2019-12-09 01:06:04,476; client.py - line: 149 -DEBUG: Try next port: 50000
2019-12-09 01:06:04,476; client.py - line: 149 -DEBUG: Try next port: 50000
2019-12-09 01:06:04,476; client.py - line: 140 -DEBUG: Socket can not connect. Make sure that the tcp_server from unity is already running.
2019-12-09 01:06:04,476; client.py - line: 140 -DEBUG: Socket can not connect. Make sure that the tcp_server from unity is already running.
2019-12-09 01:06:04,476; client.py - line: 141 -DEBUG: [Errno 103] Software caused connection abort
2019-12-09 01:06:04,476; client.py - line: 141 -DEBUG: [Errno 103] Software caused connection abort
2019-12-09 01:06:04,527; client.py - line: 149 -DEBUG: Try next port: 50001
2019-12-09 01:06:04,527; client.py - line: 149 -DEBUG: Try next port: 50001
2019-12-09 01:06:04,527; client.py - line: 140 -DEBUG: Socket can not connect. Make sure that the tcp_server from unity is already running.
2019-12-09 01:06:04,527; client.py - line: 140 -DEBUG: Socket can not connect. Make sure that the tcp_server from unity is already running.
2019-12-09 01:06:04,527; client.py - line: 141 -DEBUG: [Errno 111] Connection refused
2019-12-09 01:06:04,527; client.py - line: 141 -DEBUG: [Errno 111] Connection refused
2019-12-09 01:06:04,577; client.py - line: 149 -DEBUG: Try next port: 50002
2019-12-09 01:06:04,577; client.py - line: 149 -DEBUG: Try next port: 50002
2019-12-09 01:06:04,579; client.py - line: 140 -DEBUG: Socket can not connect. Make sure that the tcp_server from unity is already running.
2019-12-09 01:06:04,579; client.py - line: 140 -DEBUG: Socket can not connect. Make sure that the tcp_server from unity is already running.
2019-12-09 01:06:04,579; client.py - line: 141 -DEBUG: [Errno 103] Software caused connection abort
2019-12-09 01:06:04,579; client.py - line: 141 -DEBUG: [Errno 103] Software caused connection abort
2019-12-09 01:06:04,630; client.py - line: 149 -DEBUG: Try next port: 50003
2019-12-09 01:06:04,630; client.py - line: 149 -DEBUG: Try next port: 50003
2019-12-09 01:06:04,632; client.py - line: 140 -DEBUG: Socket can not connect. Make sure that the tcp_server from unity is already running.
2019-12-09 01:06:04,632; client.py - line: 140 -DEBUG: Socket can not connect. Make sure that the tcp_server from unity is already running.
2019-12-09 01:06:04,632; client.py - line: 141 -DEBUG: [Errno 111] Connection refused
2019-12-09 01:06:04,632; client.py - line: 141 -DEBUG: [Errno 111] Connection refused
2019-12-09 01:06:04,683; client.py - line: 149 -DEBUG: Try next port: 50004
2019-12-09 01:06:04,683; client.py - line: 149 -DEBUG: Try next port: 50004
2019-12-09 01:06:04,684; client.py - line: 140 -DEBUG: Socket can not connect. Make sure that the tcp_server from unity is already running.
2019-12-09 01:06:04,684; client.py - line: 140 -DEBUG: Socket can not connect. Make sure that the tcp_server from unity is already running.
2019-12-09 01:06:04,685; client.py - line: 141 -DEBUG: [Errno 103] Software caused connection abort
2019-12-09 01:06:04,685; client.py - line: 141 -DEBUG: [Errno 103] Software caused connection abort
2019-12-09 01:06:04,736; client.py - line: 149 -DEBUG: Try next port: 50005
2019-12-09 01:06:04,736; client.py - line: 149 -DEBUG: Try next port: 50005
2019-12-09 01:06:04,737; client.py - line: 140 -DEBUG: Socket can not connect. Make sure that the tcp_server from unity is already running.
2019-12-09 01:06:04,737; client.py - line: 140 -DEBUG: Socket can not connect. Make sure that the tcp_server from unity is already running.
2019-12-09 01:06:04,738; client.py - line: 141 -DEBUG: [Errno 111] Connection refused
2019-12-09 01:06:04,738; client.py - line: 141 -DEBUG: [Errno 111] Connection refused
2019-12-09 01:06:04,788; client.py - line: 149 -DEBUG: Try next port: 50006
2019-12-09 01:06:04,788; client.py - line: 149 -DEBUG: Try next port: 50006
2019-12-09 01:06:04,789; client.py - line: 140 -DEBUG: Socket can not connect. Make sure that the tcp_server from unity is already running.
2019-12-09 01:06:04,789; client.py - line: 140 -DEBUG: Socket can not connect. Make sure that the tcp_server from unity is already running.
2019-12-09 01:06:04,790; client.py - line: 141 -DEBUG: [Errno 103] Software caused connection abort
2019-12-09 01:06:04,790; client.py - line: 141 -DEBUG: [Errno 103] Software caused connection abort
2019-12-09 01:06:04,841; client.py - line: 149 -DEBUG: Try next port: 50007
2019-12-09 01:06:04,841; client.py - line: 149 -DEBUG: Try next port: 50007
2019-12-09 01:06:04,843; client.py - line: 140 -DEBUG: Socket can not connect. Make sure that the tcp_server from unity is already running.
2019-12-09 01:06:04,843; client.py - line: 140 -DEBUG: Socket can not connect. Make sure that the tcp_server from unity is already running.
2019-12-09 01:06:04,843; client.py - line: 141 -DEBUG: [Errno 111] Connection refused
2019-12-09 01:06:04,843; client.py - line: 141 -DEBUG: [Errno 111] Connection refused
2019-12-09 01:06:04,894; client.py - line: 149 -DEBUG: Try next port: 50008
2019-12-09 01:06:04,894; client.py - line: 149 -DEBUG: Try next port: 50008
2019-12-09 01:06:04,895; client.py - line: 140 -DEBUG: Socket can not connect. Make sure that the tcp_server from unity is already running.
2019-12-09 01:06:04,895; client.py - line: 140 -DEBUG: Socket can not connect. Make sure that the tcp_server from unity is already running.
2019-12-09 01:06:04,896; client.py - line: 141 -DEBUG: [Errno 103] Software caused connection abort
2019-12-09 01:06:04,896; client.py - line: 141 -DEBUG: [Errno 103] Software caused connection abort
2019-12-09 01:06:04,946; client.py - line: 149 -DEBUG: Try next port: 50009
2019-12-09 01:06:04,946; client.py - line: 149 -DEBUG: Try next port: 50009
2019-12-09 01:06:04,947; client.py - line: 140 -DEBUG: Socket can not connect. Make sure that the tcp_server from unity is already running.
2019-12-09 01:06:04,947; client.py - line: 140 -DEBUG: Socket can not connect. Make sure that the tcp_server from unity is already running.
2019-12-09 01:06:04,948; client.py - line: 141 -DEBUG: [Errno 111] Connection refused
2019-12-09 01:06:04,948; client.py - line: 141 -DEBUG: [Errno 111] Connection refused
2019-12-09 01:06:04,999; client.py - line: 149 -DEBUG: Try next port: 50010
2019-12-09 01:06:04,999; client.py - line: 149 -DEBUG: Try next port: 50010
2019-12-09 01:06:05,000; client.py - line: 140 -DEBUG: Socket can not connect. Make sure that the tcp_server from unity is already running.
2019-12-09 01:06:05,000; client.py - line: 140 -DEBUG: Socket can not connect. Make sure that the tcp_server from unity is already running.
2019-12-09 01:06:05,000; client.py - line: 141 -DEBUG: [Errno 103] Software caused connection abort
2019-12-09 01:06:05,000; client.py - line: 141 -DEBUG: [Errno 103] Software caused connection abort
2019-12-09 01:06:05,051; client.py - line: 149 -DEBUG: Try next port: 50011
2019-12-09 01:06:05,051; client.py - line: 149 -DEBUG: Try next port: 50011
2019-12-09 01:06:05,052; client.py - line: 140 -DEBUG: Socket can not connect. Make sure that the tcp_server from unity is already running.
2019-12-09 01:06:05,052; client.py - line: 140 -DEBUG: Socket can not connect. Make sure that the tcp_server from unity is already running.
2019-12-09 01:06:05,053; client.py - line: 141 -DEBUG: [Errno 111] Connection refused
2019-12-09 01:06:05,053; client.py - line: 141 -DEBUG: [Errno 111] Connection refused
2019-12-09 01:06:05,104; client.py - line: 149 -DEBUG: Try next port: 50012
2019-12-09 01:06:05,104; client.py - line: 149 -DEBUG: Try next port: 50012
2019-12-09 01:06:05,105; client.py - line: 140 -DEBUG: Socket can not connect. Make sure that the tcp_server from unity is already running.
2019-12-09 01:06:05,105; client.py - line: 140 -DEBUG: Socket can not connect. Make sure that the tcp_server from unity is already running.
2019-12-09 01:06:05,106; client.py - line: 141 -DEBUG: [Errno 103] Software caused connection abort
2019-12-09 01:06:05,106; client.py - line: 141 -DEBUG: [Errno 103] Software caused connection abort
2019-12-09 01:06:05,157; client.py - line: 149 -DEBUG: Try next port: 50013
2019-12-09 01:06:05,157; client.py - line: 149 -DEBUG: Try next port: 50013
2019-12-09 01:06:05,159; client.py - line: 140 -DEBUG: Socket can not connect. Make sure that the tcp_server from unity is already running.
2019-12-09 01:06:05,159; client.py - line: 140 -DEBUG: Socket can not connect. Make sure that the tcp_server from unity is already running.
2019-12-09 01:06:05,160; client.py - line: 141 -DEBUG: [Errno 111] Connection refused
2019-12-09 01:06:05,160; client.py - line: 141 -DEBUG: [Errno 111] Connection refused
2019-12-09 01:06:05,211; client.py - line: 149 -DEBUG: Try next port: 50014
2019-12-09 01:06:05,211; client.py - line: 149 -DEBUG: Try next port: 50014
2019-12-09 01:06:05,212; client.py - line: 140 -DEBUG: Socket can not connect. Make sure that the tcp_server from unity is already running.
2019-12-09 01:06:05,212; client.py - line: 140 -DEBUG: Socket can not connect. Make sure that the tcp_server from unity is already running.
2019-12-09 01:06:05,212; client.py - line: 141 -DEBUG: [Errno 103] Software caused connection abort
2019-12-09 01:06:05,212; client.py - line: 141 -DEBUG: [Errno 103] Software caused connection abort
2019-12-09 01:06:05,263; client.py - line: 149 -DEBUG: Try next port: 50015
2019-12-09 01:06:05,263; client.py - line: 149 -DEBUG: Try next port: 50015
2019-12-09 01:06:05,264; client.py - line: 140 -DEBUG: Socket can not connect. Make sure that the tcp_server from unity is already running.
2019-12-09 01:06:05,264; client.py - line: 140 -DEBUG: Socket can not connect. Make sure that the tcp_server from unity is already running.
2019-12-09 01:06:05,264; client.py - line: 141 -DEBUG: [Errno 111] Connection refused
2019-12-09 01:06:05,264; client.py - line: 141 -DEBUG: [Errno 111] Connection refused
2019-12-09 01:06:05,315; client.py - line: 149 -DEBUG: Try next port: 50016
2019-12-09 01:06:05,315; client.py - line: 149 -DEBUG: Try next port: 50016
2019-12-09 01:06:05,316; client.py - line: 140 -DEBUG: Socket can not connect. Make sure that the tcp_server from unity is already running.
2019-12-09 01:06:05,316; client.py - line: 140 -DEBUG: Socket can not connect. Make sure that the tcp_server from unity is already running.
2019-12-09 01:06:05,316; client.py - line: 141 -DEBUG: [Errno 103] Software caused connection abort
2019-12-09 01:06:05,316; client.py - line: 141 -DEBUG: [Errno 103] Software caused connection abort
2019-12-09 01:06:05,367; client.py - line: 149 -DEBUG: Try next port: 50017
2019-12-09 01:06:05,367; client.py - line: 149 -DEBUG: Try next port: 50017
2019-12-09 01:06:05,368; client.py - line: 140 -DEBUG: Socket can not connect. Make sure that the tcp_server from unity is already running.
2019-12-09 01:06:05,368; client.py - line: 140 -DEBUG: Socket can not connect. Make sure that the tcp_server from unity is already running.
2019-12-09 01:06:05,368; client.py - line: 141 -DEBUG: [Errno 111] Connection refused
2019-12-09 01:06:05,368; client.py - line: 141 -DEBUG: [Errno 111] Connection refused
2019-12-09 01:06:05,419; client.py - line: 149 -DEBUG: Try next port: 50018
2019-12-09 01:06:05,419; client.py - line: 149 -DEBUG: Try next port: 50018
2019-12-09 01:06:05,420; client.py - line: 140 -DEBUG: Socket can not connect. Make sure that the tcp_server from unity is already running.
2019-12-09 01:06:05,420; client.py - line: 140 -DEBUG: Socket can not connect. Make sure that the tcp_server from unity is already running.
2019-12-09 01:06:05,421; client.py - line: 141 -DEBUG: [Errno 103] Software caused connection abort
2019-12-09 01:06:05,421; client.py - line: 141 -DEBUG: [Errno 103] Software caused connection abort
2019-12-09 01:06:05,472; client.py - line: 149 -DEBUG: Try next port: 50019
2019-12-09 01:06:05,472; client.py - line: 149 -DEBUG: Try next port: 50019
2019-12-09 01:06:05,473; client.py - line: 140 -DEBUG: Socket can not connect. Make sure that the tcp_server from unity is already running.
2019-12-09 01:06:05,473; client.py - line: 140 -DEBUG: Socket can not connect. Make sure that the tcp_server from unity is already running.
2019-12-09 01:06:05,474; client.py - line: 141 -DEBUG: [Errno 111] Connection refused
2019-12-09 01:06:05,474; client.py - line: 141 -DEBUG: [Errno 111] Connection refused
2019-12-09 01:06:05,525; client.py - line: 149 -DEBUG: Try next port: 50020
2019-12-09 01:06:05,525; client.py - line: 149 -DEBUG: Try next port: 50020
2019-12-09 01:06:05,526; client.py - line: 140 -DEBUG: Socket can not connect. Make sure that the tcp_server from unity is already running.
2019-12-09 01:06:05,526; client.py - line: 140 -DEBUG: Socket can not connect. Make sure that the tcp_server from unity is already running.
2019-12-09 01:06:05,527; client.py - line: 141 -DEBUG: [Errno 103] Software caused connection abort
2019-12-09 01:06:05,527; client.py - line: 141 -DEBUG: [Errno 103] Software caused connection abort
2019-12-09 01:06:05,578; client.py - line: 149 -DEBUG: Try next port: 50021
2019-12-09 01:06:05,578; client.py - line: 149 -DEBUG: Try next port: 50021
2019-12-09 01:06:05,579; client.py - line: 140 -DEBUG: Socket can not connect. Make sure that the tcp_server from unity is already running.
2019-12-09 01:06:05,579; client.py - line: 140 -DEBUG: Socket can not connect. Make sure that the tcp_server from unity is already running.
2019-12-09 01:06:05,580; client.py - line: 141 -DEBUG: [Errno 111] Connection refused
2019-12-09 01:06:05,580; client.py - line: 141 -DEBUG: [Errno 111] Connection refused
2019-12-09 01:06:05,631; client.py - line: 149 -DEBUG: Try next port: 50022
2019-12-09 01:06:05,631; client.py - line: 149 -DEBUG: Try next port: 50022
2019-12-09 01:06:05,632; client.py - line: 140 -DEBUG: Socket can not connect. Make sure that the tcp_server from unity is already running.
2019-12-09 01:06:05,632; client.py - line: 140 -DEBUG: Socket can not connect. Make sure that the tcp_server from unity is already running.
2019-12-09 01:06:05,633; client.py - line: 141 -DEBUG: [Errno 103] Software caused connection abort
2019-12-09 01:06:05,633; client.py - line: 141 -DEBUG: [Errno 103] Software caused connection abort
2019-12-09 01:06:05,684; client.py - line: 149 -DEBUG: Try next port: 50023
2019-12-09 01:06:05,684; client.py - line: 149 -DEBUG: Try next port: 50023
2019-12-09 01:06:05,685; client.py - line: 140 -DEBUG: Socket can not connect. Make sure that the tcp_server from unity is already running.
2019-12-09 01:06:05,685; client.py - line: 140 -DEBUG: Socket can not connect. Make sure that the tcp_server from unity is already running.
2019-12-09 01:06:05,686; client.py - line: 141 -DEBUG: [Errno 111] Connection refused
2019-12-09 01:06:05,686; client.py - line: 141 -DEBUG: [Errno 111] Connection refused
2019-12-09 01:06:05,737; client.py - line: 149 -DEBUG: Try next port: 50024
2019-12-09 01:06:05,737; client.py - line: 149 -DEBUG: Try next port: 50024
2019-12-09 01:06:05,739; client.py - line: 140 -DEBUG: Socket can not connect. Make sure that the tcp_server from unity is already running.
2019-12-09 01:06:05,739; client.py - line: 140 -DEBUG: Socket can not connect. Make sure that the tcp_server from unity is already running.
2019-12-09 01:06:05,740; client.py - line: 141 -DEBUG: [Errno 103] Software caused connection abort
2019-12-09 01:06:05,740; client.py - line: 141 -DEBUG: [Errno 103] Software caused connection abort
2019-12-09 01:06:05,791; client.py - line: 149 -DEBUG: Try next port: 50025
2019-12-09 01:06:05,791; client.py - line: 149 -DEBUG: Try next port: 50025
2019-12-09 01:06:05,792; client.py - line: 140 -DEBUG: Socket can not connect. Make sure that the tcp_server from unity is already running.
2019-12-09 01:06:05,792; client.py - line: 140 -DEBUG: Socket can not connect. Make sure that the tcp_server from unity is already running.
2019-12-09 01:06:05,792; client.py - line: 141 -DEBUG: [Errno 111] Connection refused
2019-12-09 01:06:05,792; client.py - line: 141 -DEBUG: [Errno 111] Connection refused
2019-12-09 01:06:05,843; client.py - line: 149 -DEBUG: Try next port: 50026
2019-12-09 01:06:05,843; client.py - line: 149 -DEBUG: Try next port: 50026
2019-12-09 01:06:05,844; client.py - line: 140 -DEBUG: Socket can not connect. Make sure that the tcp_server from unity is already running.
2019-12-09 01:06:05,844; client.py - line: 140 -DEBUG: Socket can not connect. Make sure that the tcp_server from unity is already running.
2019-12-09 01:06:05,845; client.py - line: 141 -DEBUG: [Errno 103] Software caused connection abort
2019-12-09 01:06:05,845; client.py - line: 141 -DEBUG: [Errno 103] Software caused connection abort
2019-12-09 01:06:05,895; client.py - line: 149 -DEBUG: Try next port: 50027
2019-12-09 01:06:05,895; client.py - line: 149 -DEBUG: Try next port: 50027
2019-12-09 01:06:05,896; client.py - line: 140 -DEBUG: Socket can not connect. Make sure that the tcp_server from unity is already running.
2019-12-09 01:06:05,896; client.py - line: 140 -DEBUG: Socket can not connect. Make sure that the tcp_server from unity is already running.
2019-12-09 01:06:05,897; client.py - line: 141 -DEBUG: [Errno 111] Connection refused
2019-12-09 01:06:05,897; client.py - line: 141 -DEBUG: [Errno 111] Connection refused
2019-12-09 01:06:05,948; client.py - line: 149 -DEBUG: Try next port: 50028
2019-12-09 01:06:05,948; client.py - line: 149 -DEBUG: Try next port: 50028
2019-12-09 01:06:05,949; client.py - line: 140 -DEBUG: Socket can not connect. Make sure that the tcp_server from unity is already running.
2019-12-09 01:06:05,949; client.py - line: 140 -DEBUG: Socket can not connect. Make sure that the tcp_server from unity is already running.
2019-12-09 01:06:05,949; client.py - line: 141 -DEBUG: [Errno 103] Software caused connection abort
2019-12-09 01:06:05,949; client.py - line: 141 -DEBUG: [Errno 103] Software caused connection abort
2019-12-09 01:06:06,000; client.py - line: 149 -DEBUG: Try next port: 50029
2019-12-09 01:06:06,000; client.py - line: 149 -DEBUG: Try next port: 50029
2019-12-09 01:06:06,001; client.py - line: 140 -DEBUG: Socket can not connect. Make sure that the tcp_server from unity is already running.
2019-12-09 01:06:06,001; client.py - line: 140 -DEBUG: Socket can not connect. Make sure that the tcp_server from unity is already running.
2019-12-09 01:06:06,002; client.py - line: 141 -DEBUG: [Errno 111] Connection refused
2019-12-09 01:06:06,002; client.py - line: 141 -DEBUG: [Errno 111] Connection refused
2019-12-09 01:06:06,053; client.py - line: 149 -DEBUG: Try next port: 50030
2019-12-09 01:06:06,053; client.py - line: 149 -DEBUG: Try next port: 50030
2019-12-09 01:06:06,054; client.py - line: 140 -DEBUG: Socket can not connect. Make sure that the tcp_server from unity is already running.
2019-12-09 01:06:06,054; client.py - line: 140 -DEBUG: Socket can not connect. Make sure that the tcp_server from unity is already running.
2019-12-09 01:06:06,055; client.py - line: 141 -DEBUG: [Errno 103] Software caused connection abort
2019-12-09 01:06:06,055; client.py - line: 141 -DEBUG: [Errno 103] Software caused connection abort
2019-12-09 01:06:06,106; client.py - line: 149 -DEBUG: Try next port: 50031
2019-12-09 01:06:06,106; client.py - line: 149 -DEBUG: Try next port: 50031
2019-12-09 01:06:06,107; client.py - line: 140 -DEBUG: Socket can not connect. Make sure that the tcp_server from unity is already running.
2019-12-09 01:06:06,107; client.py - line: 140 -DEBUG: Socket can not connect. Make sure that the tcp_server from unity is already running.
2019-12-09 01:06:06,108; client.py - line: 141 -DEBUG: [Errno 111] Connection refused
2019-12-09 01:06:06,108; client.py - line: 141 -DEBUG: [Errno 111] Connection refused
2019-12-09 01:06:06,158; client.py - line: 149 -DEBUG: Try next port: 50032
2019-12-09 01:06:06,158; client.py - line: 149 -DEBUG: Try next port: 50032
2019-12-09 01:06:06,159; client.py - line: 140 -DEBUG: Socket can not connect. Make sure that the tcp_server from unity is already running.
2019-12-09 01:06:06,159; client.py - line: 140 -DEBUG: Socket can not connect. Make sure that the tcp_server from unity is already running.
2019-12-09 01:06:06,160; client.py - line: 141 -DEBUG: [Errno 103] Software caused connection abort
2019-12-09 01:06:06,160; client.py - line: 141 -DEBUG: [Errno 103] Software caused connection abort
2019-12-09 01:06:06,211; client.py - line: 149 -DEBUG: Try next port: 50033
2019-12-09 01:06:06,211; client.py - line: 149 -DEBUG: Try next port: 50033
2019-12-09 01:06:06,212; client.py - line: 140 -DEBUG: Socket can not connect. Make sure that the tcp_server from unity is already running.
2019-12-09 01:06:06,212; client.py - line: 140 -DEBUG: Socket can not connect. Make sure that the tcp_server from unity is already running.
2019-12-09 01:06:06,213; client.py - line: 141 -DEBUG: [Errno 111] Connection refused
2019-12-09 01:06:06,213; client.py - line: 141 -DEBUG: [Errno 111] Connection refused
2019-12-09 01:06:06,264; client.py - line: 149 -DEBUG: Try next port: 50034
2019-12-09 01:06:06,264; client.py - line: 149 -DEBUG: Try next port: 50034
2019-12-09 01:06:06,265; client.py - line: 140 -DEBUG: Socket can not connect. Make sure that the tcp_server from unity is already running.
2019-12-09 01:06:06,265; client.py - line: 140 -DEBUG: Socket can not connect. Make sure that the tcp_server from unity is already running.
2019-12-09 01:06:06,266; client.py - line: 141 -DEBUG: [Errno 103] Software caused connection abort
2019-12-09 01:06:06,266; client.py - line: 141 -DEBUG: [Errno 103] Software caused connection abort
2019-12-09 01:06:06,317; client.py - line: 149 -DEBUG: Try next port: 50035
2019-12-09 01:06:06,317; client.py - line: 149 -DEBUG: Try next port: 50035
2019-12-09 01:06:06,318; client.py - line: 140 -DEBUG: Socket can not connect. Make sure that the tcp_server from unity is already running.
2019-12-09 01:06:06,318; client.py - line: 140 -DEBUG: Socket can not connect. Make sure that the tcp_server from unity is already running.
2019-12-09 01:06:06,318; client.py - line: 141 -DEBUG: [Errno 111] Connection refused
2019-12-09 01:06:06,318; client.py - line: 141 -DEBUG: [Errno 111] Connection refused
2019-12-09 01:06:06,369; client.py - line: 149 -DEBUG: Try next port: 50036
2019-12-09 01:06:06,369; client.py - line: 149 -DEBUG: Try next port: 50036
2019-12-09 01:06:06,370; client.py - line: 140 -DEBUG: Socket can not connect. Make sure that the tcp_server from unity is already running.
2019-12-09 01:06:06,370; client.py - line: 140 -DEBUG: Socket can not connect. Make sure that the tcp_server from unity is already running.
2019-12-09 01:06:06,371; client.py - line: 141 -DEBUG: [Errno 103] Software caused connection abort
2019-12-09 01:06:06,371; client.py - line: 141 -DEBUG: [Errno 103] Software caused connection abort
2019-12-09 01:06:06,421; client.py - line: 149 -DEBUG: Try next port: 50037
2019-12-09 01:06:06,421; client.py - line: 149 -DEBUG: Try next port: 50037
2019-12-09 01:06:06,423; client.py - line: 140 -DEBUG: Socket can not connect. Make sure that the tcp_server from unity is already running.
2019-12-09 01:06:06,423; client.py - line: 140 -DEBUG: Socket can not connect. Make sure that the tcp_server from unity is already running.
2019-12-09 01:06:06,423; client.py - line: 141 -DEBUG: [Errno 111] Connection refused
2019-12-09 01:06:06,423; client.py - line: 141 -DEBUG: [Errno 111] Connection refused
2019-12-09 01:06:06,474; client.py - line: 149 -DEBUG: Try next port: 50038
2019-12-09 01:06:06,474; client.py - line: 149 -DEBUG: Try next port: 50038
2019-12-09 01:06:06,474; client.py - line: 140 -DEBUG: Socket can not connect. Make sure that the tcp_server from unity is already running.
2019-12-09 01:06:06,474; client.py - line: 140 -DEBUG: Socket can not connect. Make sure that the tcp_server from unity is already running.
2019-12-09 01:06:06,474; client.py - line: 141 -DEBUG: [Errno 103] Software caused connection abort
2019-12-09 01:06:06,474; client.py - line: 141 -DEBUG: [Errno 103] Software caused connection abort
2019-12-09 01:06:06,525; client.py - line: 149 -DEBUG: Try next port: 50039
2019-12-09 01:06:06,525; client.py - line: 149 -DEBUG: Try next port: 50039
2019-12-09 01:06:06,525; client.py - line: 140 -DEBUG: Socket can not connect. Make sure that the tcp_server from unity is already running.
2019-12-09 01:06:06,525; client.py - line: 140 -DEBUG: Socket can not connect. Make sure that the tcp_server from unity is already running.
2019-12-09 01:06:06,525; client.py - line: 141 -DEBUG: [Errno 111] Connection refused
2019-12-09 01:06:06,525; client.py - line: 141 -DEBUG: [Errno 111] Connection refused
2019-12-09 01:06:06,576; client.py - line: 149 -DEBUG: Try next port: 50040
2019-12-09 01:06:06,576; client.py - line: 149 -DEBUG: Try next port: 50040
2019-12-09 01:06:06,576; client.py - line: 140 -DEBUG: Socket can not connect. Make sure that the tcp_server from unity is already running.
2019-12-09 01:06:06,576; client.py - line: 140 -DEBUG: Socket can not connect. Make sure that the tcp_server from unity is already running.
2019-12-09 01:06:06,577; client.py - line: 141 -DEBUG: [Errno 103] Software caused connection abort
2019-12-09 01:06:06,577; client.py - line: 141 -DEBUG: [Errno 103] Software caused connection abort
2019-12-09 01:06:06,627; client.py - line: 149 -DEBUG: Try next port: 50041
2019-12-09 01:06:06,627; client.py - line: 149 -DEBUG: Try next port: 50041
2019-12-09 01:06:06,628; client.py - line: 140 -DEBUG: Socket can not connect. Make sure that the tcp_server from unity is already running.
2019-12-09 01:06:06,628; client.py - line: 140 -DEBUG: Socket can not connect. Make sure that the tcp_server from unity is already running.
2019-12-09 01:06:06,629; client.py - line: 141 -DEBUG: [Errno 111] Connection refused
2019-12-09 01:06:06,629; client.py - line: 141 -DEBUG: [Errno 111] Connection refused
2019-12-09 01:06:06,680; client.py - line: 149 -DEBUG: Try next port: 50042
2019-12-09 01:06:06,680; client.py - line: 149 -DEBUG: Try next port: 50042
2019-12-09 01:06:06,680; client.py - line: 140 -DEBUG: Socket can not connect. Make sure that the tcp_server from unity is already running.
2019-12-09 01:06:06,680; client.py - line: 140 -DEBUG: Socket can not connect. Make sure that the tcp_server from unity is already running.
2019-12-09 01:06:06,681; client.py - line: 141 -DEBUG: [Errno 103] Software caused connection abort
2019-12-09 01:06:06,681; client.py - line: 141 -DEBUG: [Errno 103] Software caused connection abort
2019-12-09 01:06:06,731; client.py - line: 149 -DEBUG: Try next port: 50043
2019-12-09 01:06:06,731; client.py - line: 149 -DEBUG: Try next port: 50043
2019-12-09 01:06:06,732; client.py - line: 140 -DEBUG: Socket can not connect. Make sure that the tcp_server from unity is already running.
2019-12-09 01:06:06,732; client.py - line: 140 -DEBUG: Socket can not connect. Make sure that the tcp_server from unity is already running.
2019-12-09 01:06:06,732; client.py - line: 141 -DEBUG: [Errno 111] Connection refused
2019-12-09 01:06:06,732; client.py - line: 141 -DEBUG: [Errno 111] Connection refused
2019-12-09 01:06:06,783; client.py - line: 149 -DEBUG: Try next port: 50044
2019-12-09 01:06:06,783; client.py - line: 149 -DEBUG: Try next port: 50044
2019-12-09 01:06:06,783; client.py - line: 140 -DEBUG: Socket can not connect. Make sure that the tcp_server from unity is already running.
2019-12-09 01:06:06,783; client.py - line: 140 -DEBUG: Socket can not connect. Make sure that the tcp_server from unity is already running.
2019-12-09 01:06:06,784; client.py - line: 141 -DEBUG: [Errno 103] Software caused connection abort
2019-12-09 01:06:06,784; client.py - line: 141 -DEBUG: [Errno 103] Software caused connection abort
2019-12-09 01:06:06,834; client.py - line: 149 -DEBUG: Try next port: 50045
2019-12-09 01:06:06,834; client.py - line: 149 -DEBUG: Try next port: 50045
2019-12-09 01:06:06,835; client.py - line: 140 -DEBUG: Socket can not connect. Make sure that the tcp_server from unity is already running.
2019-12-09 01:06:06,835; client.py - line: 140 -DEBUG: Socket can not connect. Make sure that the tcp_server from unity is already running.
2019-12-09 01:06:06,835; client.py - line: 141 -DEBUG: [Errno 111] Connection refused
2019-12-09 01:06:06,835; client.py - line: 141 -DEBUG: [Errno 111] Connection refused
2019-12-09 01:06:06,885; client.py - line: 149 -DEBUG: Try next port: 50046
2019-12-09 01:06:06,885; client.py - line: 149 -DEBUG: Try next port: 50046
2019-12-09 01:06:06,886; client.py - line: 140 -DEBUG: Socket can not connect. Make sure that the tcp_server from unity is already running.
2019-12-09 01:06:06,886; client.py - line: 140 -DEBUG: Socket can not connect. Make sure that the tcp_server from unity is already running.
2019-12-09 01:06:06,887; client.py - line: 141 -DEBUG: [Errno 103] Software caused connection abort
2019-12-09 01:06:06,887; client.py - line: 141 -DEBUG: [Errno 103] Software caused connection abort
2019-12-09 01:06:06,938; client.py - line: 149 -DEBUG: Try next port: 50047
2019-12-09 01:06:06,938; client.py - line: 149 -DEBUG: Try next port: 50047
2019-12-09 01:06:06,940; client.py - line: 140 -DEBUG: Socket can not connect. Make sure that the tcp_server from unity is already running.
2019-12-09 01:06:06,940; client.py - line: 140 -DEBUG: Socket can not connect. Make sure that the tcp_server from unity is already running.
2019-12-09 01:06:06,940; client.py - line: 141 -DEBUG: [Errno 111] Connection refused
2019-12-09 01:06:06,940; client.py - line: 141 -DEBUG: [Errno 111] Connection refused
2019-12-09 01:06:06,991; client.py - line: 149 -DEBUG: Try next port: 50048
2019-12-09 01:06:06,991; client.py - line: 149 -DEBUG: Try next port: 50048
2019-12-09 01:06:06,996; client.py - line: 140 -DEBUG: Socket can not connect. Make sure that the tcp_server from unity is already running.
2019-12-09 01:06:06,996; client.py - line: 140 -DEBUG: Socket can not connect. Make sure that the tcp_server from unity is already running.
2019-12-09 01:06:06,996; client.py - line: 141 -DEBUG: [Errno 103] Software caused connection abort
2019-12-09 01:06:06,996; client.py - line: 141 -DEBUG: [Errno 103] Software caused connection abort
2019-12-09 01:06:07,047; client.py - line: 149 -DEBUG: Try next port: 50049
2019-12-09 01:06:07,047; client.py - line: 149 -DEBUG: Try next port: 50049
2019-12-09 01:06:07,048; client.py - line: 140 -DEBUG: Socket can not connect. Make sure that the tcp_server from unity is already running.
2019-12-09 01:06:07,048; client.py - line: 140 -DEBUG: Socket can not connect. Make sure that the tcp_server from unity is already running.
2019-12-09 01:06:07,049; client.py - line: 141 -DEBUG: [Errno 111] Connection refused
2019-12-09 01:06:07,049; client.py - line: 141 -DEBUG: [Errno 111] Connection refused
2019-12-09 01:06:07,100; client.py - line: 149 -DEBUG: Try next port: 50050
2019-12-09 01:06:07,100; client.py - line: 149 -DEBUG: Try next port: 50050
2019-12-09 01:06:07,102; client.py - line: 140 -DEBUG: Socket can not connect. Make sure that the tcp_server from unity is already running.
2019-12-09 01:06:07,102; client.py - line: 140 -DEBUG: Socket can not connect. Make sure that the tcp_server from unity is already running.
2019-12-09 01:06:07,102; client.py - line: 141 -DEBUG: [Errno 103] Software caused connection abort
2019-12-09 01:06:07,102; client.py - line: 141 -DEBUG: [Errno 103] Software caused connection abort
2019-12-09 01:06:07,153; client.py - line: 149 -DEBUG: Try next port: 49990
2019-12-09 01:06:07,153; client.py - line: 149 -DEBUG: Try next port: 49990
2019-12-09 01:06:07,155; client.py - line: 140 -DEBUG: Socket can not connect. Make sure that the tcp_server from unity is already running.
2019-12-09 01:06:07,155; client.py - line: 140 -DEBUG: Socket can not connect. Make sure that the tcp_server from unity is already running.
2019-12-09 01:06:07,155; client.py - line: 141 -DEBUG: [Errno 111] Connection refused
2019-12-09 01:06:07,155; client.py - line: 141 -DEBUG: [Errno 111] Connection refused
2019-12-09 01:06:07,206; client.py - line: 149 -DEBUG: Try next port: 49991
2019-12-09 01:06:07,206; client.py - line: 149 -DEBUG: Try next port: 49991
2019-12-09 01:06:07,207; client.py - line: 140 -DEBUG: Socket can not connect. Make sure that the tcp_server from unity is already running.
2019-12-09 01:06:07,207; client.py - line: 140 -DEBUG: Socket can not connect. Make sure that the tcp_server from unity is already running.
2019-12-09 01:06:07,208; client.py - line: 141 -DEBUG: [Errno 103] Software caused connection abort
2019-12-09 01:06:07,208; client.py - line: 141 -DEBUG: [Errno 103] Software caused connection abort
2019-12-09 01:06:07,259; client.py - line: 149 -DEBUG: Try next port: 49992
2019-12-09 01:06:07,259; client.py - line: 149 -DEBUG: Try next port: 49992
2019-12-09 01:06:07,260; client.py - line: 140 -DEBUG: Socket can not connect. Make sure that the tcp_server from unity is already running.
2019-12-09 01:06:07,260; client.py - line: 140 -DEBUG: Socket can not connect. Make sure that the tcp_server from unity is already running.
2019-12-09 01:06:07,261; client.py - line: 141 -DEBUG: [Errno 111] Connection refused
2019-12-09 01:06:07,261; client.py - line: 141 -DEBUG: [Errno 111] Connection refused
2019-12-09 01:06:07,312; client.py - line: 149 -DEBUG: Try next port: 49993
2019-12-09 01:06:07,312; client.py - line: 149 -DEBUG: Try next port: 49993
2019-12-09 01:06:07,313; client.py - line: 140 -DEBUG: Socket can not connect. Make sure that the tcp_server from unity is already running.
2019-12-09 01:06:07,313; client.py - line: 140 -DEBUG: Socket can not connect. Make sure that the tcp_server from unity is already running.
2019-12-09 01:06:07,313; client.py - line: 141 -DEBUG: [Errno 103] Software caused connection abort
2019-12-09 01:06:07,313; client.py - line: 141 -DEBUG: [Errno 103] Software caused connection abort
2019-12-09 01:06:07,364; client.py - line: 149 -DEBUG: Try next port: 49994
2019-12-09 01:06:07,364; client.py - line: 149 -DEBUG: Try next port: 49994
2019-12-09 01:06:07,365; client.py - line: 140 -DEBUG: Socket can not connect. Make sure that the tcp_server from unity is already running.
2019-12-09 01:06:07,365; client.py - line: 140 -DEBUG: Socket can not connect. Make sure that the tcp_server from unity is already running.
2019-12-09 01:06:07,366; client.py - line: 141 -DEBUG: [Errno 111] Connection refused
2019-12-09 01:06:07,366; client.py - line: 141 -DEBUG: [Errno 111] Connection refused
2019-12-09 01:06:07,416; client.py - line: 149 -DEBUG: Try next port: 49995
2019-12-09 01:06:07,416; client.py - line: 149 -DEBUG: Try next port: 49995
2019-12-09 01:06:07,417; client.py - line: 140 -DEBUG: Socket can not connect. Make sure that the tcp_server from unity is already running.
2019-12-09 01:06:07,417; client.py - line: 140 -DEBUG: Socket can not connect. Make sure that the tcp_server from unity is already running.
2019-12-09 01:06:07,418; client.py - line: 141 -DEBUG: [Errno 103] Software caused connection abort
2019-12-09 01:06:07,418; client.py - line: 141 -DEBUG: [Errno 103] Software caused connection abort
2019-12-09 01:06:07,468; client.py - line: 149 -DEBUG: Try next port: 49996
2019-12-09 01:06:07,468; client.py - line: 149 -DEBUG: Try next port: 49996
2019-12-09 01:06:07,469; client.py - line: 140 -DEBUG: Socket can not connect. Make sure that the tcp_server from unity is already running.
2019-12-09 01:06:07,469; client.py - line: 140 -DEBUG: Socket can not connect. Make sure that the tcp_server from unity is already running.
2019-12-09 01:06:07,469; client.py - line: 141 -DEBUG: [Errno 111] Connection refused
2019-12-09 01:06:07,469; client.py - line: 141 -DEBUG: [Errno 111] Connection refused
2019-12-09 01:06:07,519; client.py - line: 149 -DEBUG: Try next port: 49997
2019-12-09 01:06:07,519; client.py - line: 149 -DEBUG: Try next port: 49997
2019-12-09 01:06:07,521; client.py - line: 140 -DEBUG: Socket can not connect. Make sure that the tcp_server from unity is already running.
2019-12-09 01:06:07,521; client.py - line: 140 -DEBUG: Socket can not connect. Make sure that the tcp_server from unity is already running.
2019-12-09 01:06:07,521; client.py - line: 141 -DEBUG: [Errno 103] Software caused connection abort
2019-12-09 01:06:07,521; client.py - line: 141 -DEBUG: [Errno 103] Software caused connection abort
2019-12-09 01:06:07,572; client.py - line: 149 -DEBUG: Try next port: 49998
2019-12-09 01:06:07,572; client.py - line: 149 -DEBUG: Try next port: 49998
2019-12-09 01:06:07,574; client.py - line: 140 -DEBUG: Socket can not connect. Make sure that the tcp_server from unity is already running.
2019-12-09 01:06:07,574; client.py - line: 140 -DEBUG: Socket can not connect. Make sure that the tcp_server from unity is already running.
2019-12-09 01:06:07,574; client.py - line: 141 -DEBUG: [Errno 111] Connection refused
2019-12-09 01:06:07,574; client.py - line: 141 -DEBUG: [Errno 111] Connection refused
2019-12-09 01:06:07,625; client.py - line: 149 -DEBUG: Try next port: 49999
2019-12-09 01:06:07,625; client.py - line: 149 -DEBUG: Try next port: 49999
2019-12-09 01:06:07,626; client.py - line: 140 -DEBUG: Socket can not connect. Make sure that the tcp_server from unity is already running.
2019-12-09 01:06:07,626; client.py - line: 140 -DEBUG: Socket can not connect. Make sure that the tcp_server from unity is already running.
2019-12-09 01:06:07,627; client.py - line: 141 -DEBUG: [Errno 103] Software caused connection abort
2019-12-09 01:06:07,627; client.py - line: 141 -DEBUG: [Errno 103] Software caused connection abort
2019-12-09 01:06:07,678; client.py - line: 149 -DEBUG: Try next port: 50000
2019-12-09 01:06:07,678; client.py - line: 149 -DEBUG: Try next port: 50000
2019-12-09 01:06:07,679; client.py - line: 140 -DEBUG: Socket can not connect. Make sure that the tcp_server from unity is already running.
2019-12-09 01:06:07,679; client.py - line: 140 -DEBUG: Socket can not connect. Make sure that the tcp_server from unity is already running.
2019-12-09 01:06:07,680; client.py - line: 141 -DEBUG: [Errno 111] Connection refused
2019-12-09 01:06:07,680; client.py - line: 141 -DEBUG: [Errno 111] Connection refused
2019-12-09 01:06:07,731; client.py - line: 149 -DEBUG: Try next port: 50001
2019-12-09 01:06:07,731; client.py - line: 149 -DEBUG: Try next port: 50001
2019-12-09 01:06:07,732; client.py - line: 140 -DEBUG: Socket can not connect. Make sure that the tcp_server from unity is already running.
2019-12-09 01:06:07,732; client.py - line: 140 -DEBUG: Socket can not connect. Make sure that the tcp_server from unity is already running.
2019-12-09 01:06:07,732; client.py - line: 141 -DEBUG: [Errno 103] Software caused connection abort
2019-12-09 01:06:07,732; client.py - line: 141 -DEBUG: [Errno 103] Software caused connection abort
2019-12-09 01:06:07,783; client.py - line: 149 -DEBUG: Try next port: 50002
2019-12-09 01:06:07,783; client.py - line: 149 -DEBUG: Try next port: 50002
2019-12-09 01:06:07,784; client.py - line: 140 -DEBUG: Socket can not connect. Make sure that the tcp_server from unity is already running.
2019-12-09 01:06:07,784; client.py - line: 140 -DEBUG: Socket can not connect. Make sure that the tcp_server from unity is already running.
2019-12-09 01:06:07,785; client.py - line: 141 -DEBUG: [Errno 111] Connection refused
2019-12-09 01:06:07,785; client.py - line: 141 -DEBUG: [Errno 111] Connection refused
2019-12-09 01:06:07,837; client.py - line: 149 -DEBUG: Try next port: 50003
2019-12-09 01:06:07,837; client.py - line: 149 -DEBUG: Try next port: 50003
2019-12-09 01:06:07,838; client.py - line: 140 -DEBUG: Socket can not connect. Make sure that the tcp_server from unity is already running.
2019-12-09 01:06:07,838; client.py - line: 140 -DEBUG: Socket can not connect. Make sure that the tcp_server from unity is already running.
2019-12-09 01:06:07,839; client.py - line: 141 -DEBUG: [Errno 103] Software caused connection abort
2019-12-09 01:06:07,839; client.py - line: 141 -DEBUG: [Errno 103] Software caused connection abort
2019-12-09 01:06:07,889; client.py - line: 149 -DEBUG: Try next port: 50004
2019-12-09 01:06:07,889; client.py - line: 149 -DEBUG: Try next port: 50004
2019-12-09 01:06:07,891; client.py - line: 140 -DEBUG: Socket can not connect. Make sure that the tcp_server from unity is already running.
2019-12-09 01:06:07,891; client.py - line: 140 -DEBUG: Socket can not connect. Make sure that the tcp_server from unity is already running.
2019-12-09 01:06:07,891; client.py - line: 141 -DEBUG: [Errno 111] Connection refused
2019-12-09 01:06:07,891; client.py - line: 141 -DEBUG: [Errno 111] Connection refused
2019-12-09 01:06:07,942; client.py - line: 149 -DEBUG: Try next port: 50005
2019-12-09 01:06:07,942; client.py - line: 149 -DEBUG: Try next port: 50005
2019-12-09 01:06:07,943; client.py - line: 140 -DEBUG: Socket can not connect. Make sure that the tcp_server from unity is already running.
2019-12-09 01:06:07,943; client.py - line: 140 -DEBUG: Socket can not connect. Make sure that the tcp_server from unity is already running.
2019-12-09 01:06:07,944; client.py - line: 141 -DEBUG: [Errno 103] Software caused connection abort
2019-12-09 01:06:07,944; client.py - line: 141 -DEBUG: [Errno 103] Software caused connection abort
2019-12-09 01:06:07,994; client.py - line: 149 -DEBUG: Try next port: 50006
2019-12-09 01:06:07,994; client.py - line: 149 -DEBUG: Try next port: 50006
2019-12-09 01:06:07,996; client.py - line: 140 -DEBUG: Socket can not connect. Make sure that the tcp_server from unity is already running.
2019-12-09 01:06:07,996; client.py - line: 140 -DEBUG: Socket can not connect. Make sure that the tcp_server from unity is already running.
2019-12-09 01:06:07,996; client.py - line: 141 -DEBUG: [Errno 111] Connection refused
2019-12-09 01:06:07,996; client.py - line: 141 -DEBUG: [Errno 111] Connection refused
2019-12-09 01:06:08,047; client.py - line: 149 -DEBUG: Try next port: 50007
2019-12-09 01:06:08,047; client.py - line: 149 -DEBUG: Try next port: 50007
2019-12-09 01:06:08,048; client.py - line: 140 -DEBUG: Socket can not connect. Make sure that the tcp_server from unity is already running.
2019-12-09 01:06:08,048; client.py - line: 140 -DEBUG: Socket can not connect. Make sure that the tcp_server from unity is already running.
2019-12-09 01:06:08,049; client.py - line: 141 -DEBUG: [Errno 103] Software caused connection abort
2019-12-09 01:06:08,049; client.py - line: 141 -DEBUG: [Errno 103] Software caused connection abort
2019-12-09 01:06:08,100; client.py - line: 149 -DEBUG: Try next port: 50008
2019-12-09 01:06:08,100; client.py - line: 149 -DEBUG: Try next port: 50008
2019-12-09 01:06:08,101; client.py - line: 140 -DEBUG: Socket can not connect. Make sure that the tcp_server from unity is already running.
2019-12-09 01:06:08,101; client.py - line: 140 -DEBUG: Socket can not connect. Make sure that the tcp_server from unity is already running.
2019-12-09 01:06:08,102; client.py - line: 141 -DEBUG: [Errno 111] Connection refused
2019-12-09 01:06:08,102; client.py - line: 141 -DEBUG: [Errno 111] Connection refused
2019-12-09 01:06:08,153; client.py - line: 149 -DEBUG: Try next port: 50009
2019-12-09 01:06:08,153; client.py - line: 149 -DEBUG: Try next port: 50009
2019-12-09 01:06:08,154; client.py - line: 140 -DEBUG: Socket can not connect. Make sure that the tcp_server from unity is already running.
2019-12-09 01:06:08,154; client.py - line: 140 -DEBUG: Socket can not connect. Make sure that the tcp_server from unity is already running.
2019-12-09 01:06:08,154; client.py - line: 141 -DEBUG: [Errno 103] Software caused connection abort
2019-12-09 01:06:08,154; client.py - line: 141 -DEBUG: [Errno 103] Software caused connection abort
2019-12-09 01:06:08,205; client.py - line: 149 -DEBUG: Try next port: 50010
2019-12-09 01:06:08,205; client.py - line: 149 -DEBUG: Try next port: 50010
2019-12-09 01:06:08,207; client.py - line: 140 -DEBUG: Socket can not connect. Make sure that the tcp_server from unity is already running.
2019-12-09 01:06:08,207; client.py - line: 140 -DEBUG: Socket can not connect. Make sure that the tcp_server from unity is already running.
2019-12-09 01:06:08,208; client.py - line: 141 -DEBUG: [Errno 111] Connection refused
2019-12-09 01:06:08,208; client.py - line: 141 -DEBUG: [Errno 111] Connection refused
2019-12-09 01:06:08,259; client.py - line: 149 -DEBUG: Try next port: 50011
2019-12-09 01:06:08,259; client.py - line: 149 -DEBUG: Try next port: 50011
2019-12-09 01:06:08,260; client.py - line: 140 -DEBUG: Socket can not connect. Make sure that the tcp_server from unity is already running.
2019-12-09 01:06:08,260; client.py - line: 140 -DEBUG: Socket can not connect. Make sure that the tcp_server from unity is already running.
2019-12-09 01:06:08,261; client.py - line: 141 -DEBUG: [Errno 103] Software caused connection abort
2019-12-09 01:06:08,261; client.py - line: 141 -DEBUG: [Errno 103] Software caused connection abort
2019-12-09 01:06:08,312; client.py - line: 149 -DEBUG: Try next port: 50012
2019-12-09 01:06:08,312; client.py - line: 149 -DEBUG: Try next port: 50012
2019-12-09 01:06:08,313; client.py - line: 140 -DEBUG: Socket can not connect. Make sure that the tcp_server from unity is already running.
2019-12-09 01:06:08,313; client.py - line: 140 -DEBUG: Socket can not connect. Make sure that the tcp_server from unity is already running.
2019-12-09 01:06:08,314; client.py - line: 141 -DEBUG: [Errno 111] Connection refused
2019-12-09 01:06:08,314; client.py - line: 141 -DEBUG: [Errno 111] Connection refused
2019-12-09 01:06:08,365; client.py - line: 149 -DEBUG: Try next port: 50013
2019-12-09 01:06:08,365; client.py - line: 149 -DEBUG: Try next port: 50013
2019-12-09 01:06:08,366; client.py - line: 140 -DEBUG: Socket can not connect. Make sure that the tcp_server from unity is already running.
2019-12-09 01:06:08,366; client.py - line: 140 -DEBUG: Socket can not connect. Make sure that the tcp_server from unity is already running.
2019-12-09 01:06:08,367; client.py - line: 141 -DEBUG: [Errno 103] Software caused connection abort
2019-12-09 01:06:08,367; client.py - line: 141 -DEBUG: [Errno 103] Software caused connection abort
2019-12-09 01:06:08,418; client.py - line: 149 -DEBUG: Try next port: 50014
2019-12-09 01:06:08,418; client.py - line: 149 -DEBUG: Try next port: 50014
2019-12-09 01:06:08,419; client.py - line: 140 -DEBUG: Socket can not connect. Make sure that the tcp_server from unity is already running.
2019-12-09 01:06:08,419; client.py - line: 140 -DEBUG: Socket can not connect. Make sure that the tcp_server from unity is already running.
2019-12-09 01:06:08,419; client.py - line: 141 -DEBUG: [Errno 111] Connection refused
2019-12-09 01:06:08,419; client.py - line: 141 -DEBUG: [Errno 111] Connection refused
2019-12-09 01:06:08,470; client.py - line: 149 -DEBUG: Try next port: 50015
2019-12-09 01:06:08,470; client.py - line: 149 -DEBUG: Try next port: 50015
2019-12-09 01:06:08,471; client.py - line: 140 -DEBUG: Socket can not connect. Make sure that the tcp_server from unity is already running.
2019-12-09 01:06:08,471; client.py - line: 140 -DEBUG: Socket can not connect. Make sure that the tcp_server from unity is already running.
2019-12-09 01:06:08,472; client.py - line: 141 -DEBUG: [Errno 103] Software caused connection abort
2019-12-09 01:06:08,472; client.py - line: 141 -DEBUG: [Errno 103] Software caused connection abort
2019-12-09 01:06:08,523; client.py - line: 149 -DEBUG: Try next port: 50016
2019-12-09 01:06:08,523; client.py - line: 149 -DEBUG: Try next port: 50016
2019-12-09 01:06:08,525; client.py - line: 140 -DEBUG: Socket can not connect. Make sure that the tcp_server from unity is already running.
2019-12-09 01:06:08,525; client.py - line: 140 -DEBUG: Socket can not connect. Make sure that the tcp_server from unity is already running.
2019-12-09 01:06:08,525; client.py - line: 141 -DEBUG: [Errno 111] Connection refused
2019-12-09 01:06:08,525; client.py - line: 141 -DEBUG: [Errno 111] Connection refused
2019-12-09 01:06:08,576; client.py - line: 149 -DEBUG: Try next port: 50017
2019-12-09 01:06:08,576; client.py - line: 149 -DEBUG: Try next port: 50017
2019-12-09 01:06:08,577; client.py - line: 140 -DEBUG: Socket can not connect. Make sure that the tcp_server from unity is already running.
2019-12-09 01:06:08,577; client.py - line: 140 -DEBUG: Socket can not connect. Make sure that the tcp_server from unity is already running.
2019-12-09 01:06:08,578; client.py - line: 141 -DEBUG: [Errno 103] Software caused connection abort
2019-12-09 01:06:08,578; client.py - line: 141 -DEBUG: [Errno 103] Software caused connection abort
2019-12-09 01:06:08,629; client.py - line: 149 -DEBUG: Try next port: 50018
2019-12-09 01:06:08,629; client.py - line: 149 -DEBUG: Try next port: 50018
2019-12-09 01:06:08,630; client.py - line: 140 -DEBUG: Socket can not connect. Make sure that the tcp_server from unity is already running.
2019-12-09 01:06:08,630; client.py - line: 140 -DEBUG: Socket can not connect. Make sure that the tcp_server from unity is already running.
2019-12-09 01:06:08,630; client.py - line: 141 -DEBUG: [Errno 111] Connection refused
2019-12-09 01:06:08,630; client.py - line: 141 -DEBUG: [Errno 111] Connection refused
2019-12-09 01:06:08,681; client.py - line: 149 -DEBUG: Try next port: 50019
2019-12-09 01:06:08,681; client.py - line: 149 -DEBUG: Try next port: 50019
2019-12-09 01:06:08,682; client.py - line: 140 -DEBUG: Socket can not connect. Make sure that the tcp_server from unity is already running.
2019-12-09 01:06:08,682; client.py - line: 140 -DEBUG: Socket can not connect. Make sure that the tcp_server from unity is already running.
2019-12-09 01:06:08,683; client.py - line: 141 -DEBUG: [Errno 103] Software caused connection abort
2019-12-09 01:06:08,683; client.py - line: 141 -DEBUG: [Errno 103] Software caused connection abort
2019-12-09 01:06:08,733; client.py - line: 149 -DEBUG: Try next port: 50020
2019-12-09 01:06:08,733; client.py - line: 149 -DEBUG: Try next port: 50020
2019-12-09 01:06:08,735; client.py - line: 140 -DEBUG: Socket can not connect. Make sure that the tcp_server from unity is already running.
2019-12-09 01:06:08,735; client.py - line: 140 -DEBUG: Socket can not connect. Make sure that the tcp_server from unity is already running.
2019-12-09 01:06:08,735; client.py - line: 141 -DEBUG: [Errno 111] Connection refused
2019-12-09 01:06:08,735; client.py - line: 141 -DEBUG: [Errno 111] Connection refused
2019-12-09 01:06:08,786; client.py - line: 149 -DEBUG: Try next port: 50021
2019-12-09 01:06:08,786; client.py - line: 149 -DEBUG: Try next port: 50021
2019-12-09 01:06:08,787; client.py - line: 140 -DEBUG: Socket can not connect. Make sure that the tcp_server from unity is already running.
2019-12-09 01:06:08,787; client.py - line: 140 -DEBUG: Socket can not connect. Make sure that the tcp_server from unity is already running.
2019-12-09 01:06:08,788; client.py - line: 141 -DEBUG: [Errno 103] Software caused connection abort
2019-12-09 01:06:08,788; client.py - line: 141 -DEBUG: [Errno 103] Software caused connection abort
2019-12-09 01:06:08,839; client.py - line: 149 -DEBUG: Try next port: 50022
2019-12-09 01:06:08,839; client.py - line: 149 -DEBUG: Try next port: 50022
2019-12-09 01:06:08,840; client.py - line: 140 -DEBUG: Socket can not connect. Make sure that the tcp_server from unity is already running.
2019-12-09 01:06:08,840; client.py - line: 140 -DEBUG: Socket can not connect. Make sure that the tcp_server from unity is already running.
2019-12-09 01:06:08,841; client.py - line: 141 -DEBUG: [Errno 111] Connection refused
2019-12-09 01:06:08,841; client.py - line: 141 -DEBUG: [Errno 111] Connection refused
2019-12-09 01:06:08,891; client.py - line: 149 -DEBUG: Try next port: 50023
2019-12-09 01:06:08,891; client.py - line: 149 -DEBUG: Try next port: 50023
2019-12-09 01:06:08,892; client.py - line: 140 -DEBUG: Socket can not connect. Make sure that the tcp_server from unity is already running.
2019-12-09 01:06:08,892; client.py - line: 140 -DEBUG: Socket can not connect. Make sure that the tcp_server from unity is already running.
2019-12-09 01:06:08,893; client.py - line: 141 -DEBUG: [Errno 103] Software caused connection abort
2019-12-09 01:06:08,893; client.py - line: 141 -DEBUG: [Errno 103] Software caused connection abort
2019-12-09 01:06:08,944; client.py - line: 149 -DEBUG: Try next port: 50024
2019-12-09 01:06:08,944; client.py - line: 149 -DEBUG: Try next port: 50024
2019-12-09 01:06:08,945; client.py - line: 140 -DEBUG: Socket can not connect. Make sure that the tcp_server from unity is already running.
2019-12-09 01:06:08,945; client.py - line: 140 -DEBUG: Socket can not connect. Make sure that the tcp_server from unity is already running.
2019-12-09 01:06:08,945; client.py - line: 141 -DEBUG: [Errno 111] Connection refused
2019-12-09 01:06:08,945; client.py - line: 141 -DEBUG: [Errno 111] Connection refused
2019-12-09 01:06:08,996; client.py - line: 149 -DEBUG: Try next port: 50025
2019-12-09 01:06:08,996; client.py - line: 149 -DEBUG: Try next port: 50025
2019-12-09 01:06:08,997; client.py - line: 140 -DEBUG: Socket can not connect. Make sure that the tcp_server from unity is already running.
2019-12-09 01:06:08,997; client.py - line: 140 -DEBUG: Socket can not connect. Make sure that the tcp_server from unity is already running.
2019-12-09 01:06:08,998; client.py - line: 141 -DEBUG: [Errno 103] Software caused connection abort
2019-12-09 01:06:08,998; client.py - line: 141 -DEBUG: [Errno 103] Software caused connection abort
2019-12-09 01:06:09,049; client.py - line: 149 -DEBUG: Try next port: 50026
2019-12-09 01:06:09,049; client.py - line: 149 -DEBUG: Try next port: 50026
2019-12-09 01:06:09,050; client.py - line: 140 -DEBUG: Socket can not connect. Make sure that the tcp_server from unity is already running.
2019-12-09 01:06:09,050; client.py - line: 140 -DEBUG: Socket can not connect. Make sure that the tcp_server from unity is already running.
2019-12-09 01:06:09,051; client.py - line: 141 -DEBUG: [Errno 111] Connection refused
2019-12-09 01:06:09,051; client.py - line: 141 -DEBUG: [Errno 111] Connection refused
2019-12-09 01:06:09,101; client.py - line: 149 -DEBUG: Try next port: 50027
2019-12-09 01:06:09,101; client.py - line: 149 -DEBUG: Try next port: 50027
2019-12-09 01:06:09,102; client.py - line: 140 -DEBUG: Socket can not connect. Make sure that the tcp_server from unity is already running.
2019-12-09 01:06:09,102; client.py - line: 140 -DEBUG: Socket can not connect. Make sure that the tcp_server from unity is already running.
2019-12-09 01:06:09,103; client.py - line: 141 -DEBUG: [Errno 103] Software caused connection abort
2019-12-09 01:06:09,103; client.py - line: 141 -DEBUG: [Errno 103] Software caused connection abort
2019-12-09 01:06:09,154; client.py - line: 149 -DEBUG: Try next port: 50028
2019-12-09 01:06:09,154; client.py - line: 149 -DEBUG: Try next port: 50028
2019-12-09 01:06:09,156; client.py - line: 140 -DEBUG: Socket can not connect. Make sure that the tcp_server from unity is already running.
2019-12-09 01:06:09,156; client.py - line: 140 -DEBUG: Socket can not connect. Make sure that the tcp_server from unity is already running.
2019-12-09 01:06:09,157; client.py - line: 141 -DEBUG: [Errno 111] Connection refused
2019-12-09 01:06:09,157; client.py - line: 141 -DEBUG: [Errno 111] Connection refused
2019-12-09 01:06:09,208; client.py - line: 149 -DEBUG: Try next port: 50029
2019-12-09 01:06:09,208; client.py - line: 149 -DEBUG: Try next port: 50029
2019-12-09 01:06:09,209; client.py - line: 140 -DEBUG: Socket can not connect. Make sure that the tcp_server from unity is already running.
2019-12-09 01:06:09,209; client.py - line: 140 -DEBUG: Socket can not connect. Make sure that the tcp_server from unity is already running.
2019-12-09 01:06:09,210; client.py - line: 141 -DEBUG: [Errno 103] Software caused connection abort
2019-12-09 01:06:09,210; client.py - line: 141 -DEBUG: [Errno 103] Software caused connection abort
2019-12-09 01:06:09,261; client.py - line: 149 -DEBUG: Try next port: 50030
2019-12-09 01:06:09,261; client.py - line: 149 -DEBUG: Try next port: 50030
2019-12-09 01:06:09,261; client.py - line: 140 -DEBUG: Socket can not connect. Make sure that the tcp_server from unity is already running.
2019-12-09 01:06:09,261; client.py - line: 140 -DEBUG: Socket can not connect. Make sure that the tcp_server from unity is already running.
2019-12-09 01:06:09,262; client.py - line: 141 -DEBUG: [Errno 111] Connection refused
2019-12-09 01:06:09,262; client.py - line: 141 -DEBUG: [Errno 111] Connection refused
2019-12-09 01:06:09,313; client.py - line: 149 -DEBUG: Try next port: 50031
2019-12-09 01:06:09,313; client.py - line: 149 -DEBUG: Try next port: 50031
2019-12-09 01:06:09,313; client.py - line: 140 -DEBUG: Socket can not connect. Make sure that the tcp_server from unity is already running.
2019-12-09 01:06:09,313; client.py - line: 140 -DEBUG: Socket can not connect. Make sure that the tcp_server from unity is already running.
2019-12-09 01:06:09,314; client.py - line: 141 -DEBUG: [Errno 103] Software caused connection abort
2019-12-09 01:06:09,314; client.py - line: 141 -DEBUG: [Errno 103] Software caused connection abort
2019-12-09 01:06:09,365; client.py - line: 149 -DEBUG: Try next port: 50032
2019-12-09 01:06:09,365; client.py - line: 149 -DEBUG: Try next port: 50032
2019-12-09 01:06:09,366; client.py - line: 140 -DEBUG: Socket can not connect. Make sure that the tcp_server from unity is already running.
2019-12-09 01:06:09,366; client.py - line: 140 -DEBUG: Socket can not connect. Make sure that the tcp_server from unity is already running.
2019-12-09 01:06:09,366; client.py - line: 141 -DEBUG: [Errno 111] Connection refused
2019-12-09 01:06:09,366; client.py - line: 141 -DEBUG: [Errno 111] Connection refused
2019-12-09 01:06:09,417; client.py - line: 149 -DEBUG: Try next port: 50033
2019-12-09 01:06:09,417; client.py - line: 149 -DEBUG: Try next port: 50033
2019-12-09 01:06:09,418; client.py - line: 140 -DEBUG: Socket can not connect. Make sure that the tcp_server from unity is already running.
2019-12-09 01:06:09,418; client.py - line: 140 -DEBUG: Socket can not connect. Make sure that the tcp_server from unity is already running.
2019-12-09 01:06:09,419; client.py - line: 141 -DEBUG: [Errno 103] Software caused connection abort
2019-12-09 01:06:09,419; client.py - line: 141 -DEBUG: [Errno 103] Software caused connection abort
2019-12-09 01:06:09,470; client.py - line: 149 -DEBUG: Try next port: 50034
2019-12-09 01:06:09,470; client.py - line: 149 -DEBUG: Try next port: 50034
2019-12-09 01:06:09,471; client.py - line: 140 -DEBUG: Socket can not connect. Make sure that the tcp_server from unity is already running.
2019-12-09 01:06:09,471; client.py - line: 140 -DEBUG: Socket can not connect. Make sure that the tcp_server from unity is already running.
2019-12-09 01:06:09,471; client.py - line: 141 -DEBUG: [Errno 111] Connection refused
2019-12-09 01:06:09,471; client.py - line: 141 -DEBUG: [Errno 111] Connection refused
2019-12-09 01:06:09,522; client.py - line: 149 -DEBUG: Try next port: 50035
2019-12-09 01:06:09,522; client.py - line: 149 -DEBUG: Try next port: 50035
2019-12-09 01:06:09,524; client.py - line: 140 -DEBUG: Socket can not connect. Make sure that the tcp_server from unity is already running.
2019-12-09 01:06:09,524; client.py - line: 140 -DEBUG: Socket can not connect. Make sure that the tcp_server from unity is already running.
2019-12-09 01:06:09,525; client.py - line: 141 -DEBUG: [Errno 103] Software caused connection abort
2019-12-09 01:06:09,525; client.py - line: 141 -DEBUG: [Errno 103] Software caused connection abort
2019-12-09 01:06:09,576; client.py - line: 149 -DEBUG: Try next port: 50036
2019-12-09 01:06:09,576; client.py - line: 149 -DEBUG: Try next port: 50036
2019-12-09 01:06:09,577; client.py - line: 140 -DEBUG: Socket can not connect. Make sure that the tcp_server from unity is already running.
2019-12-09 01:06:09,577; client.py - line: 140 -DEBUG: Socket can not connect. Make sure that the tcp_server from unity is already running.
2019-12-09 01:06:09,578; client.py - line: 141 -DEBUG: [Errno 111] Connection refused
2019-12-09 01:06:09,578; client.py - line: 141 -DEBUG: [Errno 111] Connection refused
2019-12-09 01:06:09,629; client.py - line: 149 -DEBUG: Try next port: 50037
2019-12-09 01:06:09,629; client.py - line: 149 -DEBUG: Try next port: 50037
2019-12-09 01:06:09,630; client.py - line: 140 -DEBUG: Socket can not connect. Make sure that the tcp_server from unity is already running.
2019-12-09 01:06:09,630; client.py - line: 140 -DEBUG: Socket can not connect. Make sure that the tcp_server from unity is already running.
2019-12-09 01:06:09,631; client.py - line: 141 -DEBUG: [Errno 103] Software caused connection abort
2019-12-09 01:06:09,631; client.py - line: 141 -DEBUG: [Errno 103] Software caused connection abort
2019-12-09 01:06:09,682; client.py - line: 149 -DEBUG: Try next port: 50038
2019-12-09 01:06:09,682; client.py - line: 149 -DEBUG: Try next port: 50038
2019-12-09 01:06:09,683; client.py - line: 140 -DEBUG: Socket can not connect. Make sure that the tcp_server from unity is already running.
2019-12-09 01:06:09,683; client.py - line: 140 -DEBUG: Socket can not connect. Make sure that the tcp_server from unity is already running.
2019-12-09 01:06:09,684; client.py - line: 141 -DEBUG: [Errno 111] Connection refused
2019-12-09 01:06:09,684; client.py - line: 141 -DEBUG: [Errno 111] Connection refused
2019-12-09 01:06:09,735; client.py - line: 149 -DEBUG: Try next port: 50039
2019-12-09 01:06:09,735; client.py - line: 149 -DEBUG: Try next port: 50039
2019-12-09 01:06:09,736; client.py - line: 140 -DEBUG: Socket can not connect. Make sure that the tcp_server from unity is already running.
2019-12-09 01:06:09,736; client.py - line: 140 -DEBUG: Socket can not connect. Make sure that the tcp_server from unity is already running.
2019-12-09 01:06:09,736; client.py - line: 141 -DEBUG: [Errno 103] Software caused connection abort
2019-12-09 01:06:09,736; client.py - line: 141 -DEBUG: [Errno 103] Software caused connection abort
2019-12-09 01:06:09,787; client.py - line: 149 -DEBUG: Try next port: 50040
2019-12-09 01:06:09,787; client.py - line: 149 -DEBUG: Try next port: 50040
2019-12-09 01:06:09,788; client.py - line: 140 -DEBUG: Socket can not connect. Make sure that the tcp_server from unity is already running.
2019-12-09 01:06:09,788; client.py - line: 140 -DEBUG: Socket can not connect. Make sure that the tcp_server from unity is already running.
2019-12-09 01:06:09,789; client.py - line: 141 -DEBUG: [Errno 111] Connection refused
2019-12-09 01:06:09,789; client.py - line: 141 -DEBUG: [Errno 111] Connection refused
2019-12-09 01:06:09,840; client.py - line: 149 -DEBUG: Try next port: 50041
2019-12-09 01:06:09,840; client.py - line: 149 -DEBUG: Try next port: 50041
2019-12-09 01:06:09,841; client.py - line: 140 -DEBUG: Socket can not connect. Make sure that the tcp_server from unity is already running.
2019-12-09 01:06:09,841; client.py - line: 140 -DEBUG: Socket can not connect. Make sure that the tcp_server from unity is already running.
2019-12-09 01:06:09,842; client.py - line: 141 -DEBUG: [Errno 103] Software caused connection abort
2019-12-09 01:06:09,842; client.py - line: 141 -DEBUG: [Errno 103] Software caused connection abort
2019-12-09 01:06:09,894; client.py - line: 149 -DEBUG: Try next port: 50042
2019-12-09 01:06:09,894; client.py - line: 149 -DEBUG: Try next port: 50042
2019-12-09 01:06:09,895; client.py - line: 140 -DEBUG: Socket can not connect. Make sure that the tcp_server from unity is already running.
2019-12-09 01:06:09,895; client.py - line: 140 -DEBUG: Socket can not connect. Make sure that the tcp_server from unity is already running.
2019-12-09 01:06:09,896; client.py - line: 141 -DEBUG: [Errno 111] Connection refused
2019-12-09 01:06:09,896; client.py - line: 141 -DEBUG: [Errno 111] Connection refused
2019-12-09 01:06:09,946; client.py - line: 149 -DEBUG: Try next port: 50043
2019-12-09 01:06:09,946; client.py - line: 149 -DEBUG: Try next port: 50043
2019-12-09 01:06:09,947; client.py - line: 140 -DEBUG: Socket can not connect. Make sure that the tcp_server from unity is already running.
2019-12-09 01:06:09,947; client.py - line: 140 -DEBUG: Socket can not connect. Make sure that the tcp_server from unity is already running.
2019-12-09 01:06:09,948; client.py - line: 141 -DEBUG: [Errno 103] Software caused connection abort
2019-12-09 01:06:09,948; client.py - line: 141 -DEBUG: [Errno 103] Software caused connection abort
2019-12-09 01:06:09,999; client.py - line: 149 -DEBUG: Try next port: 50044
2019-12-09 01:06:09,999; client.py - line: 149 -DEBUG: Try next port: 50044
2019-12-09 01:06:10,000; client.py - line: 140 -DEBUG: Socket can not connect. Make sure that the tcp_server from unity is already running.
2019-12-09 01:06:10,000; client.py - line: 140 -DEBUG: Socket can not connect. Make sure that the tcp_server from unity is already running.
2019-12-09 01:06:10,000; client.py - line: 141 -DEBUG: [Errno 111] Connection refused
2019-12-09 01:06:10,000; client.py - line: 141 -DEBUG: [Errno 111] Connection refused
2019-12-09 01:06:10,051; client.py - line: 149 -DEBUG: Try next port: 50045
2019-12-09 01:06:10,051; client.py - line: 149 -DEBUG: Try next port: 50045
2019-12-09 01:06:10,052; client.py - line: 140 -DEBUG: Socket can not connect. Make sure that the tcp_server from unity is already running.
2019-12-09 01:06:10,052; client.py - line: 140 -DEBUG: Socket can not connect. Make sure that the tcp_server from unity is already running.
2019-12-09 01:06:10,053; client.py - line: 141 -DEBUG: [Errno 103] Software caused connection abort
2019-12-09 01:06:10,053; client.py - line: 141 -DEBUG: [Errno 103] Software caused connection abort
2019-12-09 01:06:10,104; client.py - line: 149 -DEBUG: Try next port: 50046
2019-12-09 01:06:10,104; client.py - line: 149 -DEBUG: Try next port: 50046
2019-12-09 01:06:10,106; client.py - line: 140 -DEBUG: Socket can not connect. Make sure that the tcp_server from unity is already running.
2019-12-09 01:06:10,106; client.py - line: 140 -DEBUG: Socket can not connect. Make sure that the tcp_server from unity is already running.
2019-12-09 01:06:10,107; client.py - line: 141 -DEBUG: [Errno 111] Connection refused
2019-12-09 01:06:10,107; client.py - line: 141 -DEBUG: [Errno 111] Connection refused
2019-12-09 01:06:10,158; client.py - line: 149 -DEBUG: Try next port: 50047
2019-12-09 01:06:10,158; client.py - line: 149 -DEBUG: Try next port: 50047
2019-12-09 01:06:10,159; client.py - line: 140 -DEBUG: Socket can not connect. Make sure that the tcp_server from unity is already running.
2019-12-09 01:06:10,159; client.py - line: 140 -DEBUG: Socket can not connect. Make sure that the tcp_server from unity is already running.
2019-12-09 01:06:10,160; client.py - line: 141 -DEBUG: [Errno 103] Software caused connection abort
2019-12-09 01:06:10,160; client.py - line: 141 -DEBUG: [Errno 103] Software caused connection abort
2019-12-09 01:06:10,211; client.py - line: 149 -DEBUG: Try next port: 50048
2019-12-09 01:06:10,211; client.py - line: 149 -DEBUG: Try next port: 50048
2019-12-09 01:06:10,212; client.py - line: 140 -DEBUG: Socket can not connect. Make sure that the tcp_server from unity is already running.
2019-12-09 01:06:10,212; client.py - line: 140 -DEBUG: Socket can not connect. Make sure that the tcp_server from unity is already running.
2019-12-09 01:06:10,212; client.py - line: 141 -DEBUG: [Errno 111] Connection refused
2019-12-09 01:06:10,212; client.py - line: 141 -DEBUG: [Errno 111] Connection refused
2019-12-09 01:06:10,263; client.py - line: 149 -DEBUG: Try next port: 50049
2019-12-09 01:06:10,263; client.py - line: 149 -DEBUG: Try next port: 50049
2019-12-09 01:06:10,264; client.py - line: 140 -DEBUG: Socket can not connect. Make sure that the tcp_server from unity is already running.
2019-12-09 01:06:10,264; client.py - line: 140 -DEBUG: Socket can not connect. Make sure that the tcp_server from unity is already running.
2019-12-09 01:06:10,265; client.py - line: 141 -DEBUG: [Errno 103] Software caused connection abort
2019-12-09 01:06:10,265; client.py - line: 141 -DEBUG: [Errno 103] Software caused connection abort
2019-12-09 01:06:10,315; client.py - line: 149 -DEBUG: Try next port: 50050
2019-12-09 01:06:10,315; client.py - line: 149 -DEBUG: Try next port: 50050
2019-12-09 01:06:10,317; client.py - line: 136 -INFO: Socket connected.
2019-12-09 01:06:10,317; client.py - line: 136 -INFO: Socket connected.
2019-12-09 01:06:10,317; client.py - line: 137 -DEBUG: Saving TCP config to self.relative_path_TCPsocket_config.

2019-12-09 01:06:10,317; client.py - line: 137 -DEBUG: Saving TCP config to self.relative_path_TCPsocket_config.

2019-12-09 01:06:10,322; dataset.py - line: 53 -DEBUG: Create config.
2019-12-09 01:06:10,322; dataset.py - line: 53 -DEBUG: Create config.
2019-12-09 01:06:10,323; dataset.py - line: 63 -DEBUG: Dataset initialised.

2019-12-09 01:06:10,323; dataset.py - line: 63 -DEBUG: Dataset initialised.

2019-12-09 01:06:10,326; dataset.py - line: 396 -DEBUG: total_branches: [1]
2019-12-09 01:06:10,326; dataset.py - line: 396 -DEBUG: total_branches: [1]
2019-12-09 01:06:10,329; client.py - line: 193 -DEBUG: Json string sent.

2019-12-09 01:06:10,329; client.py - line: 193 -DEBUG: Json string sent.

2019-12-09 01:06:10,330; client.py - line: 234 -DEBUG: Json string sent.

2019-12-09 01:06:10,330; client.py - line: 234 -DEBUG: Json string sent.

2019-12-09 01:06:10,432; client.py - line: 209 -DEBUG: Timeout -> exit _receiveData()
2019-12-09 01:06:10,432; client.py - line: 209 -DEBUG: Timeout -> exit _receiveData()
2019-12-09 01:06:10,432; client.py - line: 210 -DEBUG: data_complete: type: <class 'bytearray'>, data_complete len: 1, data_complete [:10]: bytearray(b'\x00')
2019-12-09 01:06:10,432; client.py - line: 210 -DEBUG: data_complete: type: <class 'bytearray'>, data_complete len: 1, data_complete [:10]: bytearray(b'\x00')
2019-12-09 01:06:10,432; client.py - line: 240 -DEBUG: Trying to receive data.
2019-12-09 01:06:10,432; client.py - line: 240 -DEBUG: Trying to receive data.
2019-12-09 01:06:10,592; client.py - line: 209 -DEBUG: Timeout -> exit _receiveData()
2019-12-09 01:06:10,592; client.py - line: 209 -DEBUG: Timeout -> exit _receiveData()
2019-12-09 01:06:10,592; client.py - line: 210 -DEBUG: data_complete: type: <class 'bytearray'>, data_complete len: 46218, data_complete [:10]: bytearray(b'\x00\x89PNG\r\n\x1a\n\x00')
2019-12-09 01:06:10,592; client.py - line: 210 -DEBUG: data_complete: type: <class 'bytearray'>, data_complete len: 46218, data_complete [:10]: bytearray(b'\x00\x89PNG\r\n\x1a\n\x00')
2019-12-09 01:06:10,592; client.py - line: 240 -DEBUG: Trying to receive data.
2019-12-09 01:06:10,592; client.py - line: 240 -DEBUG: Trying to receive data.
2019-12-09 01:06:10,593; client.py - line: 243 -INFO: Data from Unity received.
2019-12-09 01:06:10,593; client.py - line: 243 -INFO: Data from Unity received.
2019-12-09 01:06:10,593; client.py - line: 244 -DEBUG: End_tag detected, unity_resp_bytes[0:10]: bytearray(b'\x00\x89PNG\r\n\x1a\n\x00')
2019-12-09 01:06:10,593; client.py - line: 244 -DEBUG: End_tag detected, unity_resp_bytes[0:10]: bytearray(b'\x00\x89PNG\r\n\x1a\n\x00')
2019-12-09 01:06:10,594; client.py - line: 248 -DEBUG: img_bytes type: <class 'bytearray'>, img_bytes len: 46209, img_bytes[:10]: bytearray(b'\x89PNG\r\n\x1a\n\x00\x00')
2019-12-09 01:06:10,594; client.py - line: 248 -DEBUG: img_bytes type: <class 'bytearray'>, img_bytes len: 46209, img_bytes[:10]: bytearray(b'\x89PNG\r\n\x1a\n\x00\x00')
2019-12-09 01:06:10,595; client.py - line: 251 -DEBUG: PIL Img: type: <class 'PIL.PngImagePlugin.PngImageFile'> 
2019-12-09 01:06:10,595; client.py - line: 251 -DEBUG: PIL Img: type: <class 'PIL.PngImagePlugin.PngImageFile'> 
2019-12-09 01:06:10,615; client.py - line: 253 -DEBUG: Returning img: type: <class 'numpy.ndarray'> 

2019-12-09 01:06:10,615; client.py - line: 253 -DEBUG: Returning img: type: <class 'numpy.ndarray'> 

2019-12-09 01:06:10,615; dataset.py - line: 921 -DEBUG: index: 9
2019-12-09 01:06:10,615; dataset.py - line: 921 -DEBUG: index: 9
2019-12-09 01:06:10,616; dataset.py - line: 923 -DEBUG: index: 10
2019-12-09 01:06:10,616; dataset.py - line: 923 -DEBUG: index: 10
2019-12-09 01:06:10,681; dataset.py - line: 396 -DEBUG: total_branches: [1]
2019-12-09 01:06:10,681; dataset.py - line: 396 -DEBUG: total_branches: [1]
2019-12-09 01:06:10,682; client.py - line: 193 -DEBUG: Json string sent.

2019-12-09 01:06:10,682; client.py - line: 193 -DEBUG: Json string sent.

2019-12-09 01:06:10,682; client.py - line: 234 -DEBUG: Json string sent.

2019-12-09 01:06:10,682; client.py - line: 234 -DEBUG: Json string sent.

2019-12-09 01:06:10,782; client.py - line: 209 -DEBUG: Timeout -> exit _receiveData()
2019-12-09 01:06:10,782; client.py - line: 209 -DEBUG: Timeout -> exit _receiveData()
2019-12-09 01:06:10,782; client.py - line: 210 -DEBUG: data_complete: type: <class 'bytearray'>, data_complete len: 1, data_complete [:10]: bytearray(b'\x00')
2019-12-09 01:06:10,782; client.py - line: 210 -DEBUG: data_complete: type: <class 'bytearray'>, data_complete len: 1, data_complete [:10]: bytearray(b'\x00')
2019-12-09 01:06:10,783; client.py - line: 240 -DEBUG: Trying to receive data.
2019-12-09 01:06:10,783; client.py - line: 240 -DEBUG: Trying to receive data.
2019-12-09 01:06:10,897; client.py - line: 209 -DEBUG: Timeout -> exit _receiveData()
2019-12-09 01:06:10,897; client.py - line: 209 -DEBUG: Timeout -> exit _receiveData()
2019-12-09 01:06:10,898; client.py - line: 210 -DEBUG: data_complete: type: <class 'bytearray'>, data_complete len: 79497, data_complete [:10]: bytearray(b'\x00\x89PNG\r\n\x1a\n\x00')
2019-12-09 01:06:10,898; client.py - line: 210 -DEBUG: data_complete: type: <class 'bytearray'>, data_complete len: 79497, data_complete [:10]: bytearray(b'\x00\x89PNG\r\n\x1a\n\x00')
2019-12-09 01:06:10,898; client.py - line: 240 -DEBUG: Trying to receive data.
2019-12-09 01:06:10,898; client.py - line: 240 -DEBUG: Trying to receive data.
2019-12-09 01:06:10,899; client.py - line: 243 -INFO: Data from Unity received.
2019-12-09 01:06:10,899; client.py - line: 243 -INFO: Data from Unity received.
2019-12-09 01:06:10,899; client.py - line: 244 -DEBUG: End_tag detected, unity_resp_bytes[0:10]: bytearray(b'\x00\x89PNG\r\n\x1a\n\x00')
2019-12-09 01:06:10,899; client.py - line: 244 -DEBUG: End_tag detected, unity_resp_bytes[0:10]: bytearray(b'\x00\x89PNG\r\n\x1a\n\x00')
2019-12-09 01:06:10,900; client.py - line: 248 -DEBUG: img_bytes type: <class 'bytearray'>, img_bytes len: 79488, img_bytes[:10]: bytearray(b'\x89PNG\r\n\x1a\n\x00\x00')
2019-12-09 01:06:10,900; client.py - line: 248 -DEBUG: img_bytes type: <class 'bytearray'>, img_bytes len: 79488, img_bytes[:10]: bytearray(b'\x89PNG\r\n\x1a\n\x00\x00')
2019-12-09 01:06:10,901; client.py - line: 251 -DEBUG: PIL Img: type: <class 'PIL.PngImagePlugin.PngImageFile'> 
2019-12-09 01:06:10,901; client.py - line: 251 -DEBUG: PIL Img: type: <class 'PIL.PngImagePlugin.PngImageFile'> 
2019-12-09 01:06:10,921; client.py - line: 253 -DEBUG: Returning img: type: <class 'numpy.ndarray'> 

2019-12-09 01:06:10,921; client.py - line: 253 -DEBUG: Returning img: type: <class 'numpy.ndarray'> 

2019-12-09 01:06:10,922; dataset.py - line: 921 -DEBUG: index: 10
2019-12-09 01:06:10,922; dataset.py - line: 921 -DEBUG: index: 10
2019-12-09 01:06:10,922; dataset.py - line: 923 -DEBUG: index: 11
2019-12-09 01:06:10,922; dataset.py - line: 923 -DEBUG: index: 11
2019-12-09 01:06:10,969; dataset.py - line: 396 -DEBUG: total_branches: [1]
2019-12-09 01:06:10,969; dataset.py - line: 396 -DEBUG: total_branches: [1]
2019-12-09 01:06:10,970; client.py - line: 193 -DEBUG: Json string sent.

2019-12-09 01:06:10,970; client.py - line: 193 -DEBUG: Json string sent.

2019-12-09 01:06:10,970; client.py - line: 234 -DEBUG: Json string sent.

2019-12-09 01:06:10,970; client.py - line: 234 -DEBUG: Json string sent.

2019-12-09 01:06:11,071; client.py - line: 209 -DEBUG: Timeout -> exit _receiveData()
2019-12-09 01:06:11,071; client.py - line: 209 -DEBUG: Timeout -> exit _receiveData()
2019-12-09 01:06:11,071; client.py - line: 210 -DEBUG: data_complete: type: <class 'bytearray'>, data_complete len: 1, data_complete [:10]: bytearray(b'\x00')
2019-12-09 01:06:11,071; client.py - line: 210 -DEBUG: data_complete: type: <class 'bytearray'>, data_complete len: 1, data_complete [:10]: bytearray(b'\x00')
2019-12-09 01:06:11,071; client.py - line: 240 -DEBUG: Trying to receive data.
2019-12-09 01:06:11,071; client.py - line: 240 -DEBUG: Trying to receive data.
2019-12-09 01:06:11,181; client.py - line: 209 -DEBUG: Timeout -> exit _receiveData()
2019-12-09 01:06:11,181; client.py - line: 209 -DEBUG: Timeout -> exit _receiveData()
2019-12-09 01:06:11,183; client.py - line: 210 -DEBUG: data_complete: type: <class 'bytearray'>, data_complete len: 54476, data_complete [:10]: bytearray(b'\x00\x89PNG\r\n\x1a\n\x00')
2019-12-09 01:06:11,183; client.py - line: 210 -DEBUG: data_complete: type: <class 'bytearray'>, data_complete len: 54476, data_complete [:10]: bytearray(b'\x00\x89PNG\r\n\x1a\n\x00')
2019-12-09 01:06:11,184; client.py - line: 240 -DEBUG: Trying to receive data.
2019-12-09 01:06:11,184; client.py - line: 240 -DEBUG: Trying to receive data.
2019-12-09 01:06:11,185; client.py - line: 243 -INFO: Data from Unity received.
2019-12-09 01:06:11,185; client.py - line: 243 -INFO: Data from Unity received.
2019-12-09 01:06:11,186; client.py - line: 244 -DEBUG: End_tag detected, unity_resp_bytes[0:10]: bytearray(b'\x00\x89PNG\r\n\x1a\n\x00')
2019-12-09 01:06:11,186; client.py - line: 244 -DEBUG: End_tag detected, unity_resp_bytes[0:10]: bytearray(b'\x00\x89PNG\r\n\x1a\n\x00')
2019-12-09 01:06:11,187; client.py - line: 248 -DEBUG: img_bytes type: <class 'bytearray'>, img_bytes len: 54467, img_bytes[:10]: bytearray(b'\x89PNG\r\n\x1a\n\x00\x00')
2019-12-09 01:06:11,187; client.py - line: 248 -DEBUG: img_bytes type: <class 'bytearray'>, img_bytes len: 54467, img_bytes[:10]: bytearray(b'\x89PNG\r\n\x1a\n\x00\x00')
2019-12-09 01:06:11,189; client.py - line: 251 -DEBUG: PIL Img: type: <class 'PIL.PngImagePlugin.PngImageFile'> 
2019-12-09 01:06:11,189; client.py - line: 251 -DEBUG: PIL Img: type: <class 'PIL.PngImagePlugin.PngImageFile'> 
2019-12-09 01:06:11,219; client.py - line: 253 -DEBUG: Returning img: type: <class 'numpy.ndarray'> 

2019-12-09 01:06:11,219; client.py - line: 253 -DEBUG: Returning img: type: <class 'numpy.ndarray'> 

2019-12-09 01:06:11,220; dataset.py - line: 921 -DEBUG: index: 11
2019-12-09 01:06:11,220; dataset.py - line: 921 -DEBUG: index: 11
2019-12-09 01:06:11,220; dataset.py - line: 923 -DEBUG: index: 12
2019-12-09 01:06:11,220; dataset.py - line: 923 -DEBUG: index: 12
2019-12-09 01:06:11,260; dataset.py - line: 396 -DEBUG: total_branches: [1]
2019-12-09 01:06:11,260; dataset.py - line: 396 -DEBUG: total_branches: [1]
2019-12-09 01:06:11,261; client.py - line: 193 -DEBUG: Json string sent.

2019-12-09 01:06:11,261; client.py - line: 193 -DEBUG: Json string sent.

2019-12-09 01:06:11,261; client.py - line: 234 -DEBUG: Json string sent.

2019-12-09 01:06:11,261; client.py - line: 234 -DEBUG: Json string sent.

2019-12-09 01:06:11,443; client.py - line: 209 -DEBUG: Timeout -> exit _receiveData()
2019-12-09 01:06:11,443; client.py - line: 209 -DEBUG: Timeout -> exit _receiveData()
2019-12-09 01:06:11,444; client.py - line: 210 -DEBUG: data_complete: type: <class 'bytearray'>, data_complete len: 46972, data_complete [:10]: bytearray(b'\x00\x89PNG\r\n\x1a\n\x00')
2019-12-09 01:06:11,444; client.py - line: 210 -DEBUG: data_complete: type: <class 'bytearray'>, data_complete len: 46972, data_complete [:10]: bytearray(b'\x00\x89PNG\r\n\x1a\n\x00')
2019-12-09 01:06:11,445; client.py - line: 240 -DEBUG: Trying to receive data.
2019-12-09 01:06:11,445; client.py - line: 240 -DEBUG: Trying to receive data.
2019-12-09 01:06:11,446; client.py - line: 243 -INFO: Data from Unity received.
2019-12-09 01:06:11,446; client.py - line: 243 -INFO: Data from Unity received.
2019-12-09 01:06:11,446; client.py - line: 244 -DEBUG: End_tag detected, unity_resp_bytes[0:10]: bytearray(b'\x00\x89PNG\r\n\x1a\n\x00')
2019-12-09 01:06:11,446; client.py - line: 244 -DEBUG: End_tag detected, unity_resp_bytes[0:10]: bytearray(b'\x00\x89PNG\r\n\x1a\n\x00')
2019-12-09 01:06:11,447; client.py - line: 248 -DEBUG: img_bytes type: <class 'bytearray'>, img_bytes len: 46963, img_bytes[:10]: bytearray(b'\x89PNG\r\n\x1a\n\x00\x00')
2019-12-09 01:06:11,447; client.py - line: 248 -DEBUG: img_bytes type: <class 'bytearray'>, img_bytes len: 46963, img_bytes[:10]: bytearray(b'\x89PNG\r\n\x1a\n\x00\x00')
2019-12-09 01:06:11,449; client.py - line: 251 -DEBUG: PIL Img: type: <class 'PIL.PngImagePlugin.PngImageFile'> 
2019-12-09 01:06:11,449; client.py - line: 251 -DEBUG: PIL Img: type: <class 'PIL.PngImagePlugin.PngImageFile'> 
2019-12-09 01:06:11,470; client.py - line: 253 -DEBUG: Returning img: type: <class 'numpy.ndarray'> 

2019-12-09 01:06:11,470; client.py - line: 253 -DEBUG: Returning img: type: <class 'numpy.ndarray'> 

2019-12-09 01:06:11,470; dataset.py - line: 921 -DEBUG: index: 12
2019-12-09 01:06:11,470; dataset.py - line: 921 -DEBUG: index: 12
2019-12-09 01:06:11,471; dataset.py - line: 923 -DEBUG: index: 13
2019-12-09 01:06:11,471; dataset.py - line: 923 -DEBUG: index: 13
2019-12-09 01:06:11,500; dataset.py - line: 396 -DEBUG: total_branches: [1]
2019-12-09 01:06:11,500; dataset.py - line: 396 -DEBUG: total_branches: [1]
2019-12-09 01:06:11,500; client.py - line: 193 -DEBUG: Json string sent.

2019-12-09 01:06:11,500; client.py - line: 193 -DEBUG: Json string sent.

2019-12-09 01:06:11,501; client.py - line: 234 -DEBUG: Json string sent.

2019-12-09 01:06:11,501; client.py - line: 234 -DEBUG: Json string sent.

2019-12-09 01:06:11,601; client.py - line: 209 -DEBUG: Timeout -> exit _receiveData()
2019-12-09 01:06:11,601; client.py - line: 209 -DEBUG: Timeout -> exit _receiveData()
2019-12-09 01:06:11,601; client.py - line: 210 -DEBUG: data_complete: type: <class 'bytearray'>, data_complete len: 1, data_complete [:10]: bytearray(b'\x00')
2019-12-09 01:06:11,601; client.py - line: 210 -DEBUG: data_complete: type: <class 'bytearray'>, data_complete len: 1, data_complete [:10]: bytearray(b'\x00')
2019-12-09 01:06:11,601; client.py - line: 240 -DEBUG: Trying to receive data.
2019-12-09 01:06:11,601; client.py - line: 240 -DEBUG: Trying to receive data.
2019-12-09 01:06:11,708; client.py - line: 209 -DEBUG: Timeout -> exit _receiveData()
2019-12-09 01:06:11,708; client.py - line: 209 -DEBUG: Timeout -> exit _receiveData()
2019-12-09 01:06:11,709; client.py - line: 210 -DEBUG: data_complete: type: <class 'bytearray'>, data_complete len: 78439, data_complete [:10]: bytearray(b'\x00\x89PNG\r\n\x1a\n\x00')
2019-12-09 01:06:11,709; client.py - line: 210 -DEBUG: data_complete: type: <class 'bytearray'>, data_complete len: 78439, data_complete [:10]: bytearray(b'\x00\x89PNG\r\n\x1a\n\x00')
2019-12-09 01:06:11,709; client.py - line: 240 -DEBUG: Trying to receive data.
2019-12-09 01:06:11,709; client.py - line: 240 -DEBUG: Trying to receive data.
2019-12-09 01:06:11,710; client.py - line: 243 -INFO: Data from Unity received.
2019-12-09 01:06:11,710; client.py - line: 243 -INFO: Data from Unity received.
2019-12-09 01:06:11,711; client.py - line: 244 -DEBUG: End_tag detected, unity_resp_bytes[0:10]: bytearray(b'\x00\x89PNG\r\n\x1a\n\x00')
2019-12-09 01:06:11,711; client.py - line: 244 -DEBUG: End_tag detected, unity_resp_bytes[0:10]: bytearray(b'\x00\x89PNG\r\n\x1a\n\x00')
2019-12-09 01:06:11,711; client.py - line: 248 -DEBUG: img_bytes type: <class 'bytearray'>, img_bytes len: 78430, img_bytes[:10]: bytearray(b'\x89PNG\r\n\x1a\n\x00\x00')
2019-12-09 01:06:11,711; client.py - line: 248 -DEBUG: img_bytes type: <class 'bytearray'>, img_bytes len: 78430, img_bytes[:10]: bytearray(b'\x89PNG\r\n\x1a\n\x00\x00')
2019-12-09 01:06:11,712; client.py - line: 251 -DEBUG: PIL Img: type: <class 'PIL.PngImagePlugin.PngImageFile'> 
2019-12-09 01:06:11,712; client.py - line: 251 -DEBUG: PIL Img: type: <class 'PIL.PngImagePlugin.PngImageFile'> 
2019-12-09 01:06:11,736; client.py - line: 253 -DEBUG: Returning img: type: <class 'numpy.ndarray'> 

2019-12-09 01:06:11,736; client.py - line: 253 -DEBUG: Returning img: type: <class 'numpy.ndarray'> 

2019-12-09 01:06:11,736; dataset.py - line: 921 -DEBUG: index: 13
2019-12-09 01:06:11,736; dataset.py - line: 921 -DEBUG: index: 13
2019-12-09 01:06:11,737; dataset.py - line: 923 -DEBUG: index: 14
2019-12-09 01:06:11,737; dataset.py - line: 923 -DEBUG: index: 14
2019-12-09 01:06:11,780; dataset.py - line: 396 -DEBUG: total_branches: [1]
2019-12-09 01:06:11,780; dataset.py - line: 396 -DEBUG: total_branches: [1]
2019-12-09 01:06:11,781; client.py - line: 193 -DEBUG: Json string sent.

2019-12-09 01:06:11,781; client.py - line: 193 -DEBUG: Json string sent.

2019-12-09 01:06:11,781; client.py - line: 234 -DEBUG: Json string sent.

2019-12-09 01:06:11,781; client.py - line: 234 -DEBUG: Json string sent.

2019-12-09 01:06:11,944; client.py - line: 209 -DEBUG: Timeout -> exit _receiveData()
2019-12-09 01:06:11,944; client.py - line: 209 -DEBUG: Timeout -> exit _receiveData()
2019-12-09 01:06:11,945; client.py - line: 210 -DEBUG: data_complete: type: <class 'bytearray'>, data_complete len: 39310, data_complete [:10]: bytearray(b'\x00\x89PNG\r\n\x1a\n\x00')
2019-12-09 01:06:11,945; client.py - line: 210 -DEBUG: data_complete: type: <class 'bytearray'>, data_complete len: 39310, data_complete [:10]: bytearray(b'\x00\x89PNG\r\n\x1a\n\x00')
2019-12-09 01:06:11,945; client.py - line: 240 -DEBUG: Trying to receive data.
2019-12-09 01:06:11,945; client.py - line: 240 -DEBUG: Trying to receive data.
2019-12-09 01:06:11,945; client.py - line: 243 -INFO: Data from Unity received.
2019-12-09 01:06:11,945; client.py - line: 243 -INFO: Data from Unity received.
2019-12-09 01:06:11,945; client.py - line: 244 -DEBUG: End_tag detected, unity_resp_bytes[0:10]: bytearray(b'\x00\x89PNG\r\n\x1a\n\x00')
2019-12-09 01:06:11,945; client.py - line: 244 -DEBUG: End_tag detected, unity_resp_bytes[0:10]: bytearray(b'\x00\x89PNG\r\n\x1a\n\x00')
2019-12-09 01:06:11,945; client.py - line: 248 -DEBUG: img_bytes type: <class 'bytearray'>, img_bytes len: 39301, img_bytes[:10]: bytearray(b'\x89PNG\r\n\x1a\n\x00\x00')
2019-12-09 01:06:11,945; client.py - line: 248 -DEBUG: img_bytes type: <class 'bytearray'>, img_bytes len: 39301, img_bytes[:10]: bytearray(b'\x89PNG\r\n\x1a\n\x00\x00')
2019-12-09 01:06:11,946; client.py - line: 251 -DEBUG: PIL Img: type: <class 'PIL.PngImagePlugin.PngImageFile'> 
2019-12-09 01:06:11,946; client.py - line: 251 -DEBUG: PIL Img: type: <class 'PIL.PngImagePlugin.PngImageFile'> 
2019-12-09 01:06:11,957; client.py - line: 253 -DEBUG: Returning img: type: <class 'numpy.ndarray'> 

2019-12-09 01:06:11,957; client.py - line: 253 -DEBUG: Returning img: type: <class 'numpy.ndarray'> 

2019-12-09 01:06:11,957; dataset.py - line: 921 -DEBUG: index: 14
2019-12-09 01:06:11,957; dataset.py - line: 921 -DEBUG: index: 14
2019-12-09 01:06:11,957; dataset.py - line: 923 -DEBUG: index: 15
2019-12-09 01:06:11,957; dataset.py - line: 923 -DEBUG: index: 15
2019-12-09 01:06:11,982; dataset.py - line: 396 -DEBUG: total_branches: [1]
2019-12-09 01:06:11,982; dataset.py - line: 396 -DEBUG: total_branches: [1]
2019-12-09 01:06:11,983; client.py - line: 193 -DEBUG: Json string sent.

2019-12-09 01:06:11,983; client.py - line: 193 -DEBUG: Json string sent.

2019-12-09 01:06:11,983; client.py - line: 234 -DEBUG: Json string sent.

2019-12-09 01:06:11,983; client.py - line: 234 -DEBUG: Json string sent.

2019-12-09 01:06:12,165; client.py - line: 209 -DEBUG: Timeout -> exit _receiveData()
2019-12-09 01:06:12,165; client.py - line: 209 -DEBUG: Timeout -> exit _receiveData()
2019-12-09 01:06:12,166; client.py - line: 210 -DEBUG: data_complete: type: <class 'bytearray'>, data_complete len: 45391, data_complete [:10]: bytearray(b'\x00\x89PNG\r\n\x1a\n\x00')
2019-12-09 01:06:12,166; client.py - line: 210 -DEBUG: data_complete: type: <class 'bytearray'>, data_complete len: 45391, data_complete [:10]: bytearray(b'\x00\x89PNG\r\n\x1a\n\x00')
2019-12-09 01:06:12,166; client.py - line: 240 -DEBUG: Trying to receive data.
2019-12-09 01:06:12,166; client.py - line: 240 -DEBUG: Trying to receive data.
2019-12-09 01:06:12,167; client.py - line: 243 -INFO: Data from Unity received.
2019-12-09 01:06:12,167; client.py - line: 243 -INFO: Data from Unity received.
2019-12-09 01:06:12,168; client.py - line: 244 -DEBUG: End_tag detected, unity_resp_bytes[0:10]: bytearray(b'\x00\x89PNG\r\n\x1a\n\x00')
2019-12-09 01:06:12,168; client.py - line: 244 -DEBUG: End_tag detected, unity_resp_bytes[0:10]: bytearray(b'\x00\x89PNG\r\n\x1a\n\x00')
2019-12-09 01:06:12,169; client.py - line: 248 -DEBUG: img_bytes type: <class 'bytearray'>, img_bytes len: 45382, img_bytes[:10]: bytearray(b'\x89PNG\r\n\x1a\n\x00\x00')
2019-12-09 01:06:12,169; client.py - line: 248 -DEBUG: img_bytes type: <class 'bytearray'>, img_bytes len: 45382, img_bytes[:10]: bytearray(b'\x89PNG\r\n\x1a\n\x00\x00')
2019-12-09 01:06:12,171; client.py - line: 251 -DEBUG: PIL Img: type: <class 'PIL.PngImagePlugin.PngImageFile'> 
2019-12-09 01:06:12,171; client.py - line: 251 -DEBUG: PIL Img: type: <class 'PIL.PngImagePlugin.PngImageFile'> 
2019-12-09 01:06:12,190; client.py - line: 253 -DEBUG: Returning img: type: <class 'numpy.ndarray'> 

2019-12-09 01:06:12,190; client.py - line: 253 -DEBUG: Returning img: type: <class 'numpy.ndarray'> 

2019-12-09 01:06:12,191; dataset.py - line: 921 -DEBUG: index: 15
2019-12-09 01:06:12,191; dataset.py - line: 921 -DEBUG: index: 15
2019-12-09 01:06:12,191; dataset.py - line: 923 -DEBUG: index: 16
2019-12-09 01:06:12,191; dataset.py - line: 923 -DEBUG: index: 16
2019-12-09 01:06:12,218; dataset.py - line: 396 -DEBUG: total_branches: [1]
2019-12-09 01:06:12,218; dataset.py - line: 396 -DEBUG: total_branches: [1]
2019-12-09 01:06:12,219; client.py - line: 193 -DEBUG: Json string sent.

2019-12-09 01:06:12,219; client.py - line: 193 -DEBUG: Json string sent.

2019-12-09 01:06:12,219; client.py - line: 234 -DEBUG: Json string sent.

2019-12-09 01:06:12,219; client.py - line: 234 -DEBUG: Json string sent.

2019-12-09 01:06:12,395; client.py - line: 209 -DEBUG: Timeout -> exit _receiveData()
2019-12-09 01:06:12,395; client.py - line: 209 -DEBUG: Timeout -> exit _receiveData()
2019-12-09 01:06:12,396; client.py - line: 210 -DEBUG: data_complete: type: <class 'bytearray'>, data_complete len: 39198, data_complete [:10]: bytearray(b'\x00\x89PNG\r\n\x1a\n\x00')
2019-12-09 01:06:12,396; client.py - line: 210 -DEBUG: data_complete: type: <class 'bytearray'>, data_complete len: 39198, data_complete [:10]: bytearray(b'\x00\x89PNG\r\n\x1a\n\x00')
2019-12-09 01:06:12,397; client.py - line: 240 -DEBUG: Trying to receive data.
2019-12-09 01:06:12,397; client.py - line: 240 -DEBUG: Trying to receive data.
2019-12-09 01:06:12,397; client.py - line: 243 -INFO: Data from Unity received.
2019-12-09 01:06:12,397; client.py - line: 243 -INFO: Data from Unity received.
2019-12-09 01:06:12,398; client.py - line: 244 -DEBUG: End_tag detected, unity_resp_bytes[0:10]: bytearray(b'\x00\x89PNG\r\n\x1a\n\x00')
2019-12-09 01:06:12,398; client.py - line: 244 -DEBUG: End_tag detected, unity_resp_bytes[0:10]: bytearray(b'\x00\x89PNG\r\n\x1a\n\x00')
2019-12-09 01:06:12,398; client.py - line: 248 -DEBUG: img_bytes type: <class 'bytearray'>, img_bytes len: 39189, img_bytes[:10]: bytearray(b'\x89PNG\r\n\x1a\n\x00\x00')
2019-12-09 01:06:12,398; client.py - line: 248 -DEBUG: img_bytes type: <class 'bytearray'>, img_bytes len: 39189, img_bytes[:10]: bytearray(b'\x89PNG\r\n\x1a\n\x00\x00')
2019-12-09 01:06:12,399; client.py - line: 251 -DEBUG: PIL Img: type: <class 'PIL.PngImagePlugin.PngImageFile'> 
2019-12-09 01:06:12,399; client.py - line: 251 -DEBUG: PIL Img: type: <class 'PIL.PngImagePlugin.PngImageFile'> 
2019-12-09 01:06:12,418; client.py - line: 253 -DEBUG: Returning img: type: <class 'numpy.ndarray'> 

2019-12-09 01:06:12,418; client.py - line: 253 -DEBUG: Returning img: type: <class 'numpy.ndarray'> 

2019-12-09 01:06:12,418; dataset.py - line: 921 -DEBUG: index: 16
2019-12-09 01:06:12,418; dataset.py - line: 921 -DEBUG: index: 16
2019-12-09 01:06:12,418; dataset.py - line: 923 -DEBUG: index: 17
2019-12-09 01:06:12,418; dataset.py - line: 923 -DEBUG: index: 17
2019-12-09 01:06:12,447; dataset.py - line: 396 -DEBUG: total_branches: [1]
2019-12-09 01:06:12,447; dataset.py - line: 396 -DEBUG: total_branches: [1]
2019-12-09 01:06:12,447; client.py - line: 193 -DEBUG: Json string sent.

2019-12-09 01:06:12,447; client.py - line: 193 -DEBUG: Json string sent.

2019-12-09 01:06:12,448; client.py - line: 234 -DEBUG: Json string sent.

2019-12-09 01:06:12,448; client.py - line: 234 -DEBUG: Json string sent.

2019-12-09 01:06:12,548; client.py - line: 209 -DEBUG: Timeout -> exit _receiveData()
2019-12-09 01:06:12,548; client.py - line: 209 -DEBUG: Timeout -> exit _receiveData()
2019-12-09 01:06:12,549; client.py - line: 210 -DEBUG: data_complete: type: <class 'bytearray'>, data_complete len: 1, data_complete [:10]: bytearray(b'\x00')
2019-12-09 01:06:12,549; client.py - line: 210 -DEBUG: data_complete: type: <class 'bytearray'>, data_complete len: 1, data_complete [:10]: bytearray(b'\x00')
2019-12-09 01:06:12,550; client.py - line: 240 -DEBUG: Trying to receive data.
2019-12-09 01:06:12,550; client.py - line: 240 -DEBUG: Trying to receive data.
2019-12-09 01:06:12,668; client.py - line: 209 -DEBUG: Timeout -> exit _receiveData()
2019-12-09 01:06:12,668; client.py - line: 209 -DEBUG: Timeout -> exit _receiveData()
2019-12-09 01:06:12,669; client.py - line: 210 -DEBUG: data_complete: type: <class 'bytearray'>, data_complete len: 60931, data_complete [:10]: bytearray(b'\x00\x89PNG\r\n\x1a\n\x00')
2019-12-09 01:06:12,669; client.py - line: 210 -DEBUG: data_complete: type: <class 'bytearray'>, data_complete len: 60931, data_complete [:10]: bytearray(b'\x00\x89PNG\r\n\x1a\n\x00')
2019-12-09 01:06:12,670; client.py - line: 240 -DEBUG: Trying to receive data.
2019-12-09 01:06:12,670; client.py - line: 240 -DEBUG: Trying to receive data.
2019-12-09 01:06:12,670; client.py - line: 243 -INFO: Data from Unity received.
2019-12-09 01:06:12,670; client.py - line: 243 -INFO: Data from Unity received.
2019-12-09 01:06:12,671; client.py - line: 244 -DEBUG: End_tag detected, unity_resp_bytes[0:10]: bytearray(b'\x00\x89PNG\r\n\x1a\n\x00')
2019-12-09 01:06:12,671; client.py - line: 244 -DEBUG: End_tag detected, unity_resp_bytes[0:10]: bytearray(b'\x00\x89PNG\r\n\x1a\n\x00')
2019-12-09 01:06:12,672; client.py - line: 248 -DEBUG: img_bytes type: <class 'bytearray'>, img_bytes len: 60922, img_bytes[:10]: bytearray(b'\x89PNG\r\n\x1a\n\x00\x00')
2019-12-09 01:06:12,672; client.py - line: 248 -DEBUG: img_bytes type: <class 'bytearray'>, img_bytes len: 60922, img_bytes[:10]: bytearray(b'\x89PNG\r\n\x1a\n\x00\x00')
2019-12-09 01:06:12,674; client.py - line: 251 -DEBUG: PIL Img: type: <class 'PIL.PngImagePlugin.PngImageFile'> 
2019-12-09 01:06:12,674; client.py - line: 251 -DEBUG: PIL Img: type: <class 'PIL.PngImagePlugin.PngImageFile'> 
2019-12-09 01:06:12,714; client.py - line: 253 -DEBUG: Returning img: type: <class 'numpy.ndarray'> 

2019-12-09 01:06:12,714; client.py - line: 253 -DEBUG: Returning img: type: <class 'numpy.ndarray'> 

2019-12-09 01:06:12,716; dataset.py - line: 921 -DEBUG: index: 17
2019-12-09 01:06:12,716; dataset.py - line: 921 -DEBUG: index: 17
2019-12-09 01:06:12,716; dataset.py - line: 923 -DEBUG: index: 18
2019-12-09 01:06:12,716; dataset.py - line: 923 -DEBUG: index: 18
2019-12-09 01:06:12,790; dataset.py - line: 396 -DEBUG: total_branches: [1]
2019-12-09 01:06:12,790; dataset.py - line: 396 -DEBUG: total_branches: [1]
2019-12-09 01:06:12,791; client.py - line: 193 -DEBUG: Json string sent.

2019-12-09 01:06:12,791; client.py - line: 193 -DEBUG: Json string sent.

2019-12-09 01:06:12,791; client.py - line: 234 -DEBUG: Json string sent.

2019-12-09 01:06:12,791; client.py - line: 234 -DEBUG: Json string sent.

2019-12-09 01:06:12,966; client.py - line: 209 -DEBUG: Timeout -> exit _receiveData()
2019-12-09 01:06:12,966; client.py - line: 209 -DEBUG: Timeout -> exit _receiveData()
2019-12-09 01:06:12,967; client.py - line: 210 -DEBUG: data_complete: type: <class 'bytearray'>, data_complete len: 45866, data_complete [:10]: bytearray(b'\x00\x89PNG\r\n\x1a\n\x00')
2019-12-09 01:06:12,967; client.py - line: 210 -DEBUG: data_complete: type: <class 'bytearray'>, data_complete len: 45866, data_complete [:10]: bytearray(b'\x00\x89PNG\r\n\x1a\n\x00')
2019-12-09 01:06:12,968; client.py - line: 240 -DEBUG: Trying to receive data.
2019-12-09 01:06:12,968; client.py - line: 240 -DEBUG: Trying to receive data.
2019-12-09 01:06:12,969; client.py - line: 243 -INFO: Data from Unity received.
2019-12-09 01:06:12,969; client.py - line: 243 -INFO: Data from Unity received.
2019-12-09 01:06:12,970; client.py - line: 244 -DEBUG: End_tag detected, unity_resp_bytes[0:10]: bytearray(b'\x00\x89PNG\r\n\x1a\n\x00')
2019-12-09 01:06:12,970; client.py - line: 244 -DEBUG: End_tag detected, unity_resp_bytes[0:10]: bytearray(b'\x00\x89PNG\r\n\x1a\n\x00')
2019-12-09 01:06:12,971; client.py - line: 248 -DEBUG: img_bytes type: <class 'bytearray'>, img_bytes len: 45857, img_bytes[:10]: bytearray(b'\x89PNG\r\n\x1a\n\x00\x00')
2019-12-09 01:06:12,971; client.py - line: 248 -DEBUG: img_bytes type: <class 'bytearray'>, img_bytes len: 45857, img_bytes[:10]: bytearray(b'\x89PNG\r\n\x1a\n\x00\x00')
2019-12-09 01:06:12,973; client.py - line: 251 -DEBUG: PIL Img: type: <class 'PIL.PngImagePlugin.PngImageFile'> 
2019-12-09 01:06:12,973; client.py - line: 251 -DEBUG: PIL Img: type: <class 'PIL.PngImagePlugin.PngImageFile'> 
2019-12-09 01:06:13,013; client.py - line: 253 -DEBUG: Returning img: type: <class 'numpy.ndarray'> 

2019-12-09 01:06:13,013; client.py - line: 253 -DEBUG: Returning img: type: <class 'numpy.ndarray'> 

2019-12-09 01:06:13,014; dataset.py - line: 921 -DEBUG: index: 18
2019-12-09 01:06:13,014; dataset.py - line: 921 -DEBUG: index: 18
2019-12-09 01:06:13,015; dataset.py - line: 923 -DEBUG: index: 19
2019-12-09 01:06:13,015; dataset.py - line: 923 -DEBUG: index: 19
2019-12-09 01:06:13,091; client.py - line: 173 -INFO: Exit-message is sent. Unity build and socket now closing.

2019-12-09 01:06:13,091; client.py - line: 173 -INFO: Exit-message is sent. Unity build and socket now closing.

2019-12-09 01:06:13,091; client.py - line: 190 -DEBUG: Exit request sent.

2019-12-09 01:06:13,091; client.py - line: 190 -DEBUG: Exit request sent.

2019-12-09 01:06:13,091; dataset.py - line: 964 -DEBUG: Exit socket connection to unity.
2019-12-09 01:06:13,091; dataset.py - line: 964 -DEBUG: Exit socket connection to unity.
2019-12-09 01:06:13,091; dataset.py - line: 695 -DEBUG: numb_y: 2
2019-12-09 01:06:13,091; dataset.py - line: 695 -DEBUG: numb_y: 2
2019-12-09 01:06:13,092; dataset.py - line: 696 -DEBUG: dicts[0]['image'].shape[0]: 520
2019-12-09 01:06:13,092; dataset.py - line: 696 -DEBUG: dicts[0]['image'].shape[0]: 520
2019-12-09 01:06:13,092; dataset.py - line: 697 -DEBUG: (images_per_row*dicts[0][image].shape[1]: 2600
2019-12-09 01:06:13,092; dataset.py - line: 697 -DEBUG: (images_per_row*dicts[0][image].shape[1]: 2600
2019-12-09 01:06:13,092; dataset.py - line: 698 -DEBUG: dicts[0][image].shape[2]: 3
2019-12-09 01:06:13,092; dataset.py - line: 698 -DEBUG: dicts[0][image].shape[2]: 3
2019-12-09 01:06:13,102; dataset.py - line: 700 -DEBUG: h_stacked.shape: (2, 520, 2600, 3)
2019-12-09 01:06:13,102; dataset.py - line: 700 -DEBUG: h_stacked.shape: (2, 520, 2600, 3)
2019-12-09 01:06:13,153; dataset.py - line: 713 -DEBUG: final_img.shape: (1040, 2600, 3)
2019-12-09 01:06:13,153; dataset.py - line: 713 -DEBUG: final_img.shape: (1040, 2600, 3)
