2019-12-05 14:31:27,184; client.py - line: 58 -DEBUG: Starting python client.
2019-12-05 14:31:27,185; client.py - line: 78 -INFO: Starting Unity...
2019-12-05 14:31:27,185; client.py - line: 79 -DEBUG: path to unity: /home/haecker/Documents/src/git/python_unity_images/build_linux/unity_server_rendering_images.x86_64
2019-12-05 14:31:27,188; client.py - line: 92 -INFO: Waiting for unity...
2019-12-05 14:31:30,194; client.py - line: 119 -INFO: Client now connecting to server.
2019-12-05 14:31:30,195; client.py - line: 127 -DEBUG: Config data for TCP socket: host: 127.0.0.1; port: 50050
2019-12-05 14:31:30,195; client.py - line: 140 -DEBUG: Socket can not connect. Make sure that the tcp_server from unity is already running.
2019-12-05 14:31:30,195; client.py - line: 141 -DEBUG: [Errno 111] Connection refused
2019-12-05 14:31:30,245; client.py - line: 149 -DEBUG: Try next port: 49990
2019-12-05 14:31:30,245; client.py - line: 140 -DEBUG: Socket can not connect. Make sure that the tcp_server from unity is already running.
2019-12-05 14:31:30,246; client.py - line: 141 -DEBUG: [Errno 103] Software caused connection abort
2019-12-05 14:31:30,296; client.py - line: 149 -DEBUG: Try next port: 49991
2019-12-05 14:31:30,297; client.py - line: 140 -DEBUG: Socket can not connect. Make sure that the tcp_server from unity is already running.
2019-12-05 14:31:30,297; client.py - line: 141 -DEBUG: [Errno 111] Connection refused
2019-12-05 14:31:30,347; client.py - line: 149 -DEBUG: Try next port: 49992
2019-12-05 14:31:30,348; client.py - line: 140 -DEBUG: Socket can not connect. Make sure that the tcp_server from unity is already running.
2019-12-05 14:31:30,348; client.py - line: 141 -DEBUG: [Errno 103] Software caused connection abort
2019-12-05 14:31:30,399; client.py - line: 149 -DEBUG: Try next port: 49993
2019-12-05 14:31:30,400; client.py - line: 140 -DEBUG: Socket can not connect. Make sure that the tcp_server from unity is already running.
2019-12-05 14:31:30,400; client.py - line: 141 -DEBUG: [Errno 111] Connection refused
2019-12-05 14:31:30,451; client.py - line: 149 -DEBUG: Try next port: 49994
2019-12-05 14:31:30,451; client.py - line: 140 -DEBUG: Socket can not connect. Make sure that the tcp_server from unity is already running.
2019-12-05 14:31:30,452; client.py - line: 141 -DEBUG: [Errno 103] Software caused connection abort
2019-12-05 14:31:30,502; client.py - line: 149 -DEBUG: Try next port: 49995
2019-12-05 14:31:30,503; client.py - line: 140 -DEBUG: Socket can not connect. Make sure that the tcp_server from unity is already running.
2019-12-05 14:31:30,504; client.py - line: 141 -DEBUG: [Errno 111] Connection refused
2019-12-05 14:31:30,554; client.py - line: 149 -DEBUG: Try next port: 49996
2019-12-05 14:31:30,555; client.py - line: 140 -DEBUG: Socket can not connect. Make sure that the tcp_server from unity is already running.
2019-12-05 14:31:30,555; client.py - line: 141 -DEBUG: [Errno 103] Software caused connection abort
2019-12-05 14:31:30,605; client.py - line: 149 -DEBUG: Try next port: 49997
2019-12-05 14:31:30,605; client.py - line: 140 -DEBUG: Socket can not connect. Make sure that the tcp_server from unity is already running.
2019-12-05 14:31:30,605; client.py - line: 141 -DEBUG: [Errno 111] Connection refused
2019-12-05 14:31:30,655; client.py - line: 149 -DEBUG: Try next port: 49998
2019-12-05 14:31:30,656; client.py - line: 140 -DEBUG: Socket can not connect. Make sure that the tcp_server from unity is already running.
2019-12-05 14:31:30,657; client.py - line: 141 -DEBUG: [Errno 103] Software caused connection abort
2019-12-05 14:31:30,707; client.py - line: 149 -DEBUG: Try next port: 49999
2019-12-05 14:31:30,708; client.py - line: 140 -DEBUG: Socket can not connect. Make sure that the tcp_server from unity is already running.
2019-12-05 14:31:30,709; client.py - line: 141 -DEBUG: [Errno 111] Connection refused
2019-12-05 14:31:30,759; client.py - line: 149 -DEBUG: Try next port: 50000
2019-12-05 14:31:30,760; client.py - line: 140 -DEBUG: Socket can not connect. Make sure that the tcp_server from unity is already running.
2019-12-05 14:31:30,760; client.py - line: 141 -DEBUG: [Errno 103] Software caused connection abort
2019-12-05 14:31:30,810; client.py - line: 149 -DEBUG: Try next port: 50001
2019-12-05 14:31:30,810; client.py - line: 140 -DEBUG: Socket can not connect. Make sure that the tcp_server from unity is already running.
2019-12-05 14:31:30,810; client.py - line: 141 -DEBUG: [Errno 111] Connection refused
2019-12-05 14:31:30,861; client.py - line: 149 -DEBUG: Try next port: 50002
2019-12-05 14:31:30,862; client.py - line: 140 -DEBUG: Socket can not connect. Make sure that the tcp_server from unity is already running.
2019-12-05 14:31:30,862; client.py - line: 141 -DEBUG: [Errno 103] Software caused connection abort
2019-12-05 14:31:30,913; client.py - line: 149 -DEBUG: Try next port: 50003
2019-12-05 14:31:30,914; client.py - line: 140 -DEBUG: Socket can not connect. Make sure that the tcp_server from unity is already running.
2019-12-05 14:31:30,914; client.py - line: 141 -DEBUG: [Errno 111] Connection refused
2019-12-05 14:31:30,965; client.py - line: 149 -DEBUG: Try next port: 50004
2019-12-05 14:31:30,965; client.py - line: 140 -DEBUG: Socket can not connect. Make sure that the tcp_server from unity is already running.
2019-12-05 14:31:30,966; client.py - line: 141 -DEBUG: [Errno 103] Software caused connection abort
2019-12-05 14:31:31,017; client.py - line: 149 -DEBUG: Try next port: 50005
2019-12-05 14:31:31,018; client.py - line: 140 -DEBUG: Socket can not connect. Make sure that the tcp_server from unity is already running.
2019-12-05 14:31:31,018; client.py - line: 141 -DEBUG: [Errno 111] Connection refused
2019-12-05 14:31:31,069; client.py - line: 149 -DEBUG: Try next port: 50006
2019-12-05 14:31:31,070; client.py - line: 140 -DEBUG: Socket can not connect. Make sure that the tcp_server from unity is already running.
2019-12-05 14:31:31,070; client.py - line: 141 -DEBUG: [Errno 103] Software caused connection abort
2019-12-05 14:31:31,121; client.py - line: 149 -DEBUG: Try next port: 50007
2019-12-05 14:31:31,122; client.py - line: 140 -DEBUG: Socket can not connect. Make sure that the tcp_server from unity is already running.
2019-12-05 14:31:31,122; client.py - line: 141 -DEBUG: [Errno 111] Connection refused
2019-12-05 14:31:31,172; client.py - line: 149 -DEBUG: Try next port: 50008
2019-12-05 14:31:31,173; client.py - line: 140 -DEBUG: Socket can not connect. Make sure that the tcp_server from unity is already running.
2019-12-05 14:31:31,173; client.py - line: 141 -DEBUG: [Errno 103] Software caused connection abort
2019-12-05 14:31:31,224; client.py - line: 149 -DEBUG: Try next port: 50009
2019-12-05 14:31:31,225; client.py - line: 140 -DEBUG: Socket can not connect. Make sure that the tcp_server from unity is already running.
2019-12-05 14:31:31,225; client.py - line: 141 -DEBUG: [Errno 111] Connection refused
2019-12-05 14:31:31,275; client.py - line: 149 -DEBUG: Try next port: 50010
2019-12-05 14:31:31,276; client.py - line: 140 -DEBUG: Socket can not connect. Make sure that the tcp_server from unity is already running.
2019-12-05 14:31:31,276; client.py - line: 141 -DEBUG: [Errno 103] Software caused connection abort
2019-12-05 14:31:31,327; client.py - line: 149 -DEBUG: Try next port: 50011
2019-12-05 14:31:31,328; client.py - line: 140 -DEBUG: Socket can not connect. Make sure that the tcp_server from unity is already running.
2019-12-05 14:31:31,328; client.py - line: 141 -DEBUG: [Errno 111] Connection refused
2019-12-05 14:31:31,378; client.py - line: 149 -DEBUG: Try next port: 50012
2019-12-05 14:31:31,379; client.py - line: 140 -DEBUG: Socket can not connect. Make sure that the tcp_server from unity is already running.
2019-12-05 14:31:31,379; client.py - line: 141 -DEBUG: [Errno 103] Software caused connection abort
2019-12-05 14:31:31,430; client.py - line: 149 -DEBUG: Try next port: 50013
2019-12-05 14:31:31,431; client.py - line: 140 -DEBUG: Socket can not connect. Make sure that the tcp_server from unity is already running.
2019-12-05 14:31:31,431; client.py - line: 141 -DEBUG: [Errno 111] Connection refused
2019-12-05 14:31:31,482; client.py - line: 149 -DEBUG: Try next port: 50014
2019-12-05 14:31:31,482; client.py - line: 140 -DEBUG: Socket can not connect. Make sure that the tcp_server from unity is already running.
2019-12-05 14:31:31,482; client.py - line: 141 -DEBUG: [Errno 103] Software caused connection abort
2019-12-05 14:31:31,533; client.py - line: 149 -DEBUG: Try next port: 50015
2019-12-05 14:31:31,534; client.py - line: 140 -DEBUG: Socket can not connect. Make sure that the tcp_server from unity is already running.
2019-12-05 14:31:31,534; client.py - line: 141 -DEBUG: [Errno 111] Connection refused
2019-12-05 14:31:31,584; client.py - line: 149 -DEBUG: Try next port: 50016
2019-12-05 14:31:31,585; client.py - line: 140 -DEBUG: Socket can not connect. Make sure that the tcp_server from unity is already running.
2019-12-05 14:31:31,585; client.py - line: 141 -DEBUG: [Errno 103] Software caused connection abort
2019-12-05 14:31:31,636; client.py - line: 149 -DEBUG: Try next port: 50017
2019-12-05 14:31:31,637; client.py - line: 140 -DEBUG: Socket can not connect. Make sure that the tcp_server from unity is already running.
2019-12-05 14:31:31,637; client.py - line: 141 -DEBUG: [Errno 111] Connection refused
2019-12-05 14:31:31,688; client.py - line: 149 -DEBUG: Try next port: 50018
2019-12-05 14:31:31,688; client.py - line: 140 -DEBUG: Socket can not connect. Make sure that the tcp_server from unity is already running.
2019-12-05 14:31:31,689; client.py - line: 141 -DEBUG: [Errno 103] Software caused connection abort
2019-12-05 14:31:31,740; client.py - line: 149 -DEBUG: Try next port: 50019
2019-12-05 14:31:31,740; client.py - line: 140 -DEBUG: Socket can not connect. Make sure that the tcp_server from unity is already running.
2019-12-05 14:31:31,741; client.py - line: 141 -DEBUG: [Errno 111] Connection refused
2019-12-05 14:31:31,791; client.py - line: 149 -DEBUG: Try next port: 50020
2019-12-05 14:31:31,792; client.py - line: 140 -DEBUG: Socket can not connect. Make sure that the tcp_server from unity is already running.
2019-12-05 14:31:31,792; client.py - line: 141 -DEBUG: [Errno 103] Software caused connection abort
2019-12-05 14:31:31,843; client.py - line: 149 -DEBUG: Try next port: 50021
2019-12-05 14:31:31,844; client.py - line: 140 -DEBUG: Socket can not connect. Make sure that the tcp_server from unity is already running.
2019-12-05 14:31:31,844; client.py - line: 141 -DEBUG: [Errno 111] Connection refused
2019-12-05 14:31:31,895; client.py - line: 149 -DEBUG: Try next port: 50022
2019-12-05 14:31:31,895; client.py - line: 140 -DEBUG: Socket can not connect. Make sure that the tcp_server from unity is already running.
2019-12-05 14:31:31,896; client.py - line: 141 -DEBUG: [Errno 103] Software caused connection abort
2019-12-05 14:31:31,946; client.py - line: 149 -DEBUG: Try next port: 50023
2019-12-05 14:31:31,947; client.py - line: 140 -DEBUG: Socket can not connect. Make sure that the tcp_server from unity is already running.
2019-12-05 14:31:31,947; client.py - line: 141 -DEBUG: [Errno 111] Connection refused
2019-12-05 14:31:31,998; client.py - line: 149 -DEBUG: Try next port: 50024
2019-12-05 14:31:31,998; client.py - line: 140 -DEBUG: Socket can not connect. Make sure that the tcp_server from unity is already running.
2019-12-05 14:31:31,998; client.py - line: 141 -DEBUG: [Errno 103] Software caused connection abort
2019-12-05 14:31:32,049; client.py - line: 149 -DEBUG: Try next port: 50025
2019-12-05 14:31:32,050; client.py - line: 140 -DEBUG: Socket can not connect. Make sure that the tcp_server from unity is already running.
2019-12-05 14:31:32,050; client.py - line: 141 -DEBUG: [Errno 111] Connection refused
2019-12-05 14:31:32,100; client.py - line: 149 -DEBUG: Try next port: 50026
2019-12-05 14:31:32,101; client.py - line: 140 -DEBUG: Socket can not connect. Make sure that the tcp_server from unity is already running.
2019-12-05 14:31:32,102; client.py - line: 141 -DEBUG: [Errno 103] Software caused connection abort
2019-12-05 14:31:32,152; client.py - line: 149 -DEBUG: Try next port: 50027
2019-12-05 14:31:32,153; client.py - line: 140 -DEBUG: Socket can not connect. Make sure that the tcp_server from unity is already running.
2019-12-05 14:31:32,154; client.py - line: 141 -DEBUG: [Errno 111] Connection refused
2019-12-05 14:31:32,204; client.py - line: 149 -DEBUG: Try next port: 50028
2019-12-05 14:31:32,205; client.py - line: 140 -DEBUG: Socket can not connect. Make sure that the tcp_server from unity is already running.
2019-12-05 14:31:32,205; client.py - line: 141 -DEBUG: [Errno 103] Software caused connection abort
2019-12-05 14:31:32,256; client.py - line: 149 -DEBUG: Try next port: 50029
2019-12-05 14:31:32,256; client.py - line: 140 -DEBUG: Socket can not connect. Make sure that the tcp_server from unity is already running.
2019-12-05 14:31:32,257; client.py - line: 141 -DEBUG: [Errno 111] Connection refused
2019-12-05 14:31:32,307; client.py - line: 149 -DEBUG: Try next port: 50030
2019-12-05 14:31:32,308; client.py - line: 140 -DEBUG: Socket can not connect. Make sure that the tcp_server from unity is already running.
2019-12-05 14:31:32,308; client.py - line: 141 -DEBUG: [Errno 103] Software caused connection abort
2019-12-05 14:31:32,359; client.py - line: 149 -DEBUG: Try next port: 50031
2019-12-05 14:31:32,360; client.py - line: 140 -DEBUG: Socket can not connect. Make sure that the tcp_server from unity is already running.
2019-12-05 14:31:32,360; client.py - line: 141 -DEBUG: [Errno 111] Connection refused
2019-12-05 14:31:32,410; client.py - line: 149 -DEBUG: Try next port: 50032
2019-12-05 14:31:32,411; client.py - line: 140 -DEBUG: Socket can not connect. Make sure that the tcp_server from unity is already running.
2019-12-05 14:31:32,411; client.py - line: 141 -DEBUG: [Errno 103] Software caused connection abort
2019-12-05 14:31:32,462; client.py - line: 149 -DEBUG: Try next port: 50033
2019-12-05 14:31:32,463; client.py - line: 140 -DEBUG: Socket can not connect. Make sure that the tcp_server from unity is already running.
2019-12-05 14:31:32,463; client.py - line: 141 -DEBUG: [Errno 111] Connection refused
2019-12-05 14:31:32,514; client.py - line: 149 -DEBUG: Try next port: 50034
2019-12-05 14:31:32,514; client.py - line: 140 -DEBUG: Socket can not connect. Make sure that the tcp_server from unity is already running.
2019-12-05 14:31:32,515; client.py - line: 141 -DEBUG: [Errno 103] Software caused connection abort
2019-12-05 14:31:32,565; client.py - line: 149 -DEBUG: Try next port: 50035
2019-12-05 14:31:32,566; client.py - line: 140 -DEBUG: Socket can not connect. Make sure that the tcp_server from unity is already running.
2019-12-05 14:31:32,566; client.py - line: 141 -DEBUG: [Errno 111] Connection refused
2019-12-05 14:31:32,617; client.py - line: 149 -DEBUG: Try next port: 50036
2019-12-05 14:31:32,617; client.py - line: 140 -DEBUG: Socket can not connect. Make sure that the tcp_server from unity is already running.
2019-12-05 14:31:32,621; client.py - line: 141 -DEBUG: [Errno 103] Software caused connection abort
2019-12-05 14:31:32,672; client.py - line: 149 -DEBUG: Try next port: 50037
2019-12-05 14:31:32,672; client.py - line: 140 -DEBUG: Socket can not connect. Make sure that the tcp_server from unity is already running.
2019-12-05 14:31:32,673; client.py - line: 141 -DEBUG: [Errno 111] Connection refused
2019-12-05 14:31:32,724; client.py - line: 149 -DEBUG: Try next port: 50038
2019-12-05 14:31:32,724; client.py - line: 140 -DEBUG: Socket can not connect. Make sure that the tcp_server from unity is already running.
2019-12-05 14:31:32,724; client.py - line: 141 -DEBUG: [Errno 103] Software caused connection abort
2019-12-05 14:31:32,775; client.py - line: 149 -DEBUG: Try next port: 50039
2019-12-05 14:31:32,776; client.py - line: 140 -DEBUG: Socket can not connect. Make sure that the tcp_server from unity is already running.
2019-12-05 14:31:32,776; client.py - line: 141 -DEBUG: [Errno 111] Connection refused
2019-12-05 14:31:32,827; client.py - line: 149 -DEBUG: Try next port: 50040
2019-12-05 14:31:32,827; client.py - line: 140 -DEBUG: Socket can not connect. Make sure that the tcp_server from unity is already running.
2019-12-05 14:31:32,828; client.py - line: 141 -DEBUG: [Errno 103] Software caused connection abort
2019-12-05 14:31:32,878; client.py - line: 149 -DEBUG: Try next port: 50041
2019-12-05 14:31:32,879; client.py - line: 140 -DEBUG: Socket can not connect. Make sure that the tcp_server from unity is already running.
2019-12-05 14:31:32,879; client.py - line: 141 -DEBUG: [Errno 111] Connection refused
2019-12-05 14:31:32,930; client.py - line: 149 -DEBUG: Try next port: 50042
2019-12-05 14:31:32,931; client.py - line: 140 -DEBUG: Socket can not connect. Make sure that the tcp_server from unity is already running.
2019-12-05 14:31:32,931; client.py - line: 141 -DEBUG: [Errno 103] Software caused connection abort
2019-12-05 14:31:32,981; client.py - line: 149 -DEBUG: Try next port: 50043
2019-12-05 14:31:32,982; client.py - line: 140 -DEBUG: Socket can not connect. Make sure that the tcp_server from unity is already running.
2019-12-05 14:31:32,982; client.py - line: 141 -DEBUG: [Errno 111] Connection refused
2019-12-05 14:31:33,033; client.py - line: 149 -DEBUG: Try next port: 50044
2019-12-05 14:31:33,033; client.py - line: 140 -DEBUG: Socket can not connect. Make sure that the tcp_server from unity is already running.
2019-12-05 14:31:33,034; client.py - line: 141 -DEBUG: [Errno 103] Software caused connection abort
2019-12-05 14:31:33,084; client.py - line: 149 -DEBUG: Try next port: 50045
2019-12-05 14:31:33,085; client.py - line: 140 -DEBUG: Socket can not connect. Make sure that the tcp_server from unity is already running.
2019-12-05 14:31:33,085; client.py - line: 141 -DEBUG: [Errno 111] Connection refused
2019-12-05 14:31:33,136; client.py - line: 149 -DEBUG: Try next port: 50046
2019-12-05 14:31:33,137; client.py - line: 140 -DEBUG: Socket can not connect. Make sure that the tcp_server from unity is already running.
2019-12-05 14:31:33,137; client.py - line: 141 -DEBUG: [Errno 103] Software caused connection abort
2019-12-05 14:31:33,188; client.py - line: 149 -DEBUG: Try next port: 50047
2019-12-05 14:31:33,188; client.py - line: 140 -DEBUG: Socket can not connect. Make sure that the tcp_server from unity is already running.
2019-12-05 14:31:33,189; client.py - line: 141 -DEBUG: [Errno 111] Connection refused
2019-12-05 14:31:33,240; client.py - line: 149 -DEBUG: Try next port: 50048
2019-12-05 14:31:33,240; client.py - line: 140 -DEBUG: Socket can not connect. Make sure that the tcp_server from unity is already running.
2019-12-05 14:31:33,240; client.py - line: 141 -DEBUG: [Errno 103] Software caused connection abort
2019-12-05 14:31:33,291; client.py - line: 149 -DEBUG: Try next port: 50049
2019-12-05 14:31:33,292; client.py - line: 140 -DEBUG: Socket can not connect. Make sure that the tcp_server from unity is already running.
2019-12-05 14:31:33,292; client.py - line: 141 -DEBUG: [Errno 111] Connection refused
2019-12-05 14:31:33,343; client.py - line: 149 -DEBUG: Try next port: 50050
2019-12-05 14:31:33,343; client.py - line: 140 -DEBUG: Socket can not connect. Make sure that the tcp_server from unity is already running.
2019-12-05 14:31:33,344; client.py - line: 141 -DEBUG: [Errno 103] Software caused connection abort
2019-12-05 14:31:33,394; client.py - line: 149 -DEBUG: Try next port: 49990
2019-12-05 14:31:33,395; client.py - line: 140 -DEBUG: Socket can not connect. Make sure that the tcp_server from unity is already running.
2019-12-05 14:31:33,395; client.py - line: 141 -DEBUG: [Errno 111] Connection refused
2019-12-05 14:31:33,446; client.py - line: 149 -DEBUG: Try next port: 49991
2019-12-05 14:31:33,446; client.py - line: 140 -DEBUG: Socket can not connect. Make sure that the tcp_server from unity is already running.
2019-12-05 14:31:33,447; client.py - line: 141 -DEBUG: [Errno 103] Software caused connection abort
2019-12-05 14:31:33,497; client.py - line: 149 -DEBUG: Try next port: 49992
2019-12-05 14:31:33,498; client.py - line: 140 -DEBUG: Socket can not connect. Make sure that the tcp_server from unity is already running.
2019-12-05 14:31:33,498; client.py - line: 141 -DEBUG: [Errno 111] Connection refused
2019-12-05 14:31:33,549; client.py - line: 149 -DEBUG: Try next port: 49993
2019-12-05 14:31:33,549; client.py - line: 140 -DEBUG: Socket can not connect. Make sure that the tcp_server from unity is already running.
2019-12-05 14:31:33,550; client.py - line: 141 -DEBUG: [Errno 103] Software caused connection abort
2019-12-05 14:31:33,600; client.py - line: 149 -DEBUG: Try next port: 49994
2019-12-05 14:31:33,601; client.py - line: 140 -DEBUG: Socket can not connect. Make sure that the tcp_server from unity is already running.
2019-12-05 14:31:33,601; client.py - line: 141 -DEBUG: [Errno 111] Connection refused
2019-12-05 14:31:33,652; client.py - line: 149 -DEBUG: Try next port: 49995
2019-12-05 14:31:33,653; client.py - line: 140 -DEBUG: Socket can not connect. Make sure that the tcp_server from unity is already running.
2019-12-05 14:31:33,653; client.py - line: 141 -DEBUG: [Errno 103] Software caused connection abort
2019-12-05 14:31:33,703; client.py - line: 149 -DEBUG: Try next port: 49996
2019-12-05 14:31:33,704; client.py - line: 140 -DEBUG: Socket can not connect. Make sure that the tcp_server from unity is already running.
2019-12-05 14:31:33,705; client.py - line: 141 -DEBUG: [Errno 111] Connection refused
2019-12-05 14:31:33,755; client.py - line: 149 -DEBUG: Try next port: 49997
2019-12-05 14:31:33,756; client.py - line: 140 -DEBUG: Socket can not connect. Make sure that the tcp_server from unity is already running.
2019-12-05 14:31:33,757; client.py - line: 141 -DEBUG: [Errno 103] Software caused connection abort
2019-12-05 14:31:33,807; client.py - line: 149 -DEBUG: Try next port: 49998
2019-12-05 14:31:33,808; client.py - line: 140 -DEBUG: Socket can not connect. Make sure that the tcp_server from unity is already running.
2019-12-05 14:31:33,809; client.py - line: 141 -DEBUG: [Errno 111] Connection refused
2019-12-05 14:31:33,859; client.py - line: 149 -DEBUG: Try next port: 49999
2019-12-05 14:31:33,860; client.py - line: 140 -DEBUG: Socket can not connect. Make sure that the tcp_server from unity is already running.
2019-12-05 14:31:33,861; client.py - line: 141 -DEBUG: [Errno 103] Software caused connection abort
2019-12-05 14:31:33,911; client.py - line: 149 -DEBUG: Try next port: 50000
2019-12-05 14:31:33,912; client.py - line: 140 -DEBUG: Socket can not connect. Make sure that the tcp_server from unity is already running.
2019-12-05 14:31:33,913; client.py - line: 141 -DEBUG: [Errno 111] Connection refused
2019-12-05 14:31:33,963; client.py - line: 149 -DEBUG: Try next port: 50001
2019-12-05 14:31:33,964; client.py - line: 140 -DEBUG: Socket can not connect. Make sure that the tcp_server from unity is already running.
2019-12-05 14:31:33,964; client.py - line: 141 -DEBUG: [Errno 103] Software caused connection abort
2019-12-05 14:31:34,015; client.py - line: 149 -DEBUG: Try next port: 50002
2019-12-05 14:31:34,016; client.py - line: 140 -DEBUG: Socket can not connect. Make sure that the tcp_server from unity is already running.
2019-12-05 14:31:34,016; client.py - line: 141 -DEBUG: [Errno 111] Connection refused
2019-12-05 14:31:34,066; client.py - line: 149 -DEBUG: Try next port: 50003
2019-12-05 14:31:34,067; client.py - line: 140 -DEBUG: Socket can not connect. Make sure that the tcp_server from unity is already running.
2019-12-05 14:31:34,068; client.py - line: 141 -DEBUG: [Errno 103] Software caused connection abort
2019-12-05 14:31:34,118; client.py - line: 149 -DEBUG: Try next port: 50004
2019-12-05 14:31:34,119; client.py - line: 140 -DEBUG: Socket can not connect. Make sure that the tcp_server from unity is already running.
2019-12-05 14:31:34,120; client.py - line: 141 -DEBUG: [Errno 111] Connection refused
2019-12-05 14:31:34,170; client.py - line: 149 -DEBUG: Try next port: 50005
2019-12-05 14:31:34,171; client.py - line: 140 -DEBUG: Socket can not connect. Make sure that the tcp_server from unity is already running.
2019-12-05 14:31:34,171; client.py - line: 141 -DEBUG: [Errno 103] Software caused connection abort
2019-12-05 14:31:34,222; client.py - line: 149 -DEBUG: Try next port: 50006
2019-12-05 14:31:34,223; client.py - line: 140 -DEBUG: Socket can not connect. Make sure that the tcp_server from unity is already running.
2019-12-05 14:31:34,224; client.py - line: 141 -DEBUG: [Errno 111] Connection refused
2019-12-05 14:31:34,274; client.py - line: 149 -DEBUG: Try next port: 50007
2019-12-05 14:31:34,275; client.py - line: 140 -DEBUG: Socket can not connect. Make sure that the tcp_server from unity is already running.
2019-12-05 14:31:34,276; client.py - line: 141 -DEBUG: [Errno 103] Software caused connection abort
2019-12-05 14:31:34,326; client.py - line: 149 -DEBUG: Try next port: 50008
2019-12-05 14:31:34,327; client.py - line: 140 -DEBUG: Socket can not connect. Make sure that the tcp_server from unity is already running.
2019-12-05 14:31:34,328; client.py - line: 141 -DEBUG: [Errno 111] Connection refused
2019-12-05 14:31:34,378; client.py - line: 149 -DEBUG: Try next port: 50009
2019-12-05 14:31:34,379; client.py - line: 140 -DEBUG: Socket can not connect. Make sure that the tcp_server from unity is already running.
2019-12-05 14:31:34,380; client.py - line: 141 -DEBUG: [Errno 103] Software caused connection abort
2019-12-05 14:31:34,430; client.py - line: 149 -DEBUG: Try next port: 50010
2019-12-05 14:31:34,431; client.py - line: 140 -DEBUG: Socket can not connect. Make sure that the tcp_server from unity is already running.
2019-12-05 14:31:34,432; client.py - line: 141 -DEBUG: [Errno 111] Connection refused
2019-12-05 14:31:34,482; client.py - line: 149 -DEBUG: Try next port: 50011
2019-12-05 14:31:34,483; client.py - line: 140 -DEBUG: Socket can not connect. Make sure that the tcp_server from unity is already running.
2019-12-05 14:31:34,484; client.py - line: 141 -DEBUG: [Errno 103] Software caused connection abort
2019-12-05 14:31:34,534; client.py - line: 149 -DEBUG: Try next port: 50012
2019-12-05 14:31:34,535; client.py - line: 140 -DEBUG: Socket can not connect. Make sure that the tcp_server from unity is already running.
2019-12-05 14:31:34,536; client.py - line: 141 -DEBUG: [Errno 111] Connection refused
2019-12-05 14:31:34,586; client.py - line: 149 -DEBUG: Try next port: 50013
2019-12-05 14:31:34,587; client.py - line: 140 -DEBUG: Socket can not connect. Make sure that the tcp_server from unity is already running.
2019-12-05 14:31:34,587; client.py - line: 141 -DEBUG: [Errno 103] Software caused connection abort
2019-12-05 14:31:34,638; client.py - line: 149 -DEBUG: Try next port: 50014
2019-12-05 14:31:34,639; client.py - line: 140 -DEBUG: Socket can not connect. Make sure that the tcp_server from unity is already running.
2019-12-05 14:31:34,639; client.py - line: 141 -DEBUG: [Errno 111] Connection refused
2019-12-05 14:31:34,689; client.py - line: 149 -DEBUG: Try next port: 50015
2019-12-05 14:31:34,690; client.py - line: 140 -DEBUG: Socket can not connect. Make sure that the tcp_server from unity is already running.
2019-12-05 14:31:34,690; client.py - line: 141 -DEBUG: [Errno 103] Software caused connection abort
2019-12-05 14:31:34,741; client.py - line: 149 -DEBUG: Try next port: 50016
2019-12-05 14:31:34,741; client.py - line: 140 -DEBUG: Socket can not connect. Make sure that the tcp_server from unity is already running.
2019-12-05 14:31:34,742; client.py - line: 141 -DEBUG: [Errno 111] Connection refused
2019-12-05 14:31:34,792; client.py - line: 149 -DEBUG: Try next port: 50017
2019-12-05 14:31:34,793; client.py - line: 140 -DEBUG: Socket can not connect. Make sure that the tcp_server from unity is already running.
2019-12-05 14:31:34,793; client.py - line: 141 -DEBUG: [Errno 103] Software caused connection abort
2019-12-05 14:31:34,844; client.py - line: 149 -DEBUG: Try next port: 50018
2019-12-05 14:31:34,844; client.py - line: 140 -DEBUG: Socket can not connect. Make sure that the tcp_server from unity is already running.
2019-12-05 14:31:34,845; client.py - line: 141 -DEBUG: [Errno 111] Connection refused
2019-12-05 14:31:34,895; client.py - line: 149 -DEBUG: Try next port: 50019
2019-12-05 14:31:34,896; client.py - line: 140 -DEBUG: Socket can not connect. Make sure that the tcp_server from unity is already running.
2019-12-05 14:31:34,896; client.py - line: 141 -DEBUG: [Errno 103] Software caused connection abort
2019-12-05 14:31:34,947; client.py - line: 149 -DEBUG: Try next port: 50020
2019-12-05 14:31:34,947; client.py - line: 140 -DEBUG: Socket can not connect. Make sure that the tcp_server from unity is already running.
2019-12-05 14:31:34,947; client.py - line: 141 -DEBUG: [Errno 111] Connection refused
2019-12-05 14:31:34,997; client.py - line: 149 -DEBUG: Try next port: 50021
2019-12-05 14:31:34,998; client.py - line: 140 -DEBUG: Socket can not connect. Make sure that the tcp_server from unity is already running.
2019-12-05 14:31:34,998; client.py - line: 141 -DEBUG: [Errno 103] Software caused connection abort
2019-12-05 14:31:35,048; client.py - line: 149 -DEBUG: Try next port: 50022
2019-12-05 14:31:35,049; client.py - line: 140 -DEBUG: Socket can not connect. Make sure that the tcp_server from unity is already running.
2019-12-05 14:31:35,050; client.py - line: 141 -DEBUG: [Errno 111] Connection refused
2019-12-05 14:31:35,100; client.py - line: 149 -DEBUG: Try next port: 50023
2019-12-05 14:31:35,101; client.py - line: 140 -DEBUG: Socket can not connect. Make sure that the tcp_server from unity is already running.
2019-12-05 14:31:35,101; client.py - line: 141 -DEBUG: [Errno 103] Software caused connection abort
2019-12-05 14:31:35,152; client.py - line: 149 -DEBUG: Try next port: 50024
2019-12-05 14:31:35,153; client.py - line: 140 -DEBUG: Socket can not connect. Make sure that the tcp_server from unity is already running.
2019-12-05 14:31:35,153; client.py - line: 141 -DEBUG: [Errno 111] Connection refused
2019-12-05 14:31:35,204; client.py - line: 149 -DEBUG: Try next port: 50025
2019-12-05 14:31:35,204; client.py - line: 140 -DEBUG: Socket can not connect. Make sure that the tcp_server from unity is already running.
2019-12-05 14:31:35,205; client.py - line: 141 -DEBUG: [Errno 103] Software caused connection abort
2019-12-05 14:31:35,255; client.py - line: 149 -DEBUG: Try next port: 50026
2019-12-05 14:31:35,256; client.py - line: 140 -DEBUG: Socket can not connect. Make sure that the tcp_server from unity is already running.
2019-12-05 14:31:35,256; client.py - line: 141 -DEBUG: [Errno 111] Connection refused
2019-12-05 14:31:35,307; client.py - line: 149 -DEBUG: Try next port: 50027
2019-12-05 14:31:35,308; client.py - line: 140 -DEBUG: Socket can not connect. Make sure that the tcp_server from unity is already running.
2019-12-05 14:31:35,308; client.py - line: 141 -DEBUG: [Errno 103] Software caused connection abort
2019-12-05 14:31:35,358; client.py - line: 149 -DEBUG: Try next port: 50028
2019-12-05 14:31:35,359; client.py - line: 140 -DEBUG: Socket can not connect. Make sure that the tcp_server from unity is already running.
2019-12-05 14:31:35,359; client.py - line: 141 -DEBUG: [Errno 111] Connection refused
2019-12-05 14:31:35,410; client.py - line: 149 -DEBUG: Try next port: 50029
2019-12-05 14:31:35,411; client.py - line: 140 -DEBUG: Socket can not connect. Make sure that the tcp_server from unity is already running.
2019-12-05 14:31:35,411; client.py - line: 141 -DEBUG: [Errno 103] Software caused connection abort
2019-12-05 14:31:35,462; client.py - line: 149 -DEBUG: Try next port: 50030
2019-12-05 14:31:35,462; client.py - line: 140 -DEBUG: Socket can not connect. Make sure that the tcp_server from unity is already running.
2019-12-05 14:31:35,463; client.py - line: 141 -DEBUG: [Errno 111] Connection refused
2019-12-05 14:31:35,513; client.py - line: 149 -DEBUG: Try next port: 50031
2019-12-05 14:31:35,514; client.py - line: 140 -DEBUG: Socket can not connect. Make sure that the tcp_server from unity is already running.
2019-12-05 14:31:35,514; client.py - line: 141 -DEBUG: [Errno 103] Software caused connection abort
2019-12-05 14:31:35,565; client.py - line: 149 -DEBUG: Try next port: 50032
2019-12-05 14:31:35,566; client.py - line: 140 -DEBUG: Socket can not connect. Make sure that the tcp_server from unity is already running.
2019-12-05 14:31:35,566; client.py - line: 141 -DEBUG: [Errno 111] Connection refused
2019-12-05 14:31:35,617; client.py - line: 149 -DEBUG: Try next port: 50033
2019-12-05 14:31:35,617; client.py - line: 140 -DEBUG: Socket can not connect. Make sure that the tcp_server from unity is already running.
2019-12-05 14:31:35,618; client.py - line: 141 -DEBUG: [Errno 103] Software caused connection abort
2019-12-05 14:31:35,668; client.py - line: 149 -DEBUG: Try next port: 50034
2019-12-05 14:31:35,669; client.py - line: 140 -DEBUG: Socket can not connect. Make sure that the tcp_server from unity is already running.
2019-12-05 14:31:35,669; client.py - line: 141 -DEBUG: [Errno 111] Connection refused
2019-12-05 14:31:35,720; client.py - line: 149 -DEBUG: Try next port: 50035
2019-12-05 14:31:35,720; client.py - line: 140 -DEBUG: Socket can not connect. Make sure that the tcp_server from unity is already running.
2019-12-05 14:31:35,721; client.py - line: 141 -DEBUG: [Errno 103] Software caused connection abort
2019-12-05 14:31:35,771; client.py - line: 149 -DEBUG: Try next port: 50036
2019-12-05 14:31:35,772; client.py - line: 140 -DEBUG: Socket can not connect. Make sure that the tcp_server from unity is already running.
2019-12-05 14:31:35,772; client.py - line: 141 -DEBUG: [Errno 111] Connection refused
2019-12-05 14:31:35,823; client.py - line: 149 -DEBUG: Try next port: 50037
2019-12-05 14:31:35,824; client.py - line: 140 -DEBUG: Socket can not connect. Make sure that the tcp_server from unity is already running.
2019-12-05 14:31:35,824; client.py - line: 141 -DEBUG: [Errno 103] Software caused connection abort
2019-12-05 14:31:35,874; client.py - line: 149 -DEBUG: Try next port: 50038
2019-12-05 14:31:35,875; client.py - line: 140 -DEBUG: Socket can not connect. Make sure that the tcp_server from unity is already running.
2019-12-05 14:31:35,875; client.py - line: 141 -DEBUG: [Errno 111] Connection refused
2019-12-05 14:31:35,925; client.py - line: 149 -DEBUG: Try next port: 50039
2019-12-05 14:31:35,926; client.py - line: 140 -DEBUG: Socket can not connect. Make sure that the tcp_server from unity is already running.
2019-12-05 14:31:35,926; client.py - line: 141 -DEBUG: [Errno 103] Software caused connection abort
2019-12-05 14:31:35,976; client.py - line: 149 -DEBUG: Try next port: 50040
2019-12-05 14:31:35,977; client.py - line: 140 -DEBUG: Socket can not connect. Make sure that the tcp_server from unity is already running.
2019-12-05 14:31:35,978; client.py - line: 141 -DEBUG: [Errno 111] Connection refused
2019-12-05 14:31:36,028; client.py - line: 149 -DEBUG: Try next port: 50041
2019-12-05 14:31:36,029; client.py - line: 140 -DEBUG: Socket can not connect. Make sure that the tcp_server from unity is already running.
2019-12-05 14:31:36,029; client.py - line: 141 -DEBUG: [Errno 103] Software caused connection abort
2019-12-05 14:31:36,080; client.py - line: 149 -DEBUG: Try next port: 50042
2019-12-05 14:31:36,081; client.py - line: 140 -DEBUG: Socket can not connect. Make sure that the tcp_server from unity is already running.
2019-12-05 14:31:36,081; client.py - line: 141 -DEBUG: [Errno 111] Connection refused
2019-12-05 14:31:36,132; client.py - line: 149 -DEBUG: Try next port: 50043
2019-12-05 14:31:36,132; client.py - line: 140 -DEBUG: Socket can not connect. Make sure that the tcp_server from unity is already running.
2019-12-05 14:31:36,133; client.py - line: 141 -DEBUG: [Errno 103] Software caused connection abort
2019-12-05 14:31:36,183; client.py - line: 149 -DEBUG: Try next port: 50044
2019-12-05 14:31:36,184; client.py - line: 140 -DEBUG: Socket can not connect. Make sure that the tcp_server from unity is already running.
2019-12-05 14:31:36,185; client.py - line: 141 -DEBUG: [Errno 111] Connection refused
2019-12-05 14:31:36,235; client.py - line: 149 -DEBUG: Try next port: 50045
2019-12-05 14:31:36,236; client.py - line: 140 -DEBUG: Socket can not connect. Make sure that the tcp_server from unity is already running.
2019-12-05 14:31:36,237; client.py - line: 141 -DEBUG: [Errno 103] Software caused connection abort
2019-12-05 14:31:36,287; client.py - line: 149 -DEBUG: Try next port: 50046
2019-12-05 14:31:36,288; client.py - line: 140 -DEBUG: Socket can not connect. Make sure that the tcp_server from unity is already running.
2019-12-05 14:31:36,289; client.py - line: 141 -DEBUG: [Errno 111] Connection refused
2019-12-05 14:31:36,339; client.py - line: 149 -DEBUG: Try next port: 50047
2019-12-05 14:31:36,340; client.py - line: 140 -DEBUG: Socket can not connect. Make sure that the tcp_server from unity is already running.
2019-12-05 14:31:36,340; client.py - line: 141 -DEBUG: [Errno 103] Software caused connection abort
2019-12-05 14:31:36,391; client.py - line: 149 -DEBUG: Try next port: 50048
2019-12-05 14:31:36,391; client.py - line: 140 -DEBUG: Socket can not connect. Make sure that the tcp_server from unity is already running.
2019-12-05 14:31:36,392; client.py - line: 141 -DEBUG: [Errno 111] Connection refused
2019-12-05 14:31:36,442; client.py - line: 149 -DEBUG: Try next port: 50049
2019-12-05 14:31:36,443; client.py - line: 140 -DEBUG: Socket can not connect. Make sure that the tcp_server from unity is already running.
2019-12-05 14:31:36,443; client.py - line: 141 -DEBUG: [Errno 103] Software caused connection abort
2019-12-05 14:31:36,494; client.py - line: 149 -DEBUG: Try next port: 50050
2019-12-05 14:31:36,495; client.py - line: 136 -INFO: Socket connected.
2019-12-05 14:31:36,495; client.py - line: 137 -DEBUG: Saving TCP config to self.relative_path_TCPsocket_config.

2019-12-05 14:31:36,499; dataset.py - line: 51 -DEBUG: Create config.
2019-12-05 14:31:36,499; dataset.py - line: 54 -DEBUG: Dataset initialised.

2019-12-05 14:31:36,504; dataset.py - line: 387 -DEBUG: total_branches: [1, 1]
2019-12-05 14:31:36,509; client.py - line: 193 -DEBUG: Json string sent.

2019-12-05 14:31:36,510; client.py - line: 234 -DEBUG: Json string sent.

2019-12-05 14:31:36,610; client.py - line: 209 -DEBUG: Timeout -> exit _receiveData()
2019-12-05 14:31:36,611; client.py - line: 210 -DEBUG: data_complete: type: <class 'bytearray'>, data_complete len: 1, data_complete [:10]: bytearray(b'\x00')
2019-12-05 14:31:36,611; client.py - line: 240 -DEBUG: Trying to receive data.
2019-12-05 14:31:36,747; client.py - line: 209 -DEBUG: Timeout -> exit _receiveData()
2019-12-05 14:31:36,748; client.py - line: 210 -DEBUG: data_complete: type: <class 'bytearray'>, data_complete len: 37613, data_complete [:10]: bytearray(b'\x00\x89PNG\r\n\x1a\n\x00')
2019-12-05 14:31:36,748; client.py - line: 240 -DEBUG: Trying to receive data.
2019-12-05 14:31:36,748; client.py - line: 243 -INFO: Data from Unity received.
2019-12-05 14:31:36,748; client.py - line: 244 -DEBUG: End_tag detected, unity_resp_bytes[0:10]: bytearray(b'\x00\x89PNG\r\n\x1a\n\x00')
2019-12-05 14:31:36,748; client.py - line: 248 -DEBUG: img_bytes type: <class 'bytearray'>, img_bytes len: 37604, img_bytes[:10]: bytearray(b'\x89PNG\r\n\x1a\n\x00\x00')
2019-12-05 14:31:36,769; client.py - line: 251 -DEBUG: PIL Img: type: <class 'PIL.PngImagePlugin.PngImageFile'> 
2019-12-05 14:31:36,784; client.py - line: 253 -DEBUG: Returning img: type: <class 'numpy.ndarray'> 

2019-12-05 14:31:36,784; dataset.py - line: 890 -DEBUG: index: -1
2019-12-05 14:31:36,784; dataset.py - line: 892 -DEBUG: index: 0
2019-12-05 14:31:36,810; dataset.py - line: 387 -DEBUG: total_branches: [1, 1, 2, 1, 2, 2, 1, 1, 1]
2019-12-05 14:31:36,811; client.py - line: 193 -DEBUG: Json string sent.

2019-12-05 14:31:36,811; client.py - line: 234 -DEBUG: Json string sent.

2019-12-05 14:31:37,000; client.py - line: 209 -DEBUG: Timeout -> exit _receiveData()
2019-12-05 14:31:37,001; client.py - line: 210 -DEBUG: data_complete: type: <class 'bytearray'>, data_complete len: 78941, data_complete [:10]: bytearray(b'\x00\x89PNG\r\n\x1a\n\x00')
2019-12-05 14:31:37,001; client.py - line: 240 -DEBUG: Trying to receive data.
2019-12-05 14:31:37,002; client.py - line: 243 -INFO: Data from Unity received.
2019-12-05 14:31:37,003; client.py - line: 244 -DEBUG: End_tag detected, unity_resp_bytes[0:10]: bytearray(b'\x00\x89PNG\r\n\x1a\n\x00')
2019-12-05 14:31:37,003; client.py - line: 248 -DEBUG: img_bytes type: <class 'bytearray'>, img_bytes len: 78932, img_bytes[:10]: bytearray(b'\x89PNG\r\n\x1a\n\x00\x00')
2019-12-05 14:31:37,004; client.py - line: 251 -DEBUG: PIL Img: type: <class 'PIL.PngImagePlugin.PngImageFile'> 
2019-12-05 14:31:37,036; client.py - line: 253 -DEBUG: Returning img: type: <class 'numpy.ndarray'> 

2019-12-05 14:31:37,036; dataset.py - line: 890 -DEBUG: index: 0
2019-12-05 14:31:37,036; dataset.py - line: 892 -DEBUG: index: 1
2019-12-05 14:31:37,081; dataset.py - line: 387 -DEBUG: total_branches: [1, 1, 2, 2, 1, 1, 2, 1]
2019-12-05 14:31:37,082; client.py - line: 193 -DEBUG: Json string sent.

2019-12-05 14:31:37,082; client.py - line: 234 -DEBUG: Json string sent.

2019-12-05 14:31:37,263; client.py - line: 209 -DEBUG: Timeout -> exit _receiveData()
2019-12-05 14:31:37,264; client.py - line: 210 -DEBUG: data_complete: type: <class 'bytearray'>, data_complete len: 127646, data_complete [:10]: bytearray(b'\x00\x89PNG\r\n\x1a\n\x00')
2019-12-05 14:31:37,264; client.py - line: 240 -DEBUG: Trying to receive data.
2019-12-05 14:31:37,264; client.py - line: 243 -INFO: Data from Unity received.
2019-12-05 14:31:37,264; client.py - line: 244 -DEBUG: End_tag detected, unity_resp_bytes[0:10]: bytearray(b'\x00\x89PNG\r\n\x1a\n\x00')
2019-12-05 14:31:37,264; client.py - line: 248 -DEBUG: img_bytes type: <class 'bytearray'>, img_bytes len: 127637, img_bytes[:10]: bytearray(b'\x89PNG\r\n\x1a\n\x00\x00')
2019-12-05 14:31:37,264; client.py - line: 251 -DEBUG: PIL Img: type: <class 'PIL.PngImagePlugin.PngImageFile'> 
2019-12-05 14:31:37,280; client.py - line: 253 -DEBUG: Returning img: type: <class 'numpy.ndarray'> 

2019-12-05 14:31:37,281; dataset.py - line: 890 -DEBUG: index: 1
2019-12-05 14:31:37,281; dataset.py - line: 892 -DEBUG: index: 2
2019-12-05 14:31:37,345; dataset.py - line: 387 -DEBUG: total_branches: [1, 1, 1, 1]
2019-12-05 14:31:37,345; client.py - line: 193 -DEBUG: Json string sent.

2019-12-05 14:31:37,345; client.py - line: 234 -DEBUG: Json string sent.

2019-12-05 14:31:37,513; client.py - line: 209 -DEBUG: Timeout -> exit _receiveData()
2019-12-05 14:31:37,514; client.py - line: 210 -DEBUG: data_complete: type: <class 'bytearray'>, data_complete len: 59879, data_complete [:10]: bytearray(b'\x00\x89PNG\r\n\x1a\n\x00')
2019-12-05 14:31:37,514; client.py - line: 240 -DEBUG: Trying to receive data.
2019-12-05 14:31:37,514; client.py - line: 243 -INFO: Data from Unity received.
2019-12-05 14:31:37,515; client.py - line: 244 -DEBUG: End_tag detected, unity_resp_bytes[0:10]: bytearray(b'\x00\x89PNG\r\n\x1a\n\x00')
2019-12-05 14:31:37,515; client.py - line: 248 -DEBUG: img_bytes type: <class 'bytearray'>, img_bytes len: 59870, img_bytes[:10]: bytearray(b'\x89PNG\r\n\x1a\n\x00\x00')
2019-12-05 14:31:37,516; client.py - line: 251 -DEBUG: PIL Img: type: <class 'PIL.PngImagePlugin.PngImageFile'> 
2019-12-05 14:31:37,545; client.py - line: 253 -DEBUG: Returning img: type: <class 'numpy.ndarray'> 

2019-12-05 14:31:37,545; dataset.py - line: 890 -DEBUG: index: 2
2019-12-05 14:31:37,546; dataset.py - line: 892 -DEBUG: index: 3
2019-12-05 14:31:37,581; dataset.py - line: 387 -DEBUG: total_branches: [1, 1, 1, 1, 2, 1]
2019-12-05 14:31:37,582; client.py - line: 193 -DEBUG: Json string sent.

2019-12-05 14:31:37,583; client.py - line: 234 -DEBUG: Json string sent.

2019-12-05 14:31:37,758; client.py - line: 209 -DEBUG: Timeout -> exit _receiveData()
2019-12-05 14:31:37,759; client.py - line: 210 -DEBUG: data_complete: type: <class 'bytearray'>, data_complete len: 32792, data_complete [:10]: bytearray(b'\x00\x89PNG\r\n\x1a\n\x00')
2019-12-05 14:31:37,759; client.py - line: 240 -DEBUG: Trying to receive data.
2019-12-05 14:31:37,759; client.py - line: 243 -INFO: Data from Unity received.
2019-12-05 14:31:37,760; client.py - line: 244 -DEBUG: End_tag detected, unity_resp_bytes[0:10]: bytearray(b'\x00\x89PNG\r\n\x1a\n\x00')
2019-12-05 14:31:37,760; client.py - line: 248 -DEBUG: img_bytes type: <class 'bytearray'>, img_bytes len: 32783, img_bytes[:10]: bytearray(b'\x89PNG\r\n\x1a\n\x00\x00')
2019-12-05 14:31:37,761; client.py - line: 251 -DEBUG: PIL Img: type: <class 'PIL.PngImagePlugin.PngImageFile'> 
2019-12-05 14:31:37,787; client.py - line: 253 -DEBUG: Returning img: type: <class 'numpy.ndarray'> 

2019-12-05 14:31:37,787; dataset.py - line: 890 -DEBUG: index: 3
2019-12-05 14:31:37,788; dataset.py - line: 892 -DEBUG: index: 4
2019-12-05 14:31:37,811; dataset.py - line: 387 -DEBUG: total_branches: [1, 1]
2019-12-05 14:31:37,812; client.py - line: 193 -DEBUG: Json string sent.

2019-12-05 14:31:37,812; client.py - line: 234 -DEBUG: Json string sent.

2019-12-05 14:31:38,011; client.py - line: 209 -DEBUG: Timeout -> exit _receiveData()
2019-12-05 14:31:38,011; client.py - line: 210 -DEBUG: data_complete: type: <class 'bytearray'>, data_complete len: 58517, data_complete [:10]: bytearray(b'\x00\x89PNG\r\n\x1a\n\x00')
2019-12-05 14:31:38,012; client.py - line: 240 -DEBUG: Trying to receive data.
2019-12-05 14:31:38,012; client.py - line: 243 -INFO: Data from Unity received.
2019-12-05 14:31:38,012; client.py - line: 244 -DEBUG: End_tag detected, unity_resp_bytes[0:10]: bytearray(b'\x00\x89PNG\r\n\x1a\n\x00')
2019-12-05 14:31:38,013; client.py - line: 248 -DEBUG: img_bytes type: <class 'bytearray'>, img_bytes len: 58508, img_bytes[:10]: bytearray(b'\x89PNG\r\n\x1a\n\x00\x00')
2019-12-05 14:31:38,013; client.py - line: 251 -DEBUG: PIL Img: type: <class 'PIL.PngImagePlugin.PngImageFile'> 
2019-12-05 14:31:38,044; client.py - line: 253 -DEBUG: Returning img: type: <class 'numpy.ndarray'> 

2019-12-05 14:31:38,044; dataset.py - line: 890 -DEBUG: index: 4
2019-12-05 14:31:38,044; dataset.py - line: 892 -DEBUG: index: 5
2019-12-05 14:31:38,081; dataset.py - line: 387 -DEBUG: total_branches: [1]
2019-12-05 14:31:38,082; client.py - line: 193 -DEBUG: Json string sent.

2019-12-05 14:31:38,082; client.py - line: 234 -DEBUG: Json string sent.

2019-12-05 14:31:38,241; client.py - line: 209 -DEBUG: Timeout -> exit _receiveData()
2019-12-05 14:31:38,242; client.py - line: 210 -DEBUG: data_complete: type: <class 'bytearray'>, data_complete len: 42923, data_complete [:10]: bytearray(b'\x00\x89PNG\r\n\x1a\n\x00')
2019-12-05 14:31:38,242; client.py - line: 240 -DEBUG: Trying to receive data.
2019-12-05 14:31:38,242; client.py - line: 243 -INFO: Data from Unity received.
2019-12-05 14:31:38,242; client.py - line: 244 -DEBUG: End_tag detected, unity_resp_bytes[0:10]: bytearray(b'\x00\x89PNG\r\n\x1a\n\x00')
2019-12-05 14:31:38,243; client.py - line: 248 -DEBUG: img_bytes type: <class 'bytearray'>, img_bytes len: 42914, img_bytes[:10]: bytearray(b'\x89PNG\r\n\x1a\n\x00\x00')
2019-12-05 14:31:38,243; client.py - line: 251 -DEBUG: PIL Img: type: <class 'PIL.PngImagePlugin.PngImageFile'> 
2019-12-05 14:31:38,264; client.py - line: 253 -DEBUG: Returning img: type: <class 'numpy.ndarray'> 

2019-12-05 14:31:38,264; dataset.py - line: 890 -DEBUG: index: 5
2019-12-05 14:31:38,264; dataset.py - line: 892 -DEBUG: index: 6
2019-12-05 14:31:38,294; dataset.py - line: 387 -DEBUG: total_branches: [1, 1, 1, 1, 1, 1]
2019-12-05 14:31:38,296; client.py - line: 193 -DEBUG: Json string sent.

2019-12-05 14:31:38,296; client.py - line: 234 -DEBUG: Json string sent.

2019-12-05 14:31:38,456; client.py - line: 209 -DEBUG: Timeout -> exit _receiveData()
2019-12-05 14:31:38,457; client.py - line: 210 -DEBUG: data_complete: type: <class 'bytearray'>, data_complete len: 20971, data_complete [:10]: bytearray(b'\x00\x89PNG\r\n\x1a\n\x00')
2019-12-05 14:31:38,457; client.py - line: 240 -DEBUG: Trying to receive data.
2019-12-05 14:31:38,458; client.py - line: 243 -INFO: Data from Unity received.
2019-12-05 14:31:38,459; client.py - line: 244 -DEBUG: End_tag detected, unity_resp_bytes[0:10]: bytearray(b'\x00\x89PNG\r\n\x1a\n\x00')
2019-12-05 14:31:38,459; client.py - line: 248 -DEBUG: img_bytes type: <class 'bytearray'>, img_bytes len: 20962, img_bytes[:10]: bytearray(b'\x89PNG\r\n\x1a\n\x00\x00')
2019-12-05 14:31:38,460; client.py - line: 251 -DEBUG: PIL Img: type: <class 'PIL.PngImagePlugin.PngImageFile'> 
2019-12-05 14:31:38,481; client.py - line: 253 -DEBUG: Returning img: type: <class 'numpy.ndarray'> 

2019-12-05 14:31:38,482; dataset.py - line: 890 -DEBUG: index: 6
2019-12-05 14:31:38,482; dataset.py - line: 892 -DEBUG: index: 7
2019-12-05 14:31:38,504; dataset.py - line: 387 -DEBUG: total_branches: [1, 1, 1]
2019-12-05 14:31:38,505; client.py - line: 193 -DEBUG: Json string sent.

2019-12-05 14:31:38,505; client.py - line: 234 -DEBUG: Json string sent.

2019-12-05 14:31:38,699; client.py - line: 209 -DEBUG: Timeout -> exit _receiveData()
2019-12-05 14:31:38,700; client.py - line: 210 -DEBUG: data_complete: type: <class 'bytearray'>, data_complete len: 36290, data_complete [:10]: bytearray(b'\x00\x89PNG\r\n\x1a\n\x00')
2019-12-05 14:31:38,700; client.py - line: 240 -DEBUG: Trying to receive data.
2019-12-05 14:31:38,700; client.py - line: 243 -INFO: Data from Unity received.
2019-12-05 14:31:38,701; client.py - line: 244 -DEBUG: End_tag detected, unity_resp_bytes[0:10]: bytearray(b'\x00\x89PNG\r\n\x1a\n\x00')
2019-12-05 14:31:38,701; client.py - line: 248 -DEBUG: img_bytes type: <class 'bytearray'>, img_bytes len: 36281, img_bytes[:10]: bytearray(b'\x89PNG\r\n\x1a\n\x00\x00')
2019-12-05 14:31:38,702; client.py - line: 251 -DEBUG: PIL Img: type: <class 'PIL.PngImagePlugin.PngImageFile'> 
2019-12-05 14:31:38,730; client.py - line: 253 -DEBUG: Returning img: type: <class 'numpy.ndarray'> 

2019-12-05 14:31:38,731; dataset.py - line: 890 -DEBUG: index: 7
2019-12-05 14:31:38,731; dataset.py - line: 892 -DEBUG: index: 8
2019-12-05 14:31:38,758; dataset.py - line: 387 -DEBUG: total_branches: [1, 1, 2, 1, 1, 1, 1, 2, 2]
2019-12-05 14:31:38,758; client.py - line: 193 -DEBUG: Json string sent.

2019-12-05 14:31:38,759; client.py - line: 234 -DEBUG: Json string sent.

2019-12-05 14:31:38,928; client.py - line: 209 -DEBUG: Timeout -> exit _receiveData()
2019-12-05 14:31:38,928; client.py - line: 210 -DEBUG: data_complete: type: <class 'bytearray'>, data_complete len: 31625, data_complete [:10]: bytearray(b'\x00\x89PNG\r\n\x1a\n\x00')
2019-12-05 14:31:38,928; client.py - line: 240 -DEBUG: Trying to receive data.
2019-12-05 14:31:38,928; client.py - line: 243 -INFO: Data from Unity received.
2019-12-05 14:31:38,928; client.py - line: 244 -DEBUG: End_tag detected, unity_resp_bytes[0:10]: bytearray(b'\x00\x89PNG\r\n\x1a\n\x00')
2019-12-05 14:31:38,928; client.py - line: 248 -DEBUG: img_bytes type: <class 'bytearray'>, img_bytes len: 31616, img_bytes[:10]: bytearray(b'\x89PNG\r\n\x1a\n\x00\x00')
2019-12-05 14:31:38,928; client.py - line: 251 -DEBUG: PIL Img: type: <class 'PIL.PngImagePlugin.PngImageFile'> 
2019-12-05 14:31:38,936; client.py - line: 253 -DEBUG: Returning img: type: <class 'numpy.ndarray'> 

2019-12-05 14:31:38,937; dataset.py - line: 890 -DEBUG: index: 8
2019-12-05 14:31:38,937; dataset.py - line: 892 -DEBUG: index: 9
2019-12-05 14:31:38,961; client.py - line: 173 -INFO: Exit-message is sent. Unity build and socket now closing.

2019-12-05 14:31:38,962; client.py - line: 190 -DEBUG: Exit request sent.

2019-12-05 14:31:38,962; dataset.py - line: 933 -DEBUG: Exit socket connection to unity.
2019-12-05 14:31:38,962; dataset.py - line: 669 -DEBUG: numb_y: 2
2019-12-05 14:31:38,962; dataset.py - line: 670 -DEBUG: dicts[0]['image'].shape[0]: 520
2019-12-05 14:31:38,962; dataset.py - line: 671 -DEBUG: (images_per_row*dicts[0][image].shape[1]: 2600
2019-12-05 14:31:38,963; dataset.py - line: 672 -DEBUG: dicts[0][image].shape[2]: 3
2019-12-05 14:31:38,973; dataset.py - line: 674 -DEBUG: h_stacked.shape: (2, 520, 2600, 3)
2019-12-05 14:31:39,020; dataset.py - line: 687 -DEBUG: final_img.shape: (1040, 2600, 3)
