2020-04-23 17:59:54,146; client.py - line: 58 -DEBUG: Starting python client.
2020-04-23 17:59:54,146; client.py - line: 78 -INFO: Starting Unity...
2020-04-23 17:59:54,147; client.py - line: 79 -DEBUG: path to unity: /home/haecker/Documents/src/python_unity_images/build_linux/unity_server_rendering_images.x86_64
2020-04-23 17:59:54,149; client.py - line: 92 -INFO: Waiting for unity...
2020-04-23 17:59:57,153; client.py - line: 119 -INFO: Client now connecting to server.
2020-04-23 17:59:57,153; client.py - line: 127 -DEBUG: Config data for TCP socket: host: 127.0.0.1; port: 50050
2020-04-23 17:59:57,154; client.py - line: 140 -DEBUG: Socket can not connect. Make sure that the tcp_server from unity is already running.
2020-04-23 17:59:57,154; client.py - line: 141 -DEBUG: [Errno 111] Connection refused
2020-04-23 17:59:57,204; client.py - line: 149 -DEBUG: Try next port: 49990
2020-04-23 17:59:57,204; client.py - line: 140 -DEBUG: Socket can not connect. Make sure that the tcp_server from unity is already running.
2020-04-23 17:59:57,204; client.py - line: 141 -DEBUG: [Errno 103] Software caused connection abort
2020-04-23 17:59:57,254; client.py - line: 149 -DEBUG: Try next port: 49991
2020-04-23 17:59:57,255; client.py - line: 140 -DEBUG: Socket can not connect. Make sure that the tcp_server from unity is already running.
2020-04-23 17:59:57,255; client.py - line: 141 -DEBUG: [Errno 111] Connection refused
2020-04-23 17:59:57,305; client.py - line: 149 -DEBUG: Try next port: 49992
2020-04-23 17:59:57,305; client.py - line: 140 -DEBUG: Socket can not connect. Make sure that the tcp_server from unity is already running.
2020-04-23 17:59:57,305; client.py - line: 141 -DEBUG: [Errno 103] Software caused connection abort
2020-04-23 17:59:57,355; client.py - line: 149 -DEBUG: Try next port: 49993
2020-04-23 17:59:57,356; client.py - line: 140 -DEBUG: Socket can not connect. Make sure that the tcp_server from unity is already running.
2020-04-23 17:59:57,356; client.py - line: 141 -DEBUG: [Errno 111] Connection refused
2020-04-23 17:59:57,406; client.py - line: 149 -DEBUG: Try next port: 49994
2020-04-23 17:59:57,406; client.py - line: 140 -DEBUG: Socket can not connect. Make sure that the tcp_server from unity is already running.
2020-04-23 17:59:57,406; client.py - line: 141 -DEBUG: [Errno 103] Software caused connection abort
2020-04-23 17:59:57,456; client.py - line: 149 -DEBUG: Try next port: 49995
2020-04-23 17:59:57,457; client.py - line: 140 -DEBUG: Socket can not connect. Make sure that the tcp_server from unity is already running.
2020-04-23 17:59:57,457; client.py - line: 141 -DEBUG: [Errno 111] Connection refused
2020-04-23 17:59:57,507; client.py - line: 149 -DEBUG: Try next port: 49996
2020-04-23 17:59:57,507; client.py - line: 140 -DEBUG: Socket can not connect. Make sure that the tcp_server from unity is already running.
2020-04-23 17:59:57,507; client.py - line: 141 -DEBUG: [Errno 103] Software caused connection abort
2020-04-23 17:59:57,558; client.py - line: 149 -DEBUG: Try next port: 49997
2020-04-23 17:59:57,558; client.py - line: 140 -DEBUG: Socket can not connect. Make sure that the tcp_server from unity is already running.
2020-04-23 17:59:57,558; client.py - line: 141 -DEBUG: [Errno 111] Connection refused
2020-04-23 17:59:57,608; client.py - line: 149 -DEBUG: Try next port: 49998
2020-04-23 17:59:57,609; client.py - line: 140 -DEBUG: Socket can not connect. Make sure that the tcp_server from unity is already running.
2020-04-23 17:59:57,609; client.py - line: 141 -DEBUG: [Errno 103] Software caused connection abort
2020-04-23 17:59:57,659; client.py - line: 149 -DEBUG: Try next port: 49999
2020-04-23 17:59:57,659; client.py - line: 140 -DEBUG: Socket can not connect. Make sure that the tcp_server from unity is already running.
2020-04-23 17:59:57,659; client.py - line: 141 -DEBUG: [Errno 111] Connection refused
2020-04-23 17:59:57,709; client.py - line: 149 -DEBUG: Try next port: 50000
2020-04-23 17:59:57,710; client.py - line: 140 -DEBUG: Socket can not connect. Make sure that the tcp_server from unity is already running.
2020-04-23 17:59:57,710; client.py - line: 141 -DEBUG: [Errno 103] Software caused connection abort
2020-04-23 17:59:57,760; client.py - line: 149 -DEBUG: Try next port: 50001
2020-04-23 17:59:57,761; client.py - line: 140 -DEBUG: Socket can not connect. Make sure that the tcp_server from unity is already running.
2020-04-23 17:59:57,762; client.py - line: 141 -DEBUG: [Errno 111] Connection refused
2020-04-23 17:59:57,812; client.py - line: 149 -DEBUG: Try next port: 50002
2020-04-23 17:59:57,813; client.py - line: 140 -DEBUG: Socket can not connect. Make sure that the tcp_server from unity is already running.
2020-04-23 17:59:57,813; client.py - line: 141 -DEBUG: [Errno 103] Software caused connection abort
2020-04-23 17:59:57,864; client.py - line: 149 -DEBUG: Try next port: 50003
2020-04-23 17:59:57,865; client.py - line: 140 -DEBUG: Socket can not connect. Make sure that the tcp_server from unity is already running.
2020-04-23 17:59:57,865; client.py - line: 141 -DEBUG: [Errno 111] Connection refused
2020-04-23 17:59:57,916; client.py - line: 149 -DEBUG: Try next port: 50004
2020-04-23 17:59:57,916; client.py - line: 140 -DEBUG: Socket can not connect. Make sure that the tcp_server from unity is already running.
2020-04-23 17:59:57,916; client.py - line: 141 -DEBUG: [Errno 103] Software caused connection abort
2020-04-23 17:59:57,967; client.py - line: 149 -DEBUG: Try next port: 50005
2020-04-23 17:59:57,968; client.py - line: 140 -DEBUG: Socket can not connect. Make sure that the tcp_server from unity is already running.
2020-04-23 17:59:57,968; client.py - line: 141 -DEBUG: [Errno 111] Connection refused
2020-04-23 17:59:58,019; client.py - line: 149 -DEBUG: Try next port: 50006
2020-04-23 17:59:58,020; client.py - line: 140 -DEBUG: Socket can not connect. Make sure that the tcp_server from unity is already running.
2020-04-23 17:59:58,020; client.py - line: 141 -DEBUG: [Errno 103] Software caused connection abort
2020-04-23 17:59:58,070; client.py - line: 149 -DEBUG: Try next port: 50007
2020-04-23 17:59:58,071; client.py - line: 140 -DEBUG: Socket can not connect. Make sure that the tcp_server from unity is already running.
2020-04-23 17:59:58,072; client.py - line: 141 -DEBUG: [Errno 111] Connection refused
2020-04-23 17:59:58,122; client.py - line: 149 -DEBUG: Try next port: 50008
2020-04-23 17:59:58,123; client.py - line: 140 -DEBUG: Socket can not connect. Make sure that the tcp_server from unity is already running.
2020-04-23 17:59:58,123; client.py - line: 141 -DEBUG: [Errno 103] Software caused connection abort
2020-04-23 17:59:58,174; client.py - line: 149 -DEBUG: Try next port: 50009
2020-04-23 17:59:58,174; client.py - line: 140 -DEBUG: Socket can not connect. Make sure that the tcp_server from unity is already running.
2020-04-23 17:59:58,174; client.py - line: 141 -DEBUG: [Errno 111] Connection refused
2020-04-23 17:59:58,225; client.py - line: 149 -DEBUG: Try next port: 50010
2020-04-23 17:59:58,225; client.py - line: 140 -DEBUG: Socket can not connect. Make sure that the tcp_server from unity is already running.
2020-04-23 17:59:58,225; client.py - line: 141 -DEBUG: [Errno 103] Software caused connection abort
2020-04-23 17:59:58,275; client.py - line: 149 -DEBUG: Try next port: 50011
2020-04-23 17:59:58,275; client.py - line: 140 -DEBUG: Socket can not connect. Make sure that the tcp_server from unity is already running.
2020-04-23 17:59:58,275; client.py - line: 141 -DEBUG: [Errno 111] Connection refused
2020-04-23 17:59:58,326; client.py - line: 149 -DEBUG: Try next port: 50012
2020-04-23 17:59:58,326; client.py - line: 140 -DEBUG: Socket can not connect. Make sure that the tcp_server from unity is already running.
2020-04-23 17:59:58,326; client.py - line: 141 -DEBUG: [Errno 103] Software caused connection abort
2020-04-23 17:59:58,376; client.py - line: 149 -DEBUG: Try next port: 50013
2020-04-23 17:59:58,377; client.py - line: 140 -DEBUG: Socket can not connect. Make sure that the tcp_server from unity is already running.
2020-04-23 17:59:58,377; client.py - line: 141 -DEBUG: [Errno 111] Connection refused
2020-04-23 17:59:58,427; client.py - line: 149 -DEBUG: Try next port: 50014
2020-04-23 17:59:58,427; client.py - line: 140 -DEBUG: Socket can not connect. Make sure that the tcp_server from unity is already running.
2020-04-23 17:59:58,427; client.py - line: 141 -DEBUG: [Errno 103] Software caused connection abort
2020-04-23 17:59:58,478; client.py - line: 149 -DEBUG: Try next port: 50015
2020-04-23 17:59:58,478; client.py - line: 140 -DEBUG: Socket can not connect. Make sure that the tcp_server from unity is already running.
2020-04-23 17:59:58,478; client.py - line: 141 -DEBUG: [Errno 111] Connection refused
2020-04-23 17:59:58,528; client.py - line: 149 -DEBUG: Try next port: 50016
2020-04-23 17:59:58,528; client.py - line: 140 -DEBUG: Socket can not connect. Make sure that the tcp_server from unity is already running.
2020-04-23 17:59:58,528; client.py - line: 141 -DEBUG: [Errno 103] Software caused connection abort
2020-04-23 17:59:58,578; client.py - line: 149 -DEBUG: Try next port: 50017
2020-04-23 17:59:58,579; client.py - line: 140 -DEBUG: Socket can not connect. Make sure that the tcp_server from unity is already running.
2020-04-23 17:59:58,579; client.py - line: 141 -DEBUG: [Errno 111] Connection refused
2020-04-23 17:59:58,629; client.py - line: 149 -DEBUG: Try next port: 50018
2020-04-23 17:59:58,629; client.py - line: 140 -DEBUG: Socket can not connect. Make sure that the tcp_server from unity is already running.
2020-04-23 17:59:58,629; client.py - line: 141 -DEBUG: [Errno 103] Software caused connection abort
2020-04-23 17:59:58,680; client.py - line: 149 -DEBUG: Try next port: 50019
2020-04-23 17:59:58,680; client.py - line: 140 -DEBUG: Socket can not connect. Make sure that the tcp_server from unity is already running.
2020-04-23 17:59:58,681; client.py - line: 141 -DEBUG: [Errno 111] Connection refused
2020-04-23 17:59:58,731; client.py - line: 149 -DEBUG: Try next port: 50020
2020-04-23 17:59:58,732; client.py - line: 140 -DEBUG: Socket can not connect. Make sure that the tcp_server from unity is already running.
2020-04-23 17:59:58,732; client.py - line: 141 -DEBUG: [Errno 103] Software caused connection abort
2020-04-23 17:59:58,782; client.py - line: 149 -DEBUG: Try next port: 50021
2020-04-23 17:59:58,782; client.py - line: 140 -DEBUG: Socket can not connect. Make sure that the tcp_server from unity is already running.
2020-04-23 17:59:58,782; client.py - line: 141 -DEBUG: [Errno 111] Connection refused
2020-04-23 17:59:58,833; client.py - line: 149 -DEBUG: Try next port: 50022
2020-04-23 17:59:58,833; client.py - line: 140 -DEBUG: Socket can not connect. Make sure that the tcp_server from unity is already running.
2020-04-23 17:59:58,833; client.py - line: 141 -DEBUG: [Errno 103] Software caused connection abort
2020-04-23 17:59:58,883; client.py - line: 149 -DEBUG: Try next port: 50023
2020-04-23 17:59:58,884; client.py - line: 140 -DEBUG: Socket can not connect. Make sure that the tcp_server from unity is already running.
2020-04-23 17:59:58,885; client.py - line: 141 -DEBUG: [Errno 111] Connection refused
2020-04-23 17:59:58,935; client.py - line: 149 -DEBUG: Try next port: 50024
2020-04-23 17:59:58,936; client.py - line: 140 -DEBUG: Socket can not connect. Make sure that the tcp_server from unity is already running.
2020-04-23 17:59:58,936; client.py - line: 141 -DEBUG: [Errno 103] Software caused connection abort
2020-04-23 17:59:58,986; client.py - line: 149 -DEBUG: Try next port: 50025
2020-04-23 17:59:58,987; client.py - line: 140 -DEBUG: Socket can not connect. Make sure that the tcp_server from unity is already running.
2020-04-23 17:59:58,987; client.py - line: 141 -DEBUG: [Errno 111] Connection refused
2020-04-23 17:59:59,037; client.py - line: 149 -DEBUG: Try next port: 50026
2020-04-23 17:59:59,037; client.py - line: 140 -DEBUG: Socket can not connect. Make sure that the tcp_server from unity is already running.
2020-04-23 17:59:59,037; client.py - line: 141 -DEBUG: [Errno 103] Software caused connection abort
2020-04-23 17:59:59,088; client.py - line: 149 -DEBUG: Try next port: 50027
2020-04-23 17:59:59,088; client.py - line: 140 -DEBUG: Socket can not connect. Make sure that the tcp_server from unity is already running.
2020-04-23 17:59:59,088; client.py - line: 141 -DEBUG: [Errno 111] Connection refused
2020-04-23 17:59:59,139; client.py - line: 149 -DEBUG: Try next port: 50028
2020-04-23 17:59:59,139; client.py - line: 140 -DEBUG: Socket can not connect. Make sure that the tcp_server from unity is already running.
2020-04-23 17:59:59,139; client.py - line: 141 -DEBUG: [Errno 103] Software caused connection abort
2020-04-23 17:59:59,190; client.py - line: 149 -DEBUG: Try next port: 50029
2020-04-23 17:59:59,190; client.py - line: 140 -DEBUG: Socket can not connect. Make sure that the tcp_server from unity is already running.
2020-04-23 17:59:59,190; client.py - line: 141 -DEBUG: [Errno 111] Connection refused
2020-04-23 17:59:59,241; client.py - line: 149 -DEBUG: Try next port: 50030
2020-04-23 17:59:59,241; client.py - line: 140 -DEBUG: Socket can not connect. Make sure that the tcp_server from unity is already running.
2020-04-23 17:59:59,241; client.py - line: 141 -DEBUG: [Errno 103] Software caused connection abort
2020-04-23 17:59:59,291; client.py - line: 149 -DEBUG: Try next port: 50031
2020-04-23 17:59:59,292; client.py - line: 140 -DEBUG: Socket can not connect. Make sure that the tcp_server from unity is already running.
2020-04-23 17:59:59,293; client.py - line: 141 -DEBUG: [Errno 111] Connection refused
2020-04-23 17:59:59,343; client.py - line: 149 -DEBUG: Try next port: 50032
2020-04-23 17:59:59,343; client.py - line: 140 -DEBUG: Socket can not connect. Make sure that the tcp_server from unity is already running.
2020-04-23 17:59:59,343; client.py - line: 141 -DEBUG: [Errno 103] Software caused connection abort
2020-04-23 17:59:59,394; client.py - line: 149 -DEBUG: Try next port: 50033
2020-04-23 17:59:59,394; client.py - line: 140 -DEBUG: Socket can not connect. Make sure that the tcp_server from unity is already running.
2020-04-23 17:59:59,394; client.py - line: 141 -DEBUG: [Errno 111] Connection refused
2020-04-23 17:59:59,444; client.py - line: 149 -DEBUG: Try next port: 50034
2020-04-23 17:59:59,445; client.py - line: 140 -DEBUG: Socket can not connect. Make sure that the tcp_server from unity is already running.
2020-04-23 17:59:59,445; client.py - line: 141 -DEBUG: [Errno 103] Software caused connection abort
2020-04-23 17:59:59,495; client.py - line: 149 -DEBUG: Try next port: 50035
2020-04-23 17:59:59,495; client.py - line: 140 -DEBUG: Socket can not connect. Make sure that the tcp_server from unity is already running.
2020-04-23 17:59:59,495; client.py - line: 141 -DEBUG: [Errno 111] Connection refused
2020-04-23 17:59:59,546; client.py - line: 149 -DEBUG: Try next port: 50036
2020-04-23 17:59:59,546; client.py - line: 140 -DEBUG: Socket can not connect. Make sure that the tcp_server from unity is already running.
2020-04-23 17:59:59,547; client.py - line: 141 -DEBUG: [Errno 103] Software caused connection abort
2020-04-23 17:59:59,597; client.py - line: 149 -DEBUG: Try next port: 50037
2020-04-23 17:59:59,597; client.py - line: 140 -DEBUG: Socket can not connect. Make sure that the tcp_server from unity is already running.
2020-04-23 17:59:59,597; client.py - line: 141 -DEBUG: [Errno 111] Connection refused
2020-04-23 17:59:59,648; client.py - line: 149 -DEBUG: Try next port: 50038
2020-04-23 17:59:59,648; client.py - line: 140 -DEBUG: Socket can not connect. Make sure that the tcp_server from unity is already running.
2020-04-23 17:59:59,648; client.py - line: 141 -DEBUG: [Errno 103] Software caused connection abort
2020-04-23 17:59:59,698; client.py - line: 149 -DEBUG: Try next port: 50039
2020-04-23 17:59:59,699; client.py - line: 140 -DEBUG: Socket can not connect. Make sure that the tcp_server from unity is already running.
2020-04-23 17:59:59,699; client.py - line: 141 -DEBUG: [Errno 111] Connection refused
2020-04-23 17:59:59,749; client.py - line: 149 -DEBUG: Try next port: 50040
2020-04-23 17:59:59,750; client.py - line: 140 -DEBUG: Socket can not connect. Make sure that the tcp_server from unity is already running.
2020-04-23 17:59:59,750; client.py - line: 141 -DEBUG: [Errno 103] Software caused connection abort
2020-04-23 17:59:59,800; client.py - line: 149 -DEBUG: Try next port: 50041
2020-04-23 17:59:59,801; client.py - line: 140 -DEBUG: Socket can not connect. Make sure that the tcp_server from unity is already running.
2020-04-23 17:59:59,801; client.py - line: 141 -DEBUG: [Errno 111] Connection refused
2020-04-23 17:59:59,851; client.py - line: 149 -DEBUG: Try next port: 50042
2020-04-23 17:59:59,852; client.py - line: 140 -DEBUG: Socket can not connect. Make sure that the tcp_server from unity is already running.
2020-04-23 17:59:59,852; client.py - line: 141 -DEBUG: [Errno 103] Software caused connection abort
2020-04-23 17:59:59,903; client.py - line: 149 -DEBUG: Try next port: 50043
2020-04-23 17:59:59,903; client.py - line: 140 -DEBUG: Socket can not connect. Make sure that the tcp_server from unity is already running.
2020-04-23 17:59:59,903; client.py - line: 141 -DEBUG: [Errno 111] Connection refused
2020-04-23 17:59:59,953; client.py - line: 149 -DEBUG: Try next port: 50044
2020-04-23 17:59:59,953; client.py - line: 140 -DEBUG: Socket can not connect. Make sure that the tcp_server from unity is already running.
2020-04-23 17:59:59,953; client.py - line: 141 -DEBUG: [Errno 103] Software caused connection abort
2020-04-23 18:00:00,004; client.py - line: 149 -DEBUG: Try next port: 50045
2020-04-23 18:00:00,004; client.py - line: 140 -DEBUG: Socket can not connect. Make sure that the tcp_server from unity is already running.
2020-04-23 18:00:00,004; client.py - line: 141 -DEBUG: [Errno 111] Connection refused
2020-04-23 18:00:00,054; client.py - line: 149 -DEBUG: Try next port: 50046
2020-04-23 18:00:00,055; client.py - line: 140 -DEBUG: Socket can not connect. Make sure that the tcp_server from unity is already running.
2020-04-23 18:00:00,055; client.py - line: 141 -DEBUG: [Errno 103] Software caused connection abort
2020-04-23 18:00:00,105; client.py - line: 149 -DEBUG: Try next port: 50047
2020-04-23 18:00:00,106; client.py - line: 140 -DEBUG: Socket can not connect. Make sure that the tcp_server from unity is already running.
2020-04-23 18:00:00,106; client.py - line: 141 -DEBUG: [Errno 111] Connection refused
2020-04-23 18:00:00,156; client.py - line: 149 -DEBUG: Try next port: 50048
2020-04-23 18:00:00,157; client.py - line: 140 -DEBUG: Socket can not connect. Make sure that the tcp_server from unity is already running.
2020-04-23 18:00:00,157; client.py - line: 141 -DEBUG: [Errno 103] Software caused connection abort
2020-04-23 18:00:00,208; client.py - line: 149 -DEBUG: Try next port: 50049
2020-04-23 18:00:00,208; client.py - line: 140 -DEBUG: Socket can not connect. Make sure that the tcp_server from unity is already running.
2020-04-23 18:00:00,208; client.py - line: 141 -DEBUG: [Errno 111] Connection refused
2020-04-23 18:00:00,258; client.py - line: 149 -DEBUG: Try next port: 50050
2020-04-23 18:00:00,259; client.py - line: 140 -DEBUG: Socket can not connect. Make sure that the tcp_server from unity is already running.
2020-04-23 18:00:00,260; client.py - line: 141 -DEBUG: [Errno 103] Software caused connection abort
2020-04-23 18:00:00,310; client.py - line: 149 -DEBUG: Try next port: 49990
2020-04-23 18:00:00,311; client.py - line: 140 -DEBUG: Socket can not connect. Make sure that the tcp_server from unity is already running.
2020-04-23 18:00:00,311; client.py - line: 141 -DEBUG: [Errno 111] Connection refused
2020-04-23 18:00:00,361; client.py - line: 149 -DEBUG: Try next port: 49991
2020-04-23 18:00:00,362; client.py - line: 140 -DEBUG: Socket can not connect. Make sure that the tcp_server from unity is already running.
2020-04-23 18:00:00,363; client.py - line: 141 -DEBUG: [Errno 103] Software caused connection abort
2020-04-23 18:00:00,413; client.py - line: 149 -DEBUG: Try next port: 49992
2020-04-23 18:00:00,413; client.py - line: 140 -DEBUG: Socket can not connect. Make sure that the tcp_server from unity is already running.
2020-04-23 18:00:00,413; client.py - line: 141 -DEBUG: [Errno 111] Connection refused
2020-04-23 18:00:00,464; client.py - line: 149 -DEBUG: Try next port: 49993
2020-04-23 18:00:00,464; client.py - line: 140 -DEBUG: Socket can not connect. Make sure that the tcp_server from unity is already running.
2020-04-23 18:00:00,464; client.py - line: 141 -DEBUG: [Errno 103] Software caused connection abort
2020-04-23 18:00:00,514; client.py - line: 149 -DEBUG: Try next port: 49994
2020-04-23 18:00:00,514; client.py - line: 140 -DEBUG: Socket can not connect. Make sure that the tcp_server from unity is already running.
2020-04-23 18:00:00,514; client.py - line: 141 -DEBUG: [Errno 111] Connection refused
2020-04-23 18:00:00,565; client.py - line: 149 -DEBUG: Try next port: 49995
2020-04-23 18:00:00,565; client.py - line: 140 -DEBUG: Socket can not connect. Make sure that the tcp_server from unity is already running.
2020-04-23 18:00:00,565; client.py - line: 141 -DEBUG: [Errno 103] Software caused connection abort
2020-04-23 18:00:00,615; client.py - line: 149 -DEBUG: Try next port: 49996
2020-04-23 18:00:00,616; client.py - line: 140 -DEBUG: Socket can not connect. Make sure that the tcp_server from unity is already running.
2020-04-23 18:00:00,617; client.py - line: 141 -DEBUG: [Errno 111] Connection refused
2020-04-23 18:00:00,667; client.py - line: 149 -DEBUG: Try next port: 49997
2020-04-23 18:00:00,668; client.py - line: 140 -DEBUG: Socket can not connect. Make sure that the tcp_server from unity is already running.
2020-04-23 18:00:00,668; client.py - line: 141 -DEBUG: [Errno 103] Software caused connection abort
2020-04-23 18:00:00,719; client.py - line: 149 -DEBUG: Try next port: 49998
2020-04-23 18:00:00,719; client.py - line: 140 -DEBUG: Socket can not connect. Make sure that the tcp_server from unity is already running.
2020-04-23 18:00:00,719; client.py - line: 141 -DEBUG: [Errno 111] Connection refused
2020-04-23 18:00:00,770; client.py - line: 149 -DEBUG: Try next port: 49999
2020-04-23 18:00:00,770; client.py - line: 140 -DEBUG: Socket can not connect. Make sure that the tcp_server from unity is already running.
2020-04-23 18:00:00,770; client.py - line: 141 -DEBUG: [Errno 103] Software caused connection abort
2020-04-23 18:00:00,821; client.py - line: 149 -DEBUG: Try next port: 50000
2020-04-23 18:00:00,821; client.py - line: 140 -DEBUG: Socket can not connect. Make sure that the tcp_server from unity is already running.
2020-04-23 18:00:00,821; client.py - line: 141 -DEBUG: [Errno 111] Connection refused
2020-04-23 18:00:00,871; client.py - line: 149 -DEBUG: Try next port: 50001
2020-04-23 18:00:00,872; client.py - line: 140 -DEBUG: Socket can not connect. Make sure that the tcp_server from unity is already running.
2020-04-23 18:00:00,872; client.py - line: 141 -DEBUG: [Errno 103] Software caused connection abort
2020-04-23 18:00:00,922; client.py - line: 149 -DEBUG: Try next port: 50002
2020-04-23 18:00:00,923; client.py - line: 140 -DEBUG: Socket can not connect. Make sure that the tcp_server from unity is already running.
2020-04-23 18:00:00,923; client.py - line: 141 -DEBUG: [Errno 111] Connection refused
2020-04-23 18:00:00,973; client.py - line: 149 -DEBUG: Try next port: 50003
2020-04-23 18:00:00,973; client.py - line: 140 -DEBUG: Socket can not connect. Make sure that the tcp_server from unity is already running.
2020-04-23 18:00:00,974; client.py - line: 141 -DEBUG: [Errno 103] Software caused connection abort
2020-04-23 18:00:01,024; client.py - line: 149 -DEBUG: Try next port: 50004
2020-04-23 18:00:01,024; client.py - line: 140 -DEBUG: Socket can not connect. Make sure that the tcp_server from unity is already running.
2020-04-23 18:00:01,024; client.py - line: 141 -DEBUG: [Errno 111] Connection refused
2020-04-23 18:00:01,075; client.py - line: 149 -DEBUG: Try next port: 50005
2020-04-23 18:00:01,075; client.py - line: 140 -DEBUG: Socket can not connect. Make sure that the tcp_server from unity is already running.
2020-04-23 18:00:01,075; client.py - line: 141 -DEBUG: [Errno 103] Software caused connection abort
2020-04-23 18:00:01,125; client.py - line: 149 -DEBUG: Try next port: 50006
2020-04-23 18:00:01,126; client.py - line: 140 -DEBUG: Socket can not connect. Make sure that the tcp_server from unity is already running.
2020-04-23 18:00:01,126; client.py - line: 141 -DEBUG: [Errno 111] Connection refused
2020-04-23 18:00:01,176; client.py - line: 149 -DEBUG: Try next port: 50007
2020-04-23 18:00:01,177; client.py - line: 140 -DEBUG: Socket can not connect. Make sure that the tcp_server from unity is already running.
2020-04-23 18:00:01,177; client.py - line: 141 -DEBUG: [Errno 103] Software caused connection abort
2020-04-23 18:00:01,228; client.py - line: 149 -DEBUG: Try next port: 50008
2020-04-23 18:00:01,228; client.py - line: 140 -DEBUG: Socket can not connect. Make sure that the tcp_server from unity is already running.
2020-04-23 18:00:01,228; client.py - line: 141 -DEBUG: [Errno 111] Connection refused
2020-04-23 18:00:01,278; client.py - line: 149 -DEBUG: Try next port: 50009
2020-04-23 18:00:01,278; client.py - line: 140 -DEBUG: Socket can not connect. Make sure that the tcp_server from unity is already running.
2020-04-23 18:00:01,278; client.py - line: 141 -DEBUG: [Errno 103] Software caused connection abort
2020-04-23 18:00:01,328; client.py - line: 149 -DEBUG: Try next port: 50010
2020-04-23 18:00:01,329; client.py - line: 140 -DEBUG: Socket can not connect. Make sure that the tcp_server from unity is already running.
2020-04-23 18:00:01,329; client.py - line: 141 -DEBUG: [Errno 111] Connection refused
2020-04-23 18:00:01,379; client.py - line: 149 -DEBUG: Try next port: 50011
2020-04-23 18:00:01,379; client.py - line: 140 -DEBUG: Socket can not connect. Make sure that the tcp_server from unity is already running.
2020-04-23 18:00:01,379; client.py - line: 141 -DEBUG: [Errno 103] Software caused connection abort
2020-04-23 18:00:01,429; client.py - line: 149 -DEBUG: Try next port: 50012
2020-04-23 18:00:01,430; client.py - line: 140 -DEBUG: Socket can not connect. Make sure that the tcp_server from unity is already running.
2020-04-23 18:00:01,430; client.py - line: 141 -DEBUG: [Errno 111] Connection refused
2020-04-23 18:00:01,480; client.py - line: 149 -DEBUG: Try next port: 50013
2020-04-23 18:00:01,481; client.py - line: 140 -DEBUG: Socket can not connect. Make sure that the tcp_server from unity is already running.
2020-04-23 18:00:01,481; client.py - line: 141 -DEBUG: [Errno 103] Software caused connection abort
2020-04-23 18:00:01,531; client.py - line: 149 -DEBUG: Try next port: 50014
2020-04-23 18:00:01,532; client.py - line: 140 -DEBUG: Socket can not connect. Make sure that the tcp_server from unity is already running.
2020-04-23 18:00:01,532; client.py - line: 141 -DEBUG: [Errno 111] Connection refused
2020-04-23 18:00:01,583; client.py - line: 149 -DEBUG: Try next port: 50015
2020-04-23 18:00:01,583; client.py - line: 140 -DEBUG: Socket can not connect. Make sure that the tcp_server from unity is already running.
2020-04-23 18:00:01,586; client.py - line: 141 -DEBUG: [Errno 103] Software caused connection abort
2020-04-23 18:00:01,637; client.py - line: 149 -DEBUG: Try next port: 50016
2020-04-23 18:00:01,637; client.py - line: 140 -DEBUG: Socket can not connect. Make sure that the tcp_server from unity is already running.
2020-04-23 18:00:01,637; client.py - line: 141 -DEBUG: [Errno 111] Connection refused
2020-04-23 18:00:01,687; client.py - line: 149 -DEBUG: Try next port: 50017
2020-04-23 18:00:01,688; client.py - line: 140 -DEBUG: Socket can not connect. Make sure that the tcp_server from unity is already running.
2020-04-23 18:00:01,688; client.py - line: 141 -DEBUG: [Errno 103] Software caused connection abort
2020-04-23 18:00:01,739; client.py - line: 149 -DEBUG: Try next port: 50018
2020-04-23 18:00:01,739; client.py - line: 140 -DEBUG: Socket can not connect. Make sure that the tcp_server from unity is already running.
2020-04-23 18:00:01,739; client.py - line: 141 -DEBUG: [Errno 111] Connection refused
2020-04-23 18:00:01,789; client.py - line: 149 -DEBUG: Try next port: 50019
2020-04-23 18:00:01,789; client.py - line: 140 -DEBUG: Socket can not connect. Make sure that the tcp_server from unity is already running.
2020-04-23 18:00:01,789; client.py - line: 141 -DEBUG: [Errno 103] Software caused connection abort
2020-04-23 18:00:01,840; client.py - line: 149 -DEBUG: Try next port: 50020
2020-04-23 18:00:01,840; client.py - line: 140 -DEBUG: Socket can not connect. Make sure that the tcp_server from unity is already running.
2020-04-23 18:00:01,840; client.py - line: 141 -DEBUG: [Errno 111] Connection refused
2020-04-23 18:00:01,890; client.py - line: 149 -DEBUG: Try next port: 50021
2020-04-23 18:00:01,891; client.py - line: 140 -DEBUG: Socket can not connect. Make sure that the tcp_server from unity is already running.
2020-04-23 18:00:01,891; client.py - line: 141 -DEBUG: [Errno 103] Software caused connection abort
2020-04-23 18:00:01,941; client.py - line: 149 -DEBUG: Try next port: 50022
2020-04-23 18:00:01,942; client.py - line: 140 -DEBUG: Socket can not connect. Make sure that the tcp_server from unity is already running.
2020-04-23 18:00:01,942; client.py - line: 141 -DEBUG: [Errno 111] Connection refused
2020-04-23 18:00:01,992; client.py - line: 149 -DEBUG: Try next port: 50023
2020-04-23 18:00:01,992; client.py - line: 140 -DEBUG: Socket can not connect. Make sure that the tcp_server from unity is already running.
2020-04-23 18:00:01,993; client.py - line: 141 -DEBUG: [Errno 103] Software caused connection abort
2020-04-23 18:00:02,043; client.py - line: 149 -DEBUG: Try next port: 50024
2020-04-23 18:00:02,043; client.py - line: 140 -DEBUG: Socket can not connect. Make sure that the tcp_server from unity is already running.
2020-04-23 18:00:02,044; client.py - line: 141 -DEBUG: [Errno 111] Connection refused
2020-04-23 18:00:02,094; client.py - line: 149 -DEBUG: Try next port: 50025
2020-04-23 18:00:02,094; client.py - line: 140 -DEBUG: Socket can not connect. Make sure that the tcp_server from unity is already running.
2020-04-23 18:00:02,095; client.py - line: 141 -DEBUG: [Errno 103] Software caused connection abort
2020-04-23 18:00:02,145; client.py - line: 149 -DEBUG: Try next port: 50026
2020-04-23 18:00:02,145; client.py - line: 140 -DEBUG: Socket can not connect. Make sure that the tcp_server from unity is already running.
2020-04-23 18:00:02,145; client.py - line: 141 -DEBUG: [Errno 111] Connection refused
2020-04-23 18:00:02,196; client.py - line: 149 -DEBUG: Try next port: 50027
2020-04-23 18:00:02,196; client.py - line: 140 -DEBUG: Socket can not connect. Make sure that the tcp_server from unity is already running.
2020-04-23 18:00:02,196; client.py - line: 141 -DEBUG: [Errno 103] Software caused connection abort
2020-04-23 18:00:02,246; client.py - line: 149 -DEBUG: Try next port: 50028
2020-04-23 18:00:02,246; client.py - line: 140 -DEBUG: Socket can not connect. Make sure that the tcp_server from unity is already running.
2020-04-23 18:00:02,247; client.py - line: 141 -DEBUG: [Errno 111] Connection refused
2020-04-23 18:00:02,297; client.py - line: 149 -DEBUG: Try next port: 50029
2020-04-23 18:00:02,298; client.py - line: 140 -DEBUG: Socket can not connect. Make sure that the tcp_server from unity is already running.
2020-04-23 18:00:02,299; client.py - line: 141 -DEBUG: [Errno 103] Software caused connection abort
2020-04-23 18:00:02,349; client.py - line: 149 -DEBUG: Try next port: 50030
2020-04-23 18:00:02,349; client.py - line: 140 -DEBUG: Socket can not connect. Make sure that the tcp_server from unity is already running.
2020-04-23 18:00:02,349; client.py - line: 141 -DEBUG: [Errno 111] Connection refused
2020-04-23 18:00:02,400; client.py - line: 149 -DEBUG: Try next port: 50031
2020-04-23 18:00:02,400; client.py - line: 140 -DEBUG: Socket can not connect. Make sure that the tcp_server from unity is already running.
2020-04-23 18:00:02,400; client.py - line: 141 -DEBUG: [Errno 103] Software caused connection abort
2020-04-23 18:00:02,450; client.py - line: 149 -DEBUG: Try next port: 50032
2020-04-23 18:00:02,451; client.py - line: 140 -DEBUG: Socket can not connect. Make sure that the tcp_server from unity is already running.
2020-04-23 18:00:02,451; client.py - line: 141 -DEBUG: [Errno 111] Connection refused
2020-04-23 18:00:02,501; client.py - line: 149 -DEBUG: Try next port: 50033
2020-04-23 18:00:02,501; client.py - line: 140 -DEBUG: Socket can not connect. Make sure that the tcp_server from unity is already running.
2020-04-23 18:00:02,502; client.py - line: 141 -DEBUG: [Errno 103] Software caused connection abort
2020-04-23 18:00:02,552; client.py - line: 149 -DEBUG: Try next port: 50034
2020-04-23 18:00:02,552; client.py - line: 140 -DEBUG: Socket can not connect. Make sure that the tcp_server from unity is already running.
2020-04-23 18:00:02,552; client.py - line: 141 -DEBUG: [Errno 111] Connection refused
2020-04-23 18:00:02,603; client.py - line: 149 -DEBUG: Try next port: 50035
2020-04-23 18:00:02,603; client.py - line: 140 -DEBUG: Socket can not connect. Make sure that the tcp_server from unity is already running.
2020-04-23 18:00:02,603; client.py - line: 141 -DEBUG: [Errno 103] Software caused connection abort
2020-04-23 18:00:02,653; client.py - line: 149 -DEBUG: Try next port: 50036
2020-04-23 18:00:02,654; client.py - line: 140 -DEBUG: Socket can not connect. Make sure that the tcp_server from unity is already running.
2020-04-23 18:00:02,654; client.py - line: 141 -DEBUG: [Errno 111] Connection refused
2020-04-23 18:00:02,704; client.py - line: 149 -DEBUG: Try next port: 50037
2020-04-23 18:00:02,704; client.py - line: 140 -DEBUG: Socket can not connect. Make sure that the tcp_server from unity is already running.
2020-04-23 18:00:02,704; client.py - line: 141 -DEBUG: [Errno 103] Software caused connection abort
2020-04-23 18:00:02,755; client.py - line: 149 -DEBUG: Try next port: 50038
2020-04-23 18:00:02,755; client.py - line: 140 -DEBUG: Socket can not connect. Make sure that the tcp_server from unity is already running.
2020-04-23 18:00:02,755; client.py - line: 141 -DEBUG: [Errno 111] Connection refused
2020-04-23 18:00:02,806; client.py - line: 149 -DEBUG: Try next port: 50039
2020-04-23 18:00:02,806; client.py - line: 140 -DEBUG: Socket can not connect. Make sure that the tcp_server from unity is already running.
2020-04-23 18:00:02,806; client.py - line: 141 -DEBUG: [Errno 103] Software caused connection abort
2020-04-23 18:00:02,856; client.py - line: 149 -DEBUG: Try next port: 50040
2020-04-23 18:00:02,857; client.py - line: 140 -DEBUG: Socket can not connect. Make sure that the tcp_server from unity is already running.
2020-04-23 18:00:02,857; client.py - line: 141 -DEBUG: [Errno 111] Connection refused
2020-04-23 18:00:02,908; client.py - line: 149 -DEBUG: Try next port: 50041
2020-04-23 18:00:02,908; client.py - line: 140 -DEBUG: Socket can not connect. Make sure that the tcp_server from unity is already running.
2020-04-23 18:00:02,908; client.py - line: 141 -DEBUG: [Errno 103] Software caused connection abort
2020-04-23 18:00:02,958; client.py - line: 149 -DEBUG: Try next port: 50042
2020-04-23 18:00:02,958; client.py - line: 140 -DEBUG: Socket can not connect. Make sure that the tcp_server from unity is already running.
2020-04-23 18:00:02,958; client.py - line: 141 -DEBUG: [Errno 111] Connection refused
2020-04-23 18:00:03,009; client.py - line: 149 -DEBUG: Try next port: 50043
2020-04-23 18:00:03,009; client.py - line: 140 -DEBUG: Socket can not connect. Make sure that the tcp_server from unity is already running.
2020-04-23 18:00:03,010; client.py - line: 141 -DEBUG: [Errno 103] Software caused connection abort
2020-04-23 18:00:03,060; client.py - line: 149 -DEBUG: Try next port: 50044
2020-04-23 18:00:03,060; client.py - line: 140 -DEBUG: Socket can not connect. Make sure that the tcp_server from unity is already running.
2020-04-23 18:00:03,061; client.py - line: 141 -DEBUG: [Errno 111] Connection refused
2020-04-23 18:00:03,111; client.py - line: 149 -DEBUG: Try next port: 50045
2020-04-23 18:00:03,111; client.py - line: 140 -DEBUG: Socket can not connect. Make sure that the tcp_server from unity is already running.
2020-04-23 18:00:03,111; client.py - line: 141 -DEBUG: [Errno 103] Software caused connection abort
2020-04-23 18:00:03,162; client.py - line: 149 -DEBUG: Try next port: 50046
2020-04-23 18:00:03,162; client.py - line: 140 -DEBUG: Socket can not connect. Make sure that the tcp_server from unity is already running.
2020-04-23 18:00:03,162; client.py - line: 141 -DEBUG: [Errno 111] Connection refused
2020-04-23 18:00:03,212; client.py - line: 149 -DEBUG: Try next port: 50047
2020-04-23 18:00:03,213; client.py - line: 140 -DEBUG: Socket can not connect. Make sure that the tcp_server from unity is already running.
2020-04-23 18:00:03,213; client.py - line: 141 -DEBUG: [Errno 103] Software caused connection abort
2020-04-23 18:00:03,263; client.py - line: 149 -DEBUG: Try next port: 50048
2020-04-23 18:00:03,264; client.py - line: 140 -DEBUG: Socket can not connect. Make sure that the tcp_server from unity is already running.
2020-04-23 18:00:03,264; client.py - line: 141 -DEBUG: [Errno 111] Connection refused
2020-04-23 18:00:03,315; client.py - line: 149 -DEBUG: Try next port: 50049
2020-04-23 18:00:03,315; client.py - line: 140 -DEBUG: Socket can not connect. Make sure that the tcp_server from unity is already running.
2020-04-23 18:00:03,315; client.py - line: 141 -DEBUG: [Errno 103] Software caused connection abort
2020-04-23 18:00:03,365; client.py - line: 149 -DEBUG: Try next port: 50050
2020-04-23 18:00:03,366; client.py - line: 136 -INFO: Socket connected.
2020-04-23 18:00:03,367; client.py - line: 137 -DEBUG: Saving TCP config to self.relative_path_TCPsocket_config.

2020-04-23 18:00:03,372; dataset.py - line: 75 -DEBUG: home directory: /home/haecker
2020-04-23 18:00:03,373; dataset.py - line: 78 -DEBUG: Dataset directory:/home/haecker/Documents/data_set/non
2020-04-23 18:00:03,373; dataset.py - line: 79 -DEBUG: Create config.
2020-04-23 18:00:03,375; dataset.py - line: 363 -DEBUG: Config Seed: 1978720165
2020-04-23 18:00:03,377; dataset.py - line: 83 -DEBUG: Dataset initialised.

2020-04-23 18:00:03,377; dataset.py - line: 363 -DEBUG: Config Seed: 160370228
2020-04-23 18:00:03,379; dataset.py - line: 1488 -INFO: length of sequence data set will be: 6
2020-04-23 18:00:03,380; client.py - line: 196 -DEBUG: Json string sent.

2020-04-23 18:00:03,546; client.py - line: 237 -DEBUG: Trying to receive data.
2020-04-23 18:00:03,547; client.py - line: 241 -DEBUG: Data from Unity received.
2020-04-23 18:00:03,547; client.py - line: 242 -DEBUG: End_tag detected, unity_resp_bytes[0:10]: bytearray(b'\x00\x89PNG\r\n\x1a\n\x00')
2020-04-23 18:00:03,547; client.py - line: 246 -DEBUG: img_bytes type: <class 'bytearray'>, img_bytes len: 220371, img_bytes[:10]: bytearray(b'\x89PNG\r\n\x1a\n\x00\x00')
2020-04-23 18:00:03,557; client.py - line: 249 -DEBUG: PIL Img: type: <class 'PIL.PngImagePlugin.PngImageFile'> 
2020-04-23 18:00:03,588; client.py - line: 251 -DEBUG: Returning img: type: <class 'numpy.ndarray'> 

2020-04-23 18:00:03,588; dataset.py - line: 1410 -DEBUG: index: 541
2020-04-23 18:00:03,588; dataset.py - line: 1412 -DEBUG: index: 542
2020-04-23 18:00:03,588; dataset.py - line: 1014 -DEBUG: data completed: Image index: 542
2020-04-23 18:00:03,726; client.py - line: 196 -DEBUG: Json string sent.

2020-04-23 18:00:03,876; client.py - line: 237 -DEBUG: Trying to receive data.
2020-04-23 18:00:03,876; client.py - line: 241 -DEBUG: Data from Unity received.
2020-04-23 18:00:03,876; client.py - line: 242 -DEBUG: End_tag detected, unity_resp_bytes[0:10]: bytearray(b'\x00\x89PNG\r\n\x1a\n\x00')
2020-04-23 18:00:03,877; client.py - line: 246 -DEBUG: img_bytes type: <class 'bytearray'>, img_bytes len: 268001, img_bytes[:10]: bytearray(b'\x89PNG\r\n\x1a\n\x00\x00')
2020-04-23 18:00:03,877; client.py - line: 249 -DEBUG: PIL Img: type: <class 'PIL.PngImagePlugin.PngImageFile'> 
2020-04-23 18:00:03,907; client.py - line: 251 -DEBUG: Returning img: type: <class 'numpy.ndarray'> 

2020-04-23 18:00:03,907; dataset.py - line: 1410 -DEBUG: index: 542
2020-04-23 18:00:03,907; dataset.py - line: 1412 -DEBUG: index: 543
2020-04-23 18:00:03,907; dataset.py - line: 1014 -DEBUG: data completed: Image index: 543
2020-04-23 18:00:04,069; client.py - line: 196 -DEBUG: Json string sent.

2020-04-23 18:00:04,220; client.py - line: 237 -DEBUG: Trying to receive data.
2020-04-23 18:00:04,221; client.py - line: 241 -DEBUG: Data from Unity received.
2020-04-23 18:00:04,221; client.py - line: 242 -DEBUG: End_tag detected, unity_resp_bytes[0:10]: bytearray(b'\x00\x89PNG\r\n\x1a\n\x00')
2020-04-23 18:00:04,221; client.py - line: 246 -DEBUG: img_bytes type: <class 'bytearray'>, img_bytes len: 239564, img_bytes[:10]: bytearray(b'\x89PNG\r\n\x1a\n\x00\x00')
2020-04-23 18:00:04,221; client.py - line: 249 -DEBUG: PIL Img: type: <class 'PIL.PngImagePlugin.PngImageFile'> 
2020-04-23 18:00:04,251; client.py - line: 251 -DEBUG: Returning img: type: <class 'numpy.ndarray'> 

2020-04-23 18:00:04,251; dataset.py - line: 1410 -DEBUG: index: 543
2020-04-23 18:00:04,251; dataset.py - line: 1412 -DEBUG: index: 544
2020-04-23 18:00:04,252; dataset.py - line: 1014 -DEBUG: data completed: Image index: 544
2020-04-23 18:00:04,396; client.py - line: 196 -DEBUG: Json string sent.

2020-04-23 18:00:04,572; client.py - line: 237 -DEBUG: Trying to receive data.
2020-04-23 18:00:04,572; client.py - line: 241 -DEBUG: Data from Unity received.
2020-04-23 18:00:04,572; client.py - line: 242 -DEBUG: End_tag detected, unity_resp_bytes[0:10]: bytearray(b'\x00\x89PNG\r\n\x1a\n\x00')
2020-04-23 18:00:04,572; client.py - line: 246 -DEBUG: img_bytes type: <class 'bytearray'>, img_bytes len: 241267, img_bytes[:10]: bytearray(b'\x89PNG\r\n\x1a\n\x00\x00')
2020-04-23 18:00:04,572; client.py - line: 249 -DEBUG: PIL Img: type: <class 'PIL.PngImagePlugin.PngImageFile'> 
2020-04-23 18:00:04,600; client.py - line: 251 -DEBUG: Returning img: type: <class 'numpy.ndarray'> 

2020-04-23 18:00:04,600; dataset.py - line: 1410 -DEBUG: index: 544
2020-04-23 18:00:04,600; dataset.py - line: 1412 -DEBUG: index: 545
2020-04-23 18:00:04,600; dataset.py - line: 1014 -DEBUG: data completed: Image index: 545
2020-04-23 18:00:04,739; client.py - line: 196 -DEBUG: Json string sent.

2020-04-23 18:00:04,874; client.py - line: 237 -DEBUG: Trying to receive data.
2020-04-23 18:00:04,874; client.py - line: 241 -DEBUG: Data from Unity received.
2020-04-23 18:00:04,874; client.py - line: 242 -DEBUG: End_tag detected, unity_resp_bytes[0:10]: bytearray(b'\x00\x89PNG\r\n\x1a\n\x00')
2020-04-23 18:00:04,874; client.py - line: 246 -DEBUG: img_bytes type: <class 'bytearray'>, img_bytes len: 221902, img_bytes[:10]: bytearray(b'\x89PNG\r\n\x1a\n\x00\x00')
2020-04-23 18:00:04,875; client.py - line: 249 -DEBUG: PIL Img: type: <class 'PIL.PngImagePlugin.PngImageFile'> 
2020-04-23 18:00:04,903; client.py - line: 251 -DEBUG: Returning img: type: <class 'numpy.ndarray'> 

2020-04-23 18:00:04,903; dataset.py - line: 1410 -DEBUG: index: 545
2020-04-23 18:00:04,903; dataset.py - line: 1412 -DEBUG: index: 546
2020-04-23 18:00:04,904; dataset.py - line: 1014 -DEBUG: data completed: Image index: 546
2020-04-23 18:00:05,040; client.py - line: 196 -DEBUG: Json string sent.

2020-04-23 18:00:05,186; client.py - line: 237 -DEBUG: Trying to receive data.
2020-04-23 18:00:05,187; client.py - line: 241 -DEBUG: Data from Unity received.
2020-04-23 18:00:05,187; client.py - line: 242 -DEBUG: End_tag detected, unity_resp_bytes[0:10]: bytearray(b'\x00\x89PNG\r\n\x1a\n\x00')
2020-04-23 18:00:05,187; client.py - line: 246 -DEBUG: img_bytes type: <class 'bytearray'>, img_bytes len: 220372, img_bytes[:10]: bytearray(b'\x89PNG\r\n\x1a\n\x00\x00')
2020-04-23 18:00:05,187; client.py - line: 249 -DEBUG: PIL Img: type: <class 'PIL.PngImagePlugin.PngImageFile'> 
2020-04-23 18:00:05,216; client.py - line: 251 -DEBUG: Returning img: type: <class 'numpy.ndarray'> 

2020-04-23 18:00:05,217; dataset.py - line: 1410 -DEBUG: index: 546
2020-04-23 18:00:05,217; dataset.py - line: 1412 -DEBUG: index: 547
2020-04-23 18:00:05,217; dataset.py - line: 1014 -DEBUG: data completed: Image index: 547
2020-04-23 18:00:05,368; client.py - line: 173 -INFO: Exit-message is sent. Unity build and socket now closing.

2020-04-23 18:00:05,368; client.py - line: 193 -DEBUG: Exit request sent.

2020-04-23 18:00:05,368; dataset.py - line: 1454 -DEBUG: Exit socket connection to unity.
2020-04-23 18:00:05,368; dataset.py - line: 1110 -DEBUG: Pose image is available is False
2020-04-23 18:00:05,368; dataset.py - line: 1152 -DEBUG: numb_y: 1
2020-04-23 18:00:05,368; dataset.py - line: 1153 -DEBUG: dicts[0]['image'].shape[0]: 1024
2020-04-23 18:00:05,369; dataset.py - line: 1154 -DEBUG: (images_per_row*dicts[0][image].shape[1]: 6144
2020-04-23 18:00:05,369; dataset.py - line: 1155 -DEBUG: dicts[0][image].shape[2]: 3
2020-04-23 18:00:05,397; dataset.py - line: 1157 -DEBUG: h_stacked.shape: (1, 1024, 6144, 3)
2020-04-23 18:00:05,544; dataset.py - line: 1170 -DEBUG: final_img.shape: (1024, 6144, 3)
